Workbook

Sheet Executive Summary
A1: Stoquify G1/G2 Gate Completion Workbook
A2: Answer first: G1 engineering checks pass, but authentic authority and human approval remain 0/33; G2 is predecessor-blocked and intrinsically incomplete.
A3: Fresh read-only database extraction: 2026-08-20T15:01:29.150Z | stoquify_dev_migrated_20260814 / public
A5: G1 technical 13 / 13 PASS_CURRENT | C5: G1 decisions 0 / 11 BLOCKED | E5: G1 obligations 0 / 33 17 roles | G5: Enterprise gates 0 / 10 G1 first blocker | I5: Release NO-GO Development only
A10: Executive Summary • The database contains all 34 expected development role candidates (17 roles × 2 tenants), but every row is synthetic or qualification-pending. • All 34 users, employees, contracts and assignments are active; however, MFA enrollment is 0, fresh-assurance sessions are 0, governance authority credit is 0 and approval credit is 0. • Use the workbook to select and verify real subjects, appointments, SoD/COI, fresh authentication, signatures and independent verification. The workbook cannot approve a decision or replace the canonical validator.
A14: Database finding | B14: Current value | C14: Meaning for G1
A15: Canonical role rows | B15: 34 | C15: Complete development coverage: 17 roles in each of two tenants.
A16: Candidate users | B16: 34 | C16: Candidates only; governance must select/verify one authoritative tenant and real people.
A17: Active employee/contract/assignment candidates | B17: 34 / 34 / 34 | C17: HRIS mechanics exist, but the appointments are RBAC_AND_HRIS_CONTEXT_ONLY.
A18: MFA-enrolled candidates | B18: 0 | C18: No candidate can currently satisfy a fresh-MFA approval workflow.
A19: Fresh-assurance sessions | B19: 0 | C19: No current authenticated approval evidence exists.
A20: Manager delegations | B20: 0 | C20: No delegation can be used to prove G1 authority.
A21: Governance authority credit | B21: 0 | C21: Database role, title and assignment do not establish G1 appointment authority.
A22: Approval credit | B22: 0 | C22: No deliberate, hash-bound, fresh-authenticated human approval exists.
A25: What can be automated | F25: What must remain human-controlled
A26: • Read canonical decisions, roles, paths and hashes • Prefill database subject/employee/assignment candidates • Check required fields, time window and hash shape • Detect drift, duplication and SoD conflicts • Rehash exported evidence and run validators | F26: • Confirm the real legal entity and authoritative people • Issue effective-dated G1 role appointments • Resolve conflicts or authorize documented exceptions • Review and deliberately approve/reject D-01 through D-11 • Provide qualified/external evidence and independently verify it
A33: Required completion sequence
A34: 1. Select the authoritative legal entity/tenant; do not treat either seed tenant as production truth.
A35: 2. Verify or create each real user/employee record and preserve a stable subject ID.
A36: 3. Issue scope- and date-bound G1 appointments; independently check SoD/COI and qualifications.
A37: 4. Enroll MFA, require fresh authentication and approve within ten minutes against the exact contract hash.
A38: 5. Export immutable evidence; a separate verifier rehashes it and confirms identity, role, tenant, time and intent.
A39: 6. Populate the live register only after verification and rerun the no-write G1 validator; require 11/11.

Sheet Chart Data
A1: G1 dimension | B1: Complete | C1: Remaining
A2: Technical checks | B2: 13 | C2: 0
A3: Decisions | B3: 0 | C3: 11
A4: Obligations | B4: 0 | C4: 33
A6: G2 status | B6: Count
A7: PASS_CURRENT | B7: 1
A8: PASS_WITH_LIMITATIONS | B8: 4
A9: OPEN_TECHNICAL | B9: 12
A10: OPEN_EXTERNAL_EVIDENCE | B10: 1

Sheet Enterprise Gates
A1: Enterprise POS Gate Sequence
A2: Canonical program order: 0/10 passed; G1 is the first blocker. Later gates are included only to show dependency, not to reassess G3-G9.
A5: Order | B5: Gate | C5: Name | D5: Dependencies | E5: Canonical Status | F5: First Blocker | G5: Eligible Now | H5: Required Next Step
A6: 1 | B6: G1 | C6: Architecture and control contract freeze | D6: None | E6: BLOCKED_AUTHENTIC_APPROVALS | F6: YES | G6: NO | H6: Complete the detached approval register with every required accountable role and externally verifiable fresh-auth signature evidence.
A7: 2 | B7: G2 | C7: Transaction and access trust | D7: G1 | E7: BLOCKED_DEPENDENCY_AND_PARTIAL_IMPLEMENTATION | F7: NO | G7: NO | H7: Pass predecessor gates before independent assessment.
A8: 3 | B8: G3A | C8: Provider-authoritative payment truth | D8: G2 | E8: BLOCKED_DEPENDENCY_AND_EXTERNAL_PROVIDER | F8: NO | G8: NO | H8: Pass predecessor gates before independent assessment.
A9: 4 | B9: G3B | C9: Immutable receipt and fiscal-source truth | D9: G2 | E9: BLOCKED_DEPENDENCY_AND_QUALIFIED_COUNTRY_REVIEW | F9: NO | G9: NO | H9: Pass predecessor gates before independent assessment.
A10: 5 | B10: G4 | C10: Bounded POS workstation release candidate | D10: G2, G3B | E10: BLOCKED_DEPENDENCY_AND_PHYSICAL_MATRIX | F10: NO | G10: NO | H10: Pass predecessor gates before independent assessment.
A11: 6 | B11: G5 | C11: Store financial close | D11: G3A, G3B, G4 | E11: BLOCKED_DEPENDENCY_AND_PARTIAL_CLOSE_MODEL | F11: NO | G11: NO | H11: Pass predecessor gates before independent assessment.
A12: 7 | B12: G6 | C12: Physical fulfillment truth | D12: G2 | E12: BLOCKED_DEPENDENCY_AND_MISSING_AGGREGATES | F12: NO | G12: NO | H12: Pass predecessor gates before independent assessment.
A13: 8 | B13: G7 | C13: Financial order-to-cash and returns | D13: G3A, G3B, G6 | E13: BLOCKED_DEPENDENCY_AND_PARTIAL_AR_FOUNDATION | F13: NO | G13: NO | H13: Pass predecessor gates before independent assessment.
A14: 9 | B14: G8 | C14: Operational readiness candidate | D14: G3A, G3B, G4, G5, G6, G7 | E14: BLOCKED_DEPENDENCIES_AND_PRODUCTION_LIKE_EVIDENCE | F14: NO | G14: NO | H14: Pass predecessor gates before independent assessment.
A15: 10 | B15: G9 | C15: Bounded pilot and production expansion | D15: G8 | E15: BLOCKED_DEPENDENCY_NOT_STARTED | F15: NO | G15: NO | H15: Pass predecessor gates before independent assessment.

Sheet G1 Technical
A1: G1 Technical Checks
A2: All 13 current technical contract checks pass. This does not substitute for human acceptance of D-01 through D-11.
A5: ID | B5: Canonical Check | C5: Requirement | D5: Status | E5: Validation Rule | F5: Evidence Reference | G5: Contract Hash | H5: Owner | I5: Preservation Action
A6: G1-T01 | B6: canonical_g1_numbering | C6: Canonical gate numbering is unambiguous | D6: PASS_CURRENT | E6: Contract identifies canonical G1 and legacy mapping without collision. | F6: Current canonical G1 validator output: ready=true | G6: 11434eb3e1af1826516426e90d2d53a2faa47ade361d91191b5f3e0c950a36db | H6: G1 engineering evidence owner | I6: Preserve the passing check and rerun after any relevant source, contract or policy change.
A7: G1-T02 | B7: decision_set_d01_through_d11 | C7: Decision set is exactly D-01 through D-11 | D7: PASS_CURRENT | E7: Validator finds all 11 unique decision IDs and no omissions. | F7: Current canonical G1 validator output: ready=true | G7: 11434eb3e1af1826516426e90d2d53a2faa47ade361d91191b5f3e0c950a36db | H7: G1 engineering evidence owner | I7: Preserve the passing check and rerun after any relevant source, contract or policy change.
A8: G1-T03 | B8: decisions_have_selected_fail_closed_options | C8: Every decision has a selected fail-closed option | D8: PASS_CURRENT | E8: Each decision contains a non-empty selectedOption and scoped failure policy. | F8: Current canonical G1 validator output: ready=true | G8: 11434eb3e1af1826516426e90d2d53a2faa47ade361d91191b5f3e0c950a36db | H8: G1 engineering evidence owner | I8: Preserve the passing check and rerun after any relevant source, contract or policy change.
A9: G1-T04 | B9: limited_development_scope_is_fail_closed | C9: Development scope is explicitly limited and fail-closed | D9: PASS_CURRENT | E9: Contract restricts country, currency, tenders, electronic/offline capture, receipt and hardware scope. | F9: Current canonical G1 validator output: ready=true | G9: 11434eb3e1af1826516426e90d2d53a2faa47ade361d91191b5f3e0c950a36db | H9: G1 engineering evidence owner | I9: Preserve the passing check and rerun after any relevant source, contract or policy change.
A10: G1-T05 | B10: state_machine_catalog_complete | C10: Required state-machine catalogue exists | D10: PASS_CURRENT | E10: Validator finds the canonical state-machine set in the frozen contract. | F10: Current canonical G1 validator output: ready=true | G10: 11434eb3e1af1826516426e90d2d53a2faa47ade361d91191b5f3e0c950a36db | H10: G1 engineering evidence owner | I10: Preserve the passing check and rerun after any relevant source, contract or policy change.
A11: G1-T06 | B11: runtime_mappings_and_gaps_are_explicit | C11: Runtime mappings and known gaps are explicit | D11: PASS_CURRENT | E11: Each state machine records current mapping, implementation status and gap. | F11: Current canonical G1 validator output: ready=true | G11: 11434eb3e1af1826516426e90d2d53a2faa47ade361d91191b5f3e0c950a36db | H11: G1 engineering evidence owner | I11: Preserve the passing check and rerun after any relevant source, contract or policy change.
A12: G1-T07 | B12: accounting_inventory_event_catalog_complete | C12: Accounting and inventory event catalogue exists | D12: PASS_CURRENT | E12: Contract enumerates required event ownership and consequences. | F12: Current canonical G1 validator output: ready=true | G12: 11434eb3e1af1826516426e90d2d53a2faa47ade361d91191b5f3e0c950a36db | H12: G1 engineering evidence owner | I12: Preserve the passing check and rerun after any relevant source, contract or policy change.
A13: G1-T08 | B13: single_sale_finalizer_preserved | C13: Single authoritative sale finalizer is preserved | D13: PASS_CURRENT | E13: Current source keeps commitPOSSale as the authoritative finalization boundary. | F13: Current canonical G1 validator output: ready=true | G13: 11434eb3e1af1826516426e90d2d53a2faa47ade361d91191b5f3e0c950a36db | H13: G1 engineering evidence owner | I13: Preserve the passing check and rerun after any relevant source, contract or policy change.
A14: G1-T09 | B14: cash_only_and_store_credit_runtime_control | C14: Cash-only UI and runtime control match the frozen scope | D14: PASS_CURRENT | E14: Contract permits only CASH; UI exposes CASH; runtime rejects store credit. | F14: Current canonical G1 validator output: ready=true | G14: 11434eb3e1af1826516426e90d2d53a2faa47ade361d91191b5f3e0c950a36db | H14: G1 engineering evidence owner | I14: Preserve the passing check and rerun after any relevant source, contract or policy change.
A15: G1-T10 | B15: refund_void_fresh_auth_and_compensation_contract | C15: Refund/void controls require fresh authentication and compensation | D15: PASS_CURRENT | E15: Actions require 300-second fresh auth and services use compensating events. | F15: Current canonical G1 validator output: ready=true | G15: 11434eb3e1af1826516426e90d2d53a2faa47ade361d91191b5f3e0c950a36db | H15: G1 engineering evidence owner | I15: Preserve the passing check and rerun after any relevant source, contract or policy change.
A16: G1-T11 | B16: stock_and_cogs_event_ownership | C16: Stock and COGS event ownership is explicit | D16: PASS_CURRENT | E16: Inventory stock issue and accounting consequences are source-linked. | F16: Current canonical G1 validator output: ready=true | G16: 11434eb3e1af1826516426e90d2d53a2faa47ade361d91191b5f3e0c950a36db | H16: G1 engineering evidence owner | I16: Preserve the passing check and rerun after any relevant source, contract or policy change.
... A18: G1-T13 | B18: detached_approval_register_binds_exact_contract_hash | C18: Detached register binds the exact contract hash | D18: PASS_CURRENT | E18: Approval register contract path, version, artifact ID and SHA-256 equal the frozen contract. | F18: Current canonical G1 validator output: ready=true | G18: 11434eb3e1af1826516426e90d2d53a2faa47ade361d91191b5f3e0c950a36db | H18: G1 engineering evidence owner | I18: Preserve the passing check and rerun after any relevant source, contract or policy change.

Sheet G1 Decisions
A1: G1 Decisions D-01 through D-11
A2: Decision rows are prefilled from the frozen contract. Approval counts remain canonical validator truth, not workbook self-certification.
A5: Decision ID | B5: Title | C5: Selected Option | D5: Implementation Status | E5: Required Role 1 | F5: Required Role 2 | G5: Required Role 3 | H5: Technical Contract | I5: Canonical Accepted Approvals | J5: Required Approvals | K5: Obligations Precheck Ready | L5: Canonical Decision Status | M5: External / Qualified Prerequisite | N5: Exact Next Action | O5: Contract Hash | P5: Source Artifacts
A6: D-01 | B6: Store-credit tender disposition | C6: DISABLE_HIDE_AND_REJECT_STORE_CREDIT | D6: ENFORCED_DEVELOPMENT_SCOPE | E6: Product owner | F6: Financial controller | G6: Payments owner | H6: PASS_CURRENT | I6: 0 | J6: 3 | K6: =COUNTIFS('G1 Obligations'!$B:$B,$A6,'G1 Obligations'!$Y:$Y,"READY_FOR_INDEPENDENT_VALIDATION") | L6: OPEN_AUTHORITY_EVIDENCE | M6: No separate prerequisite identified beyond authentic authority and approval. | N6: Complete and independently verify all three role obligations, then add one evidence-bound decision record to the live register without changing the frozen contract. | O6: 11434eb3e1af1826516426e90d2d53a2faa47ade361d91191b5f3e0c950a36db | P6: docs/pos-enterprise-grade-audit/EXECUTION_06_G1_CONTRACT_FREEZE_V0_2_0.json docs/pos-enterprise-grade-audit/EXECUTION_06_G1_CONTRACT_APPROVAL_REGISTER.json services/pos/pos.service.ts components/pos/ProfessionalPOSSystem.tsx
A7: D-02 | B7: Physical terminal/register and drawer session boundary | C7: TERMINAL_CURRENT_SESSION_CAS_PLUS_ONE_SESSION_DRAWER_OPENING_CLAIM | D7: PARTIALLY_ENFORCED | E7: Retail operations owner | F7: POS architect | G7: Security owner | H7: PASS_CURRENT | I7: 0 | J7: 3 | K7: =COUNTIFS('G1 Obligations'!$B:$B,$A7,'G1 Obligations'!$Y:$Y,"READY_FOR_INDEPENDENT_VALIDATION") | L7: OPEN_AUTHORITY_EVIDENCE | M7: No separate prerequisite identified beyond authentic authority and approval. | N7: Complete and independently verify all three role obligations, then add one evidence-bound decision record to the live register without changing the frozen contract. | O7: 11434eb3e1af1826516426e90d2d53a2faa47ade361d91191b5f3e0c950a36db | P7: docs/pos-enterprise-grade-audit/EXECUTION_06_G1_CONTRACT_FREEZE_V0_2_0.json docs/pos-enterprise-grade-audit/EXECUTION_06_G1_CONTRACT_APPROVAL_REGISTER.json prisma/schema.prisma:POSStation.currentSessionId services/pos/pos.service.ts:openPOSShift services/pos/pos.service.ts:commitPOSSale
A8: D-03 | B8: First electronic payment provider | C8: ELECTRONIC_TENDER_DISABLED_UNTIL_NAMED_PROVIDER_APPROVED | D8: DISABLED_CURRENT_SCOPE | E8: Payments owner | F8: Treasury owner | G8: Security owner | H8: PASS_CURRENT | I8: 0 | J8: 3 | K8: =COUNTIFS('G1 Obligations'!$B:$B,$A8,'G1 Obligations'!$Y:$Y,"READY_FOR_INDEPENDENT_VALIDATION") | L8: OPEN_AUTHORITY_EVIDENCE | M8: No separate prerequisite identified beyond authentic authority and approval. | N8: Complete and independently verify all three role obligations, then add one evidence-bound decision record to the live register without changing the frozen contract. | O8: 11434eb3e1af1826516426e90d2d53a2faa47ade361d91191b5f3e0c950a36db | P8: docs/pos-enterprise-grade-audit/EXECUTION_06_G1_CONTRACT_FREEZE_V0_2_0.json docs/pos-enterprise-grade-audit/EXECUTION_06_G1_CONTRACT_APPROVAL_REGISTER.json services/pos/pos.service.ts:assertSupportedSaleTenders components/pos/ProfessionalPOSSystem.tsx:tenderMethods
A9: D-04 | B9: Offline tender policy | C9: OFFLINE_CAPTURE_DISABLED | D9: DISABLED_CURRENT_SCOPE | E9: Product owner | F9: Risk owner | G9: Retail operations owner | H9: PASS_CURRENT | I9: 0 | J9: 3 | K9: =COUNTIFS('G1 Obligations'!$B:$B,$A9,'G1 Obligations'!$Y:$Y,"READY_FOR_INDEPENDENT_VALIDATION") | L9: OPEN_AUTHORITY_EVIDENCE | M9: No separate prerequisite identified beyond authentic authority and approval. | N9: Complete and independently verify all three role obligations, then add one evidence-bound decision record to the live register without changing the frozen contract. | O9: 11434eb3e1af1826516426e90d2d53a2faa47ade361d91191b5f3e0c950a36db | P9: docs/pos-enterprise-grade-audit/EXECUTION_06_G1_CONTRACT_FREEZE_V0_2_0.json docs/pos-enterprise-grade-audit/EXECUTION_06_G1_CONTRACT_APPROVAL_REGISTER.json services/pos/offline-sync.service.ts docs/pos-enterprise-grade-audit/EXECUTION_00_DECISION_REGISTER.json
A10: D-05 | B10: Browser, terminal and peripheral support matrix | C10: EDGE_151_WINDOWS_10_25H2_SIMULATED_DESKTOP_PDF_ONLY_DEVELOPMENT | D10: DEVELOPMENT_MATRIX_DECLARED_NOT_PHYSICALLY_CERTIFIED | E10: Retail operations owner | F10: QA owner | G10: Support owner | H10: PASS_CURRENT | I10: 0 | J10: 3 | K10: =COUNTIFS('G1 Obligations'!$B:$B,$A10,'G1 Obligations'!$Y:$Y,"READY_FOR_INDEPENDENT_VALIDATION") | L10: OPEN_AUTHORITY_EVIDENCE | M10: Signed hardware/support matrix or explicit continued production exclusion. | N10: Complete and independently verify all three role obligations, then add one evidence-bound decision record to the live register without changing the frozen contract. | O10: 11434eb3e1af1826516426e90d2d53a2faa47ade361d91191b5f3e0c950a36db | P10: docs/pos-enterprise-grade-audit/EXECUTION_06_G1_CONTRACT_FREEZE_V0_2_0.json docs/pos-enterprise-grade-audit/EXECUTION_06_G1_CONTRACT_APPROVAL_REGISTER.json docs/pos-enterprise-grade-audit/templates/TEMPLATE-04-HARDWARE-COMPLIANCE-MATRIX_FILLED_20260817.md
A11: D-06 | B11: Returns, voids and refunds policy | C11: LINKED_COMPENSATING_FULL_SALE_REFUND_AND_VOID_CURRENT_SCOPE | D11: FRESH_AUTH_AND_COMPENSATING_EVENTS_PRESENT_PARTIAL_RETURN_AND_MAKER_CHECKER_MISSING | E11: Financial controller | F11: Retail operations owner | G11: Risk owner | H11: PASS_CURRENT | I11: 0 | J11: 3 | K11: =COUNTIFS('G1 Obligations'!$B:$B,$A11,'G1 Obligations'!$Y:$Y,"READY_FOR_INDEPENDENT_VALIDATION") | L11: OPEN_AUTHORITY_EVIDENCE | M11: No separate prerequisite identified beyond authentic authority and approval. | N11: Complete and independently verify all three role obligations, then add one evidence-bound decision record to the live register without changing the frozen contract. | O11: 11434eb3e1af1826516426e90d2d53a2faa47ade361d91191b5f3e0c950a36db | P11: docs/pos-enterprise-grade-audit/EXECUTION_06_G1_CONTRACT_FREEZE_V0_2_0.json docs/pos-enterprise-grade-audit/EXECUTION_06_G1_CONTRACT_APPROVAL_REGISTER.json actions/pos/tender.actions.ts services/pos/pos.service.ts:refundPOSSale services/pos/pos.service.ts:voidPOSSale services/accounting/postings/post-refund.ts services/accounting/postings/post-void.ts
A12: D-07 | B12: Pilot country, currency, language and fiscal profile | C12: CAMEROON_XAF_EN_FR_DEVELOPMENT_ONLY | D12: DEVELOPMENT_ONLY_COUNTRY_PACK_FAILS_CLOSED_FOR_PRODUCTION | E12: Product owner | F12: Financial controller | G12: Qualified Cameroon country-pack reviewer | H12: PASS_CURRENT | I12: 0 | J12: 3 | K12: =COUNTIFS('G1 Obligations'!$B:$B,$A12,'G1 Obligations'!$Y:$Y,"READY_FOR_INDEPENDENT_VALIDATION") | L12: OPEN_AUTHORITY_EVIDENCE | M12: Qualified Cameroon country-pack review and qualification evidence. | N12: Complete and independently verify all three role obligations, then add one evidence-bound decision record to the live register without changing the frozen contract. | O12: 11434eb3e1af1826516426e90d2d53a2faa47ade361d91191b5f3e0c950a36db | P12: docs/pos-enterprise-grade-audit/EXECUTION_06_G1_CONTRACT_FREEZE_V0_2_0.json docs/pos-enterprise-grade-audit/EXECUTION_06_G1_CONTRACT_APPROVAL_REGISTER.json what-next/statutory-country-pack-production-readiness.json docs/HR-Payroll/evidence/country-packs/CM/2026-07-19/manifest.json
A13: D-08 | B13: Pilot service levels and error budgets | C13: NO_PRODUCTION_SLO_UNTIL_D05_MATRIX_AND_MEASURED_BASELINE | D13: TARGET_CONTRACT_NOT_BASELINED | E13: SRE owner | F13: Product owner | G13: Support owner | H13: PASS_CURRENT | I13: 0 | J13: 3 | K13: =COUNTIFS('G1 Obligations'!$B:$B,$A13,'G1 Obligations'!$Y:$Y,"READY_FOR_INDEPENDENT_VALIDATION") | L13: OPEN_AUTHORITY_EVIDENCE | M13: Measured baseline supporting the proposed production SLO/error budget. | N13: Complete and independently verify all three role obligations, then add one evidence-bound decision record to the live register without changing the frozen contract. | O13: 11434eb3e1af1826516426e90d2d53a2faa47ade361d91191b5f3e0c950a36db | P13: docs/pos-enterprise-grade-audit/EXECUTION_06_G1_CONTRACT_FREEZE_V0_2_0.json docs/pos-enterprise-grade-audit/EXECUTION_06_G1_CONTRACT_APPROVAL_REGISTER.json
A14: D-09 | B14: Delivery invoice recognition event | C14: ORDER_CONFIRMATION_NON_POSTING_INVOICE_FROM_ACCEPTED_DELIVERED_QUANTITY | D14: NOT_IMPLEMENTED_AS_DELIVERY_O2C_AGGREGATES | E14: Financial controller | F14: Order-to-cash product owner | G14: Qualified accounting reviewer | H14: PASS_CURRENT | I14: 0 | J14: 3 | K14: =COUNTIFS('G1 Obligations'!$B:$B,$A14,'G1 Obligations'!$Y:$Y,"READY_FOR_INDEPENDENT_VALIDATION") | L14: OPEN_AUTHORITY_EVIDENCE | M14: Qualified accounting review and qualification evidence. | N14: Complete and independently verify all three role obligations, then add one evidence-bound decision record to the live register without changing the frozen contract. | O14: 11434eb3e1af1826516426e90d2d53a2faa47ade361d91191b5f3e0c950a36db | P14: docs/pos-enterprise-grade-audit/EXECUTION_06_G1_CONTRACT_FREEZE_V0_2_0.json docs/pos-enterprise-grade-audit/EXECUTION_06_G1_CONTRACT_APPROVAL_REGISTER.json prisma/schema.prisma:SalesOrderStatus
A15: D-10 | B15: Reservation, availability and goods-issue policy | C15: RESERVATION_AFFECTS_AVAILABILITY_ONLY_PHYSICAL_ISSUE_OWNS_STOCK_AND_COGS | D15: IMMEDIATE_POS_GOODS_ISSUE_PRESENT_DELIVERY_RESERVATION_AGGREGATE_NOT_IMPLEMENTED | E15: Inventory controller | F15: Fulfillment owner | G15: Accounting owner | H15: PASS_CURRENT | I15: 0 | J15: 3 | K15: =COUNTIFS('G1 Obligations'!$B:$B,$A15,'G1 Obligations'!$Y:$Y,"READY_FOR_INDEPENDENT_VALIDATION") | L15: OPEN_AUTHORITY_EVIDENCE | M15: No separate prerequisite identified beyond authentic authority and approval. | N15: Complete and independently verify all three role obligations, then add one evidence-bound decision record to the live register without changing the frozen contract. | O15: 11434eb3e1af1826516426e90d2d53a2faa47ade361d91191b5f3e0c950a36db | P15: docs/pos-enterprise-grade-audit/EXECUTION_06_G1_CONTRACT_FREEZE_V0_2_0.json docs/pos-enterprise-grade-audit/EXECUTION_06_G1_CONTRACT_APPROVAL_REGISTER.json services/inventory/inventory-stock-event.service.ts:postPOSStockIssue services/inventory/inventory-stock-event.service.ts:postStockReservation
A16: D-11 | B16: Business-day, statement, reconciliation and accounting-close boundary | C16: KEEP_SESSION_DRAWER_BUSINESS_DAY_STATEMENT_RECONCILIATION_AND_CLOSE_SEPARATE | D16: SESSION_STATEMENT_RECONCILIATION_AND_ACCOUNTING_PERIOD_PRESENT_BUSINESS_DAY_AGGREGATE_MISSING | E16: Financial controller | F16: Treasury owner | G16: Retail operations owner | H16: PASS_CURRENT | I16: 0 | J16: 3 | K16: =COUNTIFS('G1 Obligations'!$B:$B,$A16,'G1 Obligations'!$Y:$Y,"READY_FOR_INDEPENDENT_VALIDATION") | L16: OPEN_AUTHORITY_EVIDENCE | M16: No separate prerequisite identified beyond authentic authority and approval. | N16: Complete and independently verify all three role obligations, then add one evidence-bound decision record to the live register without changing the frozen contract. | O16: 11434eb3e1af1826516426e90d2d53a2faa47ade361d91191b5f3e0c950a36db | P16: docs/pos-enterprise-grade-audit/EXECUTION_06_G1_CONTRACT_FREEZE_V0_2_0.json docs/pos-enterprise-grade-audit/EXECUTION_06_G1_CONTRACT_APPROVAL_REGISTER.json prisma/schema.prisma:POSSession prisma/schema.prisma:StatementFile prisma/schema.prisma:ReconciliationRun services/accounting/periods.service.ts

Sheet G1 Obligations
A1: G1 Decision-Role Obligations
A2: Exactly 33 obligations. Blue cells are formulas/current truth; yellow cells require authentic human/governance evidence and are intentionally blank.
A5: Obligation ID | B5: Decision ID | C5: Decision Title | D5: Canonical Role | E5: Role Code | F5: Current Status | G5: DB Candidate Count | H5: DB Candidate Options (Development Only) | I5: Verified Subject ID | J5: Verified Person Name | K5: Authoritative Tenant ID | L5: Authority Reference | M5: Appointment Scope | N5: Authority Effective From | O5: Authority Effective To / Open-ended | P5: SoD / COI Result | Q5: Fresh Auth Verified At | R5: Approved At | S5: Within 10 Minutes | T5: Decision Intent | U5: Signature / Evidence Reference | V5: Signature Evidence SHA-256 | W5: Independent Verifier Subject ID | X5: Independent Verification Result | Y5: Precheck Status | Z5: Canonical Validator Result | AA5: Contract Version | AB5: Contract Hash | AC5: Selected Option | AD5: Blocking Reason | AE5: Next Human Action | AF5: Evidence Credit Note
A6: G1-D01-01 | B6: D-01 | C6: Store-credit tender disposition | D6: Product owner | E6: product_owner | F6: OPEN_AUTHORITY_EVIDENCE | G6: 2 | H6: rds_org_001 | Estelle Nkom | rds_org_001_compliance_user_product_owner | SYNTHETIC_DEVELOPMENT_PERSONA rds_org_002 | Estelle Nkom | rds_org_002_compliance_user_product_owner | SYNTHETIC_DEVELOPMENT_PERSONA | S6: =IF(OR(Q6="",R6=""),"MISSING",IF(AND(R6>=Q6,(R6-Q6)*1440<=10),"PASS","FAIL")) | Y6: =IF(AND(I6<>"",J6<>"",K6<>"",L6<>"",M6<>"",N6<>"",O6<>"",P6="PASS",Q6<>"",R6<>"",S6="PASS",T6<>"",U6<>"",LEN(V6)=64,W6<>"",X6="PASS"),"READY_FOR_INDEPENDENT_VALIDATION","INCOMPLETE") | Z6: NOT_ACCEPTED | AA6: 0.2.0 | AB6: 11434eb3e1af1826516426e90d2d53a2faa47ade361d91191b5f3e0c950a36db | AC6: DISABLE_HIDE_AND_REJECT_STORE_CREDIT | AD6: No verified Product owner or authentic approval evidence. | AE6: Confirm the real Product owner by stable subject ID and exact authority; obtain fresh-authenticated artifact-bound approval; export, hash and independently verify the evidence. | AF6: Database candidates receive zero authority/approval credit until independently verified appointment and approval evidence exists.
A7: G1-D01-02 | B7: D-01 | C7: Store-credit tender disposition | D7: Financial controller | E7: financial_controller | F7: OPEN_AUTHORITY_EVIDENCE | G7: 2 | H7: rds_org_001 | Rodrigue Etoa | rds_org_001_compliance_user_financial_controller | SYNTHETIC_DEVELOPMENT_PERSONA rds_org_002 | Rodrigue Etoa | rds_org_002_compliance_user_financial_controller | SYNTHETIC_DEVELOPMENT_PERSONA | S7: =IF(OR(Q7="",R7=""),"MISSING",IF(AND(R7>=Q7,(R7-Q7)*1440<=10),"PASS","FAIL")) | Y7: =IF(AND(I7<>"",J7<>"",K7<>"",L7<>"",M7<>"",N7<>"",O7<>"",P7="PASS",Q7<>"",R7<>"",S7="PASS",T7<>"",U7<>"",LEN(V7)=64,W7<>"",X7="PASS"),"READY_FOR_INDEPENDENT_VALIDATION","INCOMPLETE") | Z7: NOT_ACCEPTED | AA7: 0.2.0 | AB7: 11434eb3e1af1826516426e90d2d53a2faa47ade361d91191b5f3e0c950a36db | AC7: DISABLE_HIDE_AND_REJECT_STORE_CREDIT | AD7: No verified Financial controller or authentic approval evidence. | AE7: Confirm exact finance authority; approve the liability and accounting boundary after fresh authentication; export, hash and independently verify the evidence. | AF7: Database candidates receive zero authority/approval credit until independently verified appointment and approval evidence exists.
A8: G1-D01-03 | B8: D-01 | C8: Store-credit tender disposition | D8: Payments owner | E8: payments_owner | F8: OPEN_AUTHORITY_EVIDENCE | G8: 2 | H8: rds_org_001 | Carine Mbappe | rds_org_001_compliance_user_payments_owner | SYNTHETIC_DEVELOPMENT_PERSONA rds_org_002 | Carine Mbappe | rds_org_002_compliance_user_payments_owner | SYNTHETIC_DEVELOPMENT_PERSONA | S8: =IF(OR(Q8="",R8=""),"MISSING",IF(AND(R8>=Q8,(R8-Q8)*1440<=10),"PASS","FAIL")) | Y8: =IF(AND(I8<>"",J8<>"",K8<>"",L8<>"",M8<>"",N8<>"",O8<>"",P8="PASS",Q8<>"",R8<>"",S8="PASS",T8<>"",U8<>"",LEN(V8)=64,W8<>"",X8="PASS"),"READY_FOR_INDEPENDENT_VALIDATION","INCOMPLETE") | Z8: NOT_ACCEPTED | AA8: 0.2.0 | AB8: 11434eb3e1af1826516426e90d2d53a2faa47ade361d91191b5f3e0c950a36db | AC8: DISABLE_HIDE_AND_REJECT_STORE_CREDIT | AD8: No verified Payments owner or authentic approval evidence. | AE8: Confirm payments authority; approve cash-only/store-credit rejection after fresh authentication; export, hash and independently verify the evidence. | AF8: Database candidates receive zero authority/approval credit until independently verified appointment and approval evidence exists.
A9: G1-D02-01 | B9: D-02 | C9: Physical terminal/register and drawer session boundary | D9: Retail operations owner | E9: retail_operations_owner | F9: OPEN_AUTHORITY_EVIDENCE | G9: 2 | H9: rds_org_001 | Boris Moukouri | rds_org_001_compliance_user_retail_operations_owner | SYNTHETIC_DEVELOPMENT_PERSONA rds_org_002 | Boris Moukouri | rds_org_002_compliance_user_retail_operations_owner | SYNTHETIC_DEVELOPMENT_PERSONA | S9: =IF(OR(Q9="",R9=""),"MISSING",IF(AND(R9>=Q9,(R9-Q9)*1440<=10),"PASS","FAIL")) | Y9: =IF(AND(I9<>"",J9<>"",K9<>"",L9<>"",M9<>"",N9<>"",O9<>"",P9="PASS",Q9<>"",R9<>"",S9="PASS",T9<>"",U9<>"",LEN(V9)=64,W9<>"",X9="PASS"),"READY_FOR_INDEPENDENT_VALIDATION","INCOMPLETE") | Z9: NOT_ACCEPTED | AA9: 0.2.0 | AB9: 11434eb3e1af1826516426e90d2d53a2faa47ade361d91191b5f3e0c950a36db | AC9: TERMINAL_CURRENT_SESSION_CAS_PLUS_ONE_SESSION_DRAWER_OPENING_CLAIM | AD9: No verified Retail operations owner or authentic approval evidence. | AE9: Confirm retail operations authority and approve the terminal/session/drawer operating boundary with its stated limitation. | AF9: Database candidates receive zero authority/approval credit until independently verified appointment and approval evidence exists.
A10: G1-D02-02 | B10: D-02 | C10: Physical terminal/register and drawer session boundary | D10: POS architect | E10: pos_architect | F10: OPEN_AUTHORITY_EVIDENCE | G10: 2 | H10: rds_org_001 | Kevin Abanda | rds_org_001_compliance_user_pos_architect | SYNTHETIC_DEVELOPMENT_PERSONA rds_org_002 | Kevin Abanda | rds_org_002_compliance_user_pos_architect | SYNTHETIC_DEVELOPMENT_PERSONA | S10: =IF(OR(Q10="",R10=""),"MISSING",IF(AND(R10>=Q10,(R10-Q10)*1440<=10),"PASS","FAIL")) | Y10: =IF(AND(I10<>"",J10<>"",K10<>"",L10<>"",M10<>"",N10<>"",O10<>"",P10="PASS",Q10<>"",R10<>"",S10="PASS",T10<>"",U10<>"",LEN(V10)=64,W10<>"",X10="PASS"),"READY_FOR_INDEPENDENT_VALIDATION","INCOMPLETE") | Z10: NOT_ACCEPTED | AA10: 0.2.0 | AB10: 11434eb3e1af1826516426e90d2d53a2faa47ade361d91191b5f3e0c950a36db | AC10: TERMINAL_CURRENT_SESSION_CAS_PLUS_ONE_SESSION_DRAWER_OPENING_CLAIM | AD10: No verified POS architect or authentic approval evidence. | AE10: Confirm architecture authority and approve the CAS/session/drawer invariant and documented gap after evidence review. | AF10: Database candidates receive zero authority/approval credit until independently verified appointment and approval evidence exists.
A11: G1-D02-03 | B11: D-02 | C11: Physical terminal/register and drawer session boundary | D11: Security owner | E11: security_owner | F11: OPEN_AUTHORITY_EVIDENCE | G11: 2 | H11: rds_org_001 | Solange Mekongo | rds_org_001_compliance_user_security_owner | SYNTHETIC_DEVELOPMENT_PERSONA rds_org_002 | Solange Mekongo | rds_org_002_compliance_user_security_owner | SYNTHETIC_DEVELOPMENT_PERSONA | S11: =IF(OR(Q11="",R11=""),"MISSING",IF(AND(R11>=Q11,(R11-Q11)*1440<=10),"PASS","FAIL")) | Y11: =IF(AND(I11<>"",J11<>"",K11<>"",L11<>"",M11<>"",N11<>"",O11<>"",P11="PASS",Q11<>"",R11<>"",S11="PASS",T11<>"",U11<>"",LEN(V11)=64,W11<>"",X11="PASS"),"READY_FOR_INDEPENDENT_VALIDATION","INCOMPLETE") | Z11: NOT_ACCEPTED | AA11: 0.2.0 | AB11: 11434eb3e1af1826516426e90d2d53a2faa47ade361d91191b5f3e0c950a36db | AC11: TERMINAL_CURRENT_SESSION_CAS_PLUS_ONE_SESSION_DRAWER_OPENING_CLAIM | AD11: No verified Security owner or authentic approval evidence. | AE11: Confirm security authority and approve tenant/session ownership, race and recovery controls with the documented gap. | AF11: Database candidates receive zero authority/approval credit until independently verified appointment and approval evidence exists.
A12: G1-D03-01 | B12: D-03 | C12: First electronic payment provider | D12: Payments owner | E12: payments_owner | F12: OPEN_AUTHORITY_EVIDENCE | G12: 2 | H12: rds_org_001 | Carine Mbappe | rds_org_001_compliance_user_payments_owner | SYNTHETIC_DEVELOPMENT_PERSONA rds_org_002 | Carine Mbappe | rds_org_002_compliance_user_payments_owner | SYNTHETIC_DEVELOPMENT_PERSONA | S12: =IF(OR(Q12="",R12=""),"MISSING",IF(AND(R12>=Q12,(R12-Q12)*1440<=10),"PASS","FAIL")) | Y12: =IF(AND(I12<>"",J12<>"",K12<>"",L12<>"",M12<>"",N12<>"",O12<>"",P12="PASS",Q12<>"",R12<>"",S12="PASS",T12<>"",U12<>"",LEN(V12)=64,W12<>"",X12="PASS"),"READY_FOR_INDEPENDENT_VALIDATION","INCOMPLETE") | Z12: NOT_ACCEPTED | AA12: 0.2.0 | AB12: 11434eb3e1af1826516426e90d2d53a2faa47ade361d91191b5f3e0c950a36db | AC12: ELECTRONIC_TENDER_DISABLED_UNTIL_NAMED_PROVIDER_APPROVED | AD12: No verified Payments owner or authentic approval evidence. | AE12: Confirm payments authority and approve continued electronic-tender disablement until a governed provider exists. | AF12: Database candidates receive zero authority/approval credit until independently verified appointment and approval evidence exists.
A13: G1-D03-02 | B13: D-03 | C13: First electronic payment provider | D13: Treasury owner | E13: treasury_owner | F13: OPEN_AUTHORITY_EVIDENCE | G13: 2 | H13: rds_org_001 | Mireille Ekani | rds_org_001_compliance_user_treasury_owner | SYNTHETIC_DEVELOPMENT_PERSONA rds_org_002 | Mireille Ekani | rds_org_002_compliance_user_treasury_owner | SYNTHETIC_DEVELOPMENT_PERSONA | S13: =IF(OR(Q13="",R13=""),"MISSING",IF(AND(R13>=Q13,(R13-Q13)*1440<=10),"PASS","FAIL")) | Y13: =IF(AND(I13<>"",J13<>"",K13<>"",L13<>"",M13<>"",N13<>"",O13<>"",P13="PASS",Q13<>"",R13<>"",S13="PASS",T13<>"",U13<>"",LEN(V13)=64,W13<>"",X13="PASS"),"READY_FOR_INDEPENDENT_VALIDATION","INCOMPLETE") | Z13: NOT_ACCEPTED | AA13: 0.2.0 | AB13: 11434eb3e1af1826516426e90d2d53a2faa47ade361d91191b5f3e0c950a36db | AC13: ELECTRONIC_TENDER_DISABLED_UNTIL_NAMED_PROVIDER_APPROVED | AD13: No verified Treasury owner or authentic approval evidence. | AE13: Confirm treasury authority and approve the provider/settlement fail-closed boundary. | AF13: Database candidates receive zero authority/approval credit until independently verified appointment and approval evidence exists.
A14: G1-D03-03 | B14: D-03 | C14: First electronic payment provider | D14: Security owner | E14: security_owner | F14: OPEN_AUTHORITY_EVIDENCE | G14: 2 | H14: rds_org_001 | Solange Mekongo | rds_org_001_compliance_user_security_owner | SYNTHETIC_DEVELOPMENT_PERSONA rds_org_002 | Solange Mekongo | rds_org_002_compliance_user_security_owner | SYNTHETIC_DEVELOPMENT_PERSONA | S14: =IF(OR(Q14="",R14=""),"MISSING",IF(AND(R14>=Q14,(R14-Q14)*1440<=10),"PASS","FAIL")) | Y14: =IF(AND(I14<>"",J14<>"",K14<>"",L14<>"",M14<>"",N14<>"",O14<>"",P14="PASS",Q14<>"",R14<>"",S14="PASS",T14<>"",U14<>"",LEN(V14)=64,W14<>"",X14="PASS"),"READY_FOR_INDEPENDENT_VALIDATION","INCOMPLETE") | Z14: NOT_ACCEPTED | AA14: 0.2.0 | AB14: 11434eb3e1af1826516426e90d2d53a2faa47ade361d91191b5f3e0c950a36db | AC14: ELECTRONIC_TENDER_DISABLED_UNTIL_NAMED_PROVIDER_APPROVED | AD14: No verified Security owner or authentic approval evidence. | AE14: Confirm security authority and approve continued disablement until provider security, credential and kill-switch controls exist. | AF14: Database candidates receive zero authority/approval credit until independently verified appointment and approval evidence exists.
A15: G1-D04-01 | B15: D-04 | C15: Offline tender policy | D15: Product owner | E15: product_owner | F15: OPEN_AUTHORITY_EVIDENCE | G15: 2 | H15: rds_org_001 | Estelle Nkom | rds_org_001_compliance_user_product_owner | SYNTHETIC_DEVELOPMENT_PERSONA rds_org_002 | Estelle Nkom | rds_org_002_compliance_user_product_owner | SYNTHETIC_DEVELOPMENT_PERSONA | S15: =IF(OR(Q15="",R15=""),"MISSING",IF(AND(R15>=Q15,(R15-Q15)*1440<=10),"PASS","FAIL")) | Y15: =IF(AND(I15<>"",J15<>"",K15<>"",L15<>"",M15<>"",N15<>"",O15<>"",P15="PASS",Q15<>"",R15<>"",S15="PASS",T15<>"",U15<>"",LEN(V15)=64,W15<>"",X15="PASS"),"READY_FOR_INDEPENDENT_VALIDATION","INCOMPLETE") | Z15: NOT_ACCEPTED | AA15: 0.2.0 | AB15: 11434eb3e1af1826516426e90d2d53a2faa47ade361d91191b5f3e0c950a36db | AC15: OFFLINE_CAPTURE_DISABLED | AD15: No verified Product owner or authentic approval evidence. | AE15: Confirm product authority and approve continued offline-capture disablement after reviewing replay gaps. | AF15: Database candidates receive zero authority/approval credit until independently verified appointment and approval evidence exists.
A16: G1-D04-02 | B16: D-04 | C16: Offline tender policy | D16: Risk owner | E16: risk_owner | F16: OPEN_AUTHORITY_EVIDENCE | G16: 2 | H16: rds_org_001 | Alain Fokou | rds_org_001_compliance_user_risk_owner | SYNTHETIC_DEVELOPMENT_PERSONA rds_org_002 | Alain Fokou | rds_org_002_compliance_user_risk_owner | SYNTHETIC_DEVELOPMENT_PERSONA | S16: =IF(OR(Q16="",R16=""),"MISSING",IF(AND(R16>=Q16,(R16-Q16)*1440<=10),"PASS","FAIL")) | Y16: =IF(AND(I16<>"",J16<>"",K16<>"",L16<>"",M16<>"",N16<>"",O16<>"",P16="PASS",Q16<>"",R16<>"",S16="PASS",T16<>"",U16<>"",LEN(V16)=64,W16<>"",X16="PASS"),"READY_FOR_INDEPENDENT_VALIDATION","INCOMPLETE") | Z16: NOT_ACCEPTED | AA16: 0.2.0 | AB16: 11434eb3e1af1826516426e90d2d53a2faa47ade361d91191b5f3e0c950a36db | AC16: OFFLINE_CAPTURE_DISABLED | AD16: No verified Risk owner or authentic approval evidence. | AE16: Confirm risk authority and accept the fail-closed offline policy and residual limitations. | AF16: Database candidates receive zero authority/approval credit until independently verified appointment and approval evidence exists.
A17: G1-D04-03 | B17: D-04 | C17: Offline tender policy | D17: Retail operations owner | E17: retail_operations_owner | F17: OPEN_AUTHORITY_EVIDENCE | G17: 2 | H17: rds_org_001 | Boris Moukouri | rds_org_001_compliance_user_retail_operations_owner | SYNTHETIC_DEVELOPMENT_PERSONA rds_org_002 | Boris Moukouri | rds_org_002_compliance_user_retail_operations_owner | SYNTHETIC_DEVELOPMENT_PERSONA | S17: =IF(OR(Q17="",R17=""),"MISSING",IF(AND(R17>=Q17,(R17-Q17)*1440<=10),"PASS","FAIL")) | Y17: =IF(AND(I17<>"",J17<>"",K17<>"",L17<>"",M17<>"",N17<>"",O17<>"",P17="PASS",Q17<>"",R17<>"",S17="PASS",T17<>"",U17<>"",LEN(V17)=64,W17<>"",X17="PASS"),"READY_FOR_INDEPENDENT_VALIDATION","INCOMPLETE") | Z17: NOT_ACCEPTED | AA17: 0.2.0 | AB17: 11434eb3e1af1826516426e90d2d53a2faa47ade361d91191b5f3e0c950a36db | AC17: OFFLINE_CAPTURE_DISABLED | AD17: No verified Retail operations owner or authentic approval evidence. | AE17: Confirm operations authority and approve the online-only operating procedure and recovery route. | AF17: Database candidates receive zero authority/approval credit until independently verified appointment and approval evidence exists.
... A38: G1-D11-03 | B38: D-11 | C38: Business-day, statement, reconciliation and accounting-close boundary | D38: Retail operations owner | E38: retail_operations_owner | F38: OPEN_AUTHORITY_EVIDENCE | G38: 2 | H38: rds_org_001 | Boris Moukouri | rds_org_001_compliance_user_retail_operations_owner | SYNTHETIC_DEVELOPMENT_PERSONA rds_org_002 | Boris Moukouri | rds_org_002_compliance_user_retail_operations_owner | SYNTHETIC_DEVELOPMENT_PERSONA | S38: =IF(OR(Q38="",R38=""),"MISSING",IF(AND(R38>=Q38,(R38-Q38)*1440<=10),"PASS","FAIL")) | Y38: =IF(AND(I38<>"",J38<>"",K38<>"",L38<>"",M38<>"",N38<>"",O38<>"",P38="PASS",Q38<>"",R38<>"",S38="PASS",T38<>"",U38<>"",LEN(V38)=64,W38<>"",X38="PASS"),"READY_FOR_INDEPENDENT_VALIDATION","INCOMPLETE") | Z38: NOT_ACCEPTED | AA38: 0.2.0 | AB38: 11434eb3e1af1826516426e90d2d53a2faa47ade361d91191b5f3e0c950a36db | AC38: KEEP_SESSION_DRAWER_BUSINESS_DAY_STATEMENT_RECONCILIATION_AND_CLOSE_SEPARATE | AD38: No verified Retail operations owner or authentic approval evidence. | AE38: Confirm operations authority and approve session/drawer/business-day procedures and exception handoffs. | AF38: Database candidates receive zero authority/approval credit until independently verified appointment and approval evidence exists.

Sheet DB Role Candidates
A1: Database Role Candidates
A2: Fresh read-only extraction. These rows prove development RBAC/HRIS context only; no row is automatically copied into an authority or approval field.
A5: Organization ID | B5: Organization Name | C5: Trade Name | D5: Tax Identifier (DB) | E5: Role Code | F5: Role Name | G5: Role ID | H5: Stable Subject ID | I5: Candidate Name | J5: User Active | K5: Account Verified | L5: Email Verified | M5: MFA Enabled At | N5: Employee ID | O5: Employee Number | P5: Employee Status | Q5: Employee Job Title | R5: Contract ID | S5: Contract Status | T5: Contract Effective From | U5: Contract Effective To | V5: Signed Document Hash | W5: Assignment ID | X5: Assignment Status | Y5: Assignment Effective From | Z5: Assignment Effective To | AA5: Org Unit | AB5: Position | AC5: Source Classification | AD5: Appointment Status | AE5: Signature Status | AF5: Qualification Status | AG5: Fresh Assurance Sessions | AH5: Latest Assurance At | AI5: Authority Credit | AJ5: Approval Credit | AK5: Eligible for Auto-Population?
A6: rds_org_001 | B6: Wilkinson - Feeney 001 | C6: Stoquify | D6: SEED-NIU-001-XAF | E6: accounting_owner | F6: Accounting Owner | G6: rds_org_001_compliance_role_accounting_owner | H6: rds_org_001_compliance_user_accounting_owner | I6: Francis Mbe | J6: TRUE | K6: TRUE | L6: TRUE | N6: rds_org_001_compliance_employee_accounting_owner | O6: CMP-035 | P6: ACTIVE | Q6: Accounting Owner | R6: rds_org_001_compliance_contract_accounting_owner | S6: ACTIVE | T6: 46023 | W6: rds_org_001_compliance_assignment_accounting_owner | X6: ACTIVE | Y6: 46023 | AA6: Finance and Accounting | AB6: Accounting Owner | AC6: SYNTHETIC_DEVELOPMENT_PERSONA | AD6: RBAC_AND_HRIS_CONTEXT_ONLY | AE6: NOT_STORED_NOT_CLAIMED | AF6: NOT_CLAIMED | AG6: 0 | AI6: 0 | AJ6: 0 | AK6: NO
A7: rds_org_001 | B7: Wilkinson - Feeney 001 | C7: Stoquify | D7: SEED-NIU-001-XAF | E7: financial_controller | F7: Financial Controller | G7: rds_org_001_compliance_role_financial_controller | H7: rds_org_001_compliance_user_financial_controller | I7: Rodrigue Etoa | J7: TRUE | K7: TRUE | L7: TRUE | N7: rds_org_001_compliance_employee_financial_controller | O7: CMP-019 | P7: ACTIVE | Q7: Financial Controller | R7: rds_org_001_compliance_contract_financial_controller | S7: ACTIVE | T7: 46023 | W7: rds_org_001_compliance_assignment_financial_controller | X7: ACTIVE | Y7: 46023 | AA7: Finance and Accounting | AB7: Financial Controller | AC7: SYNTHETIC_DEVELOPMENT_PERSONA | AD7: RBAC_AND_HRIS_CONTEXT_ONLY | AE7: NOT_STORED_NOT_CLAIMED | AF7: NOT_CLAIMED | AG7: 0 | AI7: 0 | AJ7: 0 | AK7: NO
A8: rds_org_001 | B8: Wilkinson - Feeney 001 | C8: Stoquify | D8: SEED-NIU-001-XAF | E8: fulfillment_owner | F8: Fulfillment Owner | G8: rds_org_001_compliance_role_fulfillment_owner | H8: rds_org_001_compliance_user_fulfillment_owner | I8: Agnes Metou | J8: TRUE | K8: TRUE | L8: TRUE | N8: rds_org_001_compliance_employee_fulfillment_owner | O8: CMP-034 | P8: ACTIVE | Q8: Fulfillment Owner | R8: rds_org_001_compliance_contract_fulfillment_owner | S8: ACTIVE | T8: 46023 | W8: rds_org_001_compliance_assignment_fulfillment_owner | X8: ACTIVE | Y8: 46023 | AA8: Retail Operations | AB8: Fulfillment Owner | AC8: SYNTHETIC_DEVELOPMENT_PERSONA | AD8: RBAC_AND_HRIS_CONTEXT_ONLY | AE8: NOT_STORED_NOT_CLAIMED | AF8: NOT_CLAIMED | AG8: 0 | AI8: 0 | AJ8: 0 | AK8: NO
A9: rds_org_001 | B9: Wilkinson - Feeney 001 | C9: Stoquify | D9: SEED-NIU-001-XAF | E9: inventory_controller | F9: Inventory Controller | G9: rds_org_001_compliance_role_inventory_controller | H9: rds_org_001_compliance_user_inventory_controller | I9: Didier Belinga | J9: TRUE | K9: TRUE | L9: TRUE | N9: rds_org_001_compliance_employee_inventory_controller | O9: CMP-033 | P9: ACTIVE | Q9: Inventory Controller | R9: rds_org_001_compliance_contract_inventory_controller | S9: ACTIVE | T9: 46023 | W9: rds_org_001_compliance_assignment_inventory_controller | X9: ACTIVE | Y9: 46023 | AA9: Finance and Accounting | AB9: Inventory Controller | AC9: SYNTHETIC_DEVELOPMENT_PERSONA | AD9: RBAC_AND_HRIS_CONTEXT_ONLY | AE9: NOT_STORED_NOT_CLAIMED | AF9: NOT_CLAIMED | AG9: 0 | AI9: 0 | AJ9: 0 | AK9: NO
A10: rds_org_001 | B10: Wilkinson - Feeney 001 | C10: Stoquify | D10: SEED-NIU-001-XAF | E10: order_to_cash_product_owner | F10: Order-to-Cash Product Owner | G10: rds_org_001_compliance_role_order_to_cash_product_owner | H10: rds_org_001_compliance_user_order_to_cash_product_owner | I10: Sandrine Ngassa | J10: TRUE | K10: TRUE | L10: TRUE | N10: rds_org_001_compliance_employee_order_to_cash_product_owner | O10: CMP-030 | P10: ACTIVE | Q10: Order-to-Cash Product Owner | R10: rds_org_001_compliance_contract_order_to_cash_product_owner | S10: ACTIVE | T10: 46023 | W10: rds_org_001_compliance_assignment_order_to_cash_product_owner | X10: ACTIVE | Y10: 46023 | AA10: Retail Operations | AB10: Order-to-Cash Product Owner | AC10: SYNTHETIC_DEVELOPMENT_PERSONA | AD10: RBAC_AND_HRIS_CONTEXT_ONLY | AE10: NOT_STORED_NOT_CLAIMED | AF10: NOT_CLAIMED | AG10: 0 | AI10: 0 | AJ10: 0 | AK10: NO
A11: rds_org_001 | B11: Wilkinson - Feeney 001 | C11: Stoquify | D11: SEED-NIU-001-XAF | E11: payments_owner | F11: Payments Owner | G11: rds_org_001_compliance_role_payments_owner | H11: rds_org_001_compliance_user_payments_owner | I11: Carine Mbappe | J11: TRUE | K11: TRUE | L11: TRUE | N11: rds_org_001_compliance_employee_payments_owner | O11: CMP-021 | P11: ACTIVE | Q11: Payments Owner | R11: rds_org_001_compliance_contract_payments_owner | S11: ACTIVE | T11: 46023 | W11: rds_org_001_compliance_assignment_payments_owner | X11: ACTIVE | Y11: 46023 | AA11: Finance and Accounting | AB11: Payments Owner | AC11: SYNTHETIC_DEVELOPMENT_PERSONA | AD11: RBAC_AND_HRIS_CONTEXT_ONLY | AE11: NOT_STORED_NOT_CLAIMED | AF11: NOT_CLAIMED | AG11: 0 | AI11: 0 | AJ11: 0 | AK11: NO
A12: rds_org_001 | B12: Wilkinson - Feeney 001 | C12: Stoquify | D12: SEED-NIU-001-XAF | E12: pos_architect | F12: POS Architect | G12: rds_org_001_compliance_role_pos_architect | H12: rds_org_001_compliance_user_pos_architect | I12: Kevin Abanda | J12: TRUE | K12: TRUE | L12: TRUE | N12: rds_org_001_compliance_employee_pos_architect | O12: CMP-023 | P12: ACTIVE | Q12: POS Architect | R12: rds_org_001_compliance_contract_pos_architect | S12: ACTIVE | T12: 46023 | W12: rds_org_001_compliance_assignment_pos_architect | X12: ACTIVE | Y12: 46023 | AA12: Platform Engineering | AB12: POS Architect | AC12: SYNTHETIC_DEVELOPMENT_PERSONA | AD12: RBAC_AND_HRIS_CONTEXT_ONLY | AE12: NOT_STORED_NOT_CLAIMED | AF12: NOT_CLAIMED | AG12: 0 | AI12: 0 | AJ12: 0 | AK12: NO
A13: rds_org_001 | B13: Wilkinson - Feeney 001 | C13: Stoquify | D13: SEED-NIU-001-XAF | E13: product_owner | F13: Product Owner | G13: rds_org_001_compliance_role_product_owner | H13: rds_org_001_compliance_user_product_owner | I13: Estelle Nkom | J13: TRUE | K13: TRUE | L13: TRUE | N13: rds_org_001_compliance_employee_product_owner | O13: CMP-017 | P13: ACTIVE | Q13: Product Owner | R13: rds_org_001_compliance_contract_product_owner | S13: ACTIVE | T13: 46023 | W13: rds_org_001_compliance_assignment_product_owner | X13: ACTIVE | Y13: 46023 | AA13: Executive and Product | AB13: Product Owner | AC13: SYNTHETIC_DEVELOPMENT_PERSONA | AD13: RBAC_AND_HRIS_CONTEXT_ONLY | AE13: NOT_STORED_NOT_CLAIMED | AF13: NOT_CLAIMED | AG13: 0 | AI13: 0 | AJ13: 0 | AK13: NO
A14: rds_org_001 | B14: Wilkinson - Feeney 001 | C14: Stoquify | D14: SEED-NIU-001-XAF | E14: qa_owner | F14: QA Owner | G14: rds_org_001_compliance_role_qa_owner | H14: rds_org_001_compliance_user_qa_owner | I14: Audrey Ndam | J14: TRUE | K14: TRUE | L14: TRUE | N14: rds_org_001_compliance_employee_qa_owner | O14: CMP-027 | P14: ACTIVE | Q14: QA Owner | R14: rds_org_001_compliance_contract_qa_owner | S14: ACTIVE | T14: 46023 | W14: rds_org_001_compliance_assignment_qa_owner | X14: ACTIVE | Y14: 46023 | AA14: Audit and Assurance | AB14: QA Owner | AC14: SYNTHETIC_DEVELOPMENT_PERSONA | AD14: RBAC_AND_HRIS_CONTEXT_ONLY | AE14: NOT_STORED_NOT_CLAIMED | AF14: NOT_CLAIMED | AG14: 0 | AI14: 0 | AJ14: 0 | AK14: NO
A15: rds_org_001 | B15: Wilkinson - Feeney 001 | C15: Stoquify | D15: SEED-NIU-001-XAF | E15: qualified_accounting_reviewer | F15: Qualified Accounting Reviewer (verification pending) | G15: rds_org_001_compliance_role_qualified_accounting_reviewer | H15: rds_org_001_compliance_user_qualified_accounting_reviewer | I15: Blandine Menye | J15: TRUE | K15: TRUE | L15: TRUE | N15: rds_org_001_compliance_employee_qualified_accounting_reviewer | O15: CMP-031 | P15: ACTIVE | Q15: Qualified Accounting Reviewer (verification pending) | R15: rds_org_001_compliance_contract_qualified_accounting_reviewer | S15: ACTIVE | T15: 46023 | W15: rds_org_001_compliance_assignment_qualified_accounting_reviewer | X15: ACTIVE | Y15: 46023 | AA15: Audit and Assurance | AB15: Qualified Accounting Reviewer (verification pending) | AC15: SYNTHETIC_QUALIFICATION_PENDING | AD15: RBAC_AND_HRIS_CONTEXT_ONLY | AE15: NOT_STORED_NOT_CLAIMED | AF15: REQUIRES_QUALIFIED_HUMAN_REVIEW | AG15: 0 | AI15: 0 | AJ15: 0 | AK15: NO
A16: rds_org_001 | B16: Wilkinson - Feeney 001 | C16: Stoquify | D16: SEED-NIU-001-XAF | E16: qualified_cameroon_country_pack_reviewer | F16: Qualified Cameroon Country-Pack Reviewer (verification pending) | G16: rds_org_001_compliance_role_qualified_cameroon_country_pack_reviewer | H16: rds_org_001_compliance_user_qualified_cameroon_country_pack_reviewer | I16: Josephine Ebogo | J16: TRUE | K16: TRUE | L16: TRUE | N16: rds_org_001_compliance_employee_qualified_cameroon_country_pack_reviewer | O16: CMP-032 | P16: ACTIVE | Q16: Qualified Cameroon Country-Pack Reviewer (verification pending) | R16: rds_org_001_compliance_contract_qualified_cameroon_country_pack_reviewer | S16: ACTIVE | T16: 46023 | W16: rds_org_001_compliance_assignment_qualified_cameroon_country_pack_reviewer | X16: ACTIVE | Y16: 46023 | AA16: Audit and Assurance | AB16: Qualified Cameroon Country-Pack Reviewer (verification pending) | AC16: SYNTHETIC_QUALIFICATION_PENDING | AD16: RBAC_AND_HRIS_CONTEXT_ONLY | AE16: NOT_STORED_NOT_CLAIMED | AF16: REQUIRES_QUALIFIED_HUMAN_REVIEW | AG16: 0 | AI16: 0 | AJ16: 0 | AK16: NO
A17: rds_org_001 | B17: Wilkinson - Feeney 001 | C17: Stoquify | D17: SEED-NIU-001-XAF | E17: retail_operations_owner | F17: Retail Operations Owner | G17: rds_org_001_compliance_role_retail_operations_owner | H17: rds_org_001_compliance_user_retail_operations_owner | I17: Boris Moukouri | J17: TRUE | K17: TRUE | L17: TRUE | N17: rds_org_001_compliance_employee_retail_operations_owner | O17: CMP-022 | P17: ACTIVE | Q17: Retail Operations Owner | R17: rds_org_001_compliance_contract_retail_operations_owner | S17: ACTIVE | T17: 46023 | W17: rds_org_001_compliance_assignment_retail_operations_owner | X17: ACTIVE | Y17: 46023 | AA17: Retail Operations | AB17: Retail Operations Owner | AC17: SYNTHETIC_DEVELOPMENT_PERSONA | AD17: RBAC_AND_HRIS_CONTEXT_ONLY | AE17: NOT_STORED_NOT_CLAIMED | AF17: NOT_CLAIMED | AG17: 0 | AI17: 0 | AJ17: 0 | AK17: NO
... A39: rds_org_002 | B39: McDermott, Greenholt and Johnson 002 | C39: AqStoq Market 002 | D39: SEED-NIU-002-XAF | E39: treasury_owner | F39: Treasury Owner | G39: rds_org_002_compliance_role_treasury_owner | H39: rds_org_002_compliance_user_treasury_owner | I39: Mireille Ekani | J39: TRUE | K39: TRUE | L39: TRUE | N39: rds_org_002_compliance_employee_treasury_owner | O39: CMP-025 | P39: ACTIVE | Q39: Treasury Owner | R39: rds_org_002_compliance_contract_treasury_owner | S39: ACTIVE | T39: 46023 | W39: rds_org_002_compliance_assignment_treasury_owner | X39: ACTIVE | Y39: 46023 | AA39: Finance and Accounting | AB39: Treasury Owner | AC39: SYNTHETIC_DEVELOPMENT_PERSONA | AD39: RBAC_AND_HRIS_CONTEXT_ONLY | AE39: NOT_STORED_NOT_CLAIMED | AF39: NOT_CLAIMED | AG39: 0 | AI39: 0 | AJ39: 0 | AK39: NO

Sheet 17 Role Summary
A1: Canonical G1 Role Summary
A2: One row per canonical role. Candidate coverage is complete for development; authentic appointment, MFA, fresh-auth and approval remain unresolved.
A5: Canonical Role | B5: Role Code | C5: Obligation Count | D5: Decision IDs | E5: DB Candidate Count | F5: Candidate Options | G5: Active Candidates | H5: MFA-Enrolled Candidates | I5: Fresh Assurance Sessions | J5: Authority Credit | K5: Approval Credit | L5: Current Status | M5: Human Owner | N5: Required Next Action
A6: Product owner | B6: product_owner | C6: 4 | D6: D-01, D-04, D-07, D-08 | E6: 2 | F6: rds_org_001 | Estelle Nkom | rds_org_001_compliance_user_product_owner rds_org_002 | Estelle Nkom | rds_org_002_compliance_user_product_owner | G6: 2 | H6: 0 | I6: 0 | J6: 0 | K6: 0 | L6: OPEN_AUTHORITY_EVIDENCE | M6: Governance/HR/security owner plus independent verifier | N6: Select and verify the real Product owner; issue an exact G1 appointment; complete SoD/COI, MFA, fresh-auth approval and independent evidence verification.
A7: Financial controller | B7: financial_controller | C7: 5 | D7: D-01, D-06, D-07, D-09, D-11 | E7: 2 | F7: rds_org_001 | Rodrigue Etoa | rds_org_001_compliance_user_financial_controller rds_org_002 | Rodrigue Etoa | rds_org_002_compliance_user_financial_controller | G7: 2 | H7: 0 | I7: 0 | J7: 0 | K7: 0 | L7: OPEN_AUTHORITY_EVIDENCE | M7: Governance/HR/security owner plus independent verifier | N7: Select and verify the real Financial controller; issue an exact G1 appointment; complete SoD/COI, MFA, fresh-auth approval and independent evidence verification.
A8: Payments owner | B8: payments_owner | C8: 2 | D8: D-01, D-03 | E8: 2 | F8: rds_org_001 | Carine Mbappe | rds_org_001_compliance_user_payments_owner rds_org_002 | Carine Mbappe | rds_org_002_compliance_user_payments_owner | G8: 2 | H8: 0 | I8: 0 | J8: 0 | K8: 0 | L8: OPEN_AUTHORITY_EVIDENCE | M8: Governance/HR/security owner plus independent verifier | N8: Select and verify the real Payments owner; issue an exact G1 appointment; complete SoD/COI, MFA, fresh-auth approval and independent evidence verification.
A9: Retail operations owner | B9: retail_operations_owner | C9: 5 | D9: D-02, D-04, D-05, D-06, D-11 | E9: 2 | F9: rds_org_001 | Boris Moukouri | rds_org_001_compliance_user_retail_operations_owner rds_org_002 | Boris Moukouri | rds_org_002_compliance_user_retail_operations_owner | G9: 2 | H9: 0 | I9: 0 | J9: 0 | K9: 0 | L9: OPEN_AUTHORITY_EVIDENCE | M9: Governance/HR/security owner plus independent verifier | N9: Select and verify the real Retail operations owner; issue an exact G1 appointment; complete SoD/COI, MFA, fresh-auth approval and independent evidence verification.
A10: POS architect | B10: pos_architect | C10: 1 | D10: D-02 | E10: 2 | F10: rds_org_001 | Kevin Abanda | rds_org_001_compliance_user_pos_architect rds_org_002 | Kevin Abanda | rds_org_002_compliance_user_pos_architect | G10: 2 | H10: 0 | I10: 0 | J10: 0 | K10: 0 | L10: OPEN_AUTHORITY_EVIDENCE | M10: Governance/HR/security owner plus independent verifier | N10: Select and verify the real POS architect; issue an exact G1 appointment; complete SoD/COI, MFA, fresh-auth approval and independent evidence verification.
A11: Security owner | B11: security_owner | C11: 2 | D11: D-02, D-03 | E11: 2 | F11: rds_org_001 | Solange Mekongo | rds_org_001_compliance_user_security_owner rds_org_002 | Solange Mekongo | rds_org_002_compliance_user_security_owner | G11: 2 | H11: 0 | I11: 0 | J11: 0 | K11: 0 | L11: OPEN_AUTHORITY_EVIDENCE | M11: Governance/HR/security owner plus independent verifier | N11: Select and verify the real Security owner; issue an exact G1 appointment; complete SoD/COI, MFA, fresh-auth approval and independent evidence verification.
A12: Treasury owner | B12: treasury_owner | C12: 2 | D12: D-03, D-11 | E12: 2 | F12: rds_org_001 | Mireille Ekani | rds_org_001_compliance_user_treasury_owner rds_org_002 | Mireille Ekani | rds_org_002_compliance_user_treasury_owner | G12: 2 | H12: 0 | I12: 0 | J12: 0 | K12: 0 | L12: OPEN_AUTHORITY_EVIDENCE | M12: Governance/HR/security owner plus independent verifier | N12: Select and verify the real Treasury owner; issue an exact G1 appointment; complete SoD/COI, MFA, fresh-auth approval and independent evidence verification.
A13: Risk owner | B13: risk_owner | C13: 2 | D13: D-04, D-06 | E13: 2 | F13: rds_org_001 | Alain Fokou | rds_org_001_compliance_user_risk_owner rds_org_002 | Alain Fokou | rds_org_002_compliance_user_risk_owner | G13: 2 | H13: 0 | I13: 0 | J13: 0 | K13: 0 | L13: OPEN_AUTHORITY_EVIDENCE | M13: Governance/HR/security owner plus independent verifier | N13: Select and verify the real Risk owner; issue an exact G1 appointment; complete SoD/COI, MFA, fresh-auth approval and independent evidence verification.
A14: QA owner | B14: qa_owner | C14: 1 | D14: D-05 | E14: 2 | F14: rds_org_001 | Audrey Ndam | rds_org_001_compliance_user_qa_owner rds_org_002 | Audrey Ndam | rds_org_002_compliance_user_qa_owner | G14: 2 | H14: 0 | I14: 0 | J14: 0 | K14: 0 | L14: OPEN_AUTHORITY_EVIDENCE | M14: Governance/HR/security owner plus independent verifier | N14: Select and verify the real QA owner; issue an exact G1 appointment; complete SoD/COI, MFA, fresh-auth approval and independent evidence verification.
A15: Support owner | B15: support_owner | C15: 2 | D15: D-05, D-08 | E15: 2 | F15: rds_org_001 | Pascal Ekotto | rds_org_001_compliance_user_support_owner rds_org_002 | Pascal Ekotto | rds_org_002_compliance_user_support_owner | G15: 2 | H15: 0 | I15: 0 | J15: 0 | K15: 0 | L15: OPEN_AUTHORITY_EVIDENCE | M15: Governance/HR/security owner plus independent verifier | N15: Select and verify the real Support owner; issue an exact G1 appointment; complete SoD/COI, MFA, fresh-auth approval and independent evidence verification.
A16: Qualified Cameroon country-pack reviewer | B16: qualified_cameroon_country_pack_reviewer | C16: 1 | D16: D-07 | E16: 2 | F16: rds_org_001 | Josephine Ebogo | rds_org_001_compliance_user_qualified_cameroon_country_pack_reviewer rds_org_002 | Josephine Ebogo | rds_org_002_compliance_user_qualified_cameroon_country_pack_reviewer | G16: 2 | H16: 0 | I16: 0 | J16: 0 | K16: 0 | L16: OPEN_EXTERNAL_EVIDENCE | M16: Governance/HR/security owner plus independent verifier | N16: Select and verify the real Qualified Cameroon country-pack reviewer; issue an exact G1 appointment; complete SoD/COI, MFA, fresh-auth approval and independent evidence verification.
A17: SRE owner | B17: sre_owner | C17: 1 | D17: D-08 | E17: 2 | F17: rds_org_001 | Christian Nlend | rds_org_001_compliance_user_sre_owner rds_org_002 | Christian Nlend | rds_org_002_compliance_user_sre_owner | G17: 2 | H17: 0 | I17: 0 | J17: 0 | K17: 0 | L17: OPEN_AUTHORITY_EVIDENCE | M17: Governance/HR/security owner plus independent verifier | N17: Select and verify the real SRE owner; issue an exact G1 appointment; complete SoD/COI, MFA, fresh-auth approval and independent evidence verification.
... A22: Accounting owner | B22: accounting_owner | C22: 1 | D22: D-10 | E22: 2 | F22: rds_org_001 | Francis Mbe | rds_org_001_compliance_user_accounting_owner rds_org_002 | Francis Mbe | rds_org_002_compliance_user_accounting_owner | G22: 2 | H22: 0 | I22: 0 | J22: 0 | K22: 0 | L22: OPEN_AUTHORITY_EVIDENCE | M22: Governance/HR/security owner plus independent verifier | N22: Select and verify the real Accounting owner; issue an exact G1 appointment; complete SoD/COI, MFA, fresh-auth approval and independent evidence verification.

Sheet G2 Controls
A1: G2 Intrinsic Control Status
A2: G2 remains blocked by G1 and has independent work: 1 current pass, 4 limited passes, 12 technical blockers and 1 external-evidence blocker.
