Workbook

Sheet Read me
A1: Nkambe recipe and costing registers H3
A2: 8 October 2026 — all formulas require production validation
A3: Prices holds editable FCFA/kg. Empty cells mean unknown, not zero.
A4: Ingredients recalculates direct prices and prepared-component subtotals. Component rates use the usable mass on Summary; update that mass after measured yield changes.
A5: Summary shows known ingredient subtotals only; full variable cost and selling price must be entered separately before contribution is computed.
A6: Missing-price counts cover direct lines; review each prepared-component recipe too. Original missing-input notes are the export snapshot.
A7: Oil price/kg uses provisional 0.92 kg/L. Do not apply Top Milk to unspecified condensed milk.
A8: Source IDs and exact cell references are preserved in the comparison and source sheets.
A9: BAG-H2-01 uses a 40-piece pilot and 80-piece load. Its checked H2 model is carried unchanged in the H3 planner.
A10: H3: EDC is separate and unpriced. T01 and H05 are held, with usable yield and unit-cost calculation withdrawn. See EDC correction.

Sheet Prices
A1: Ingredient | B1: FCFA per kg editable | C1: Basis / specification
A2: Bread flour | B2: 420 | C2: Owner flour price; flour performance requires trial
A3: Water | C3: Purchase quote/specification required
A4: Sugar | B4: 640 | C4: Owner granulated sugar price; grind specification must match
A5: Margarine | B5: 1333.3333 | C5: Roma; fat, salt and application suitability unconfirmed
A6: Salt | B6: 194.44444 | C6: Owner price
A7: Yeast | B7: 1666.6667 | C7: Nevada instant dry; sweet-dough suitability requires trial
A8: Condensed milk | C8: Purchase quote/specification required
A9: Egg | C9: Purchase quote/specification required
A10: Whole milk powder | C10: Purchase quote/specification required
A11: Vanilla | C11: Purchase quote/specification required
A12: Sweet potato flour | C12: Purchase quote/specification required
A13: Nutmeg | C13: Purchase quote/specification required
A14: Plain flour | C14: Purchase quote/specification required
A15: Baking powder | C15: Purchase quote/specification required
A16: Canned fish drained | C16: Purchase quote/specification required
A17: Onion trimmed | C17: Purchase quote/specification required
A18: Carrot trimmed | C18: Purchase quote/specification required
A19: Oil | B19: 1413.0435 | C19: PROVISIONAL 0.92 kg/L; correct after weighing
A20: Garlic peeled | C20: Purchase quote/specification required
A21: Ginger peeled | C21: Purchase quote/specification required
A22: Black pepper | C22: Purchase quote/specification required
A23: Paprika | C23: Purchase quote/specification required
A24: Beef mince | C24: Purchase quote/specification required
A25: Potato peeled | C25: Purchase quote/specification required
A26: Thyme | C26: Purchase quote/specification required
A27: Curry powder | C27: Purchase quote/specification required
A28: Sausage meat | C28: Purchase quote/specification required
A29: Breadcrumbs | C29: Purchase quote/specification required
A30: Chicken boneless | C30: Purchase quote/specification required
A31: Pepper trimmed | C31: Purchase quote/specification required
... A71: Peanut roasted | C71: Purchase quote/specification required
A72: Nevada instant dry yeast | B72: 1666.6667 | C72: Nevada instant dry; sweet-dough suitability requires trial
A73: Margarine 80% | C73: Purchase quote/specification required
A74: Butter 82% | C74: Purchase quote/specification required
A75: Whole egg | C75: Purchase quote/specification required
A76: Whole milk 3.5% | C76: Purchase quote/specification required
A77: Desiccated coconut | C77: Purchase quote/specification required
A78: Banana pulp | C78: Purchase quote/specification required
A79: Raw beef mince | C79: Purchase quote/specification required
...

Sheet Ingredients
A1: Recipe ID | B1: Recipe | C1: Component | D1: Ingredient | E1: Pilot grams | F1: Commercial grams | G1: FCFA per kg | H1: Known extended FCFA | I1: Status / price basis | J1: Component reference
A2: O-B01 | B2: Family bread dough | C2: Main formula | D2: Bread flour | E2: 1000 | F2: 5000 | G2: =IF(Prices!B2="","",Prices!B2) | H2: =IF(G2="","",E2/1000*G2) | I2: Owner flour price; flour performance requires trial
A3: O-B01 | B3: Family bread dough | C3: Main formula | D3: Water | E3: 600 | F3: 3000 | G3: =IF(Prices!B3="","",Prices!B3) | H3: =IF(G3="","",E3/1000*G3) | I3: Purchase quote/specification required
A4: O-B01 | B4: Family bread dough | C4: Main formula | D4: Sugar | E4: 50 | F4: 250 | G4: =IF(Prices!B4="","",Prices!B4) | H4: =IF(G4="","",E4/1000*G4) | I4: Owner granulated sugar price; grind specification must match
A5: O-B01 | B5: Family bread dough | C5: Main formula | D5: Margarine | E5: 35 | F5: 175 | G5: =IF(Prices!B5="","",Prices!B5) | H5: =IF(G5="","",E5/1000*G5) | I5: Roma; fat, salt and application suitability unconfirmed
A6: O-B01 | B6: Family bread dough | C6: Main formula | D6: Salt | E6: 18 | F6: 90 | G6: =IF(Prices!B6="","",Prices!B6) | H6: =IF(G6="","",E6/1000*G6) | I6: Owner price
A7: O-B01 | B7: Family bread dough | C7: Main formula | D7: Yeast | E7: 12 | F7: 60 | G7: =IF(Prices!B7="","",Prices!B7) | H7: =IF(G7="","",E7/1000*G7) | I7: Nevada instant dry; sweet-dough suitability requires trial
A8: O-B02 | B8: Condensed milk bun dough | C8: Main formula | D8: Bread flour | E8: 1000 | F8: 5000 | G8: =IF(Prices!B2="","",Prices!B2) | H8: =IF(G8="","",E8/1000*G8) | I8: Owner flour price; flour performance requires trial
A9: O-B02 | B9: Condensed milk bun dough | C9: Main formula | D9: Water | E9: 430 | F9: 2150 | G9: =IF(Prices!B3="","",Prices!B3) | H9: =IF(G9="","",E9/1000*G9) | I9: Purchase quote/specification required
A10: O-B02 | B10: Condensed milk bun dough | C10: Main formula | D10: Condensed milk | E10: 150 | F10: 750 | G10: =IF(Prices!B8="","",Prices!B8) | H10: =IF(G10="","",E10/1000*G10) | I10: Purchase quote/specification required
A11: O-B02 | B11: Condensed milk bun dough | C11: Main formula | D11: Sugar | E11: 80 | F11: 400 | G11: =IF(Prices!B4="","",Prices!B4) | H11: =IF(G11="","",E11/1000*G11) | I11: Owner granulated sugar price; grind specification must match
A12: O-B02 | B12: Condensed milk bun dough | C12: Main formula | D12: Egg | E12: 100 | F12: 500 | G12: =IF(Prices!B9="","",Prices!B9) | H12: =IF(G12="","",E12/1000*G12) | I12: Purchase quote/specification required
A13: O-B02 | B13: Condensed milk bun dough | C13: Main formula | D13: Margarine | E13: 80 | F13: 400 | G13: =IF(Prices!B5="","",Prices!B5) | H13: =IF(G13="","",E13/1000*G13) | I13: Roma; fat, salt and application suitability unconfirmed
A14: O-B02 | B14: Condensed milk bun dough | C14: Main formula | D14: Whole milk powder | E14: 20 | F14: 100 | G14: =IF(Prices!B10="","",Prices!B10) | H14: =IF(G14="","",E14/1000*G14) | I14: Purchase quote/specification required
A15: O-B02 | B15: Condensed milk bun dough | C15: Main formula | D15: Salt | E15: 16 | F15: 80 | G15: =IF(Prices!B6="","",Prices!B6) | H15: =IF(G15="","",E15/1000*G15) | I15: Owner price
A16: O-B02 | B16: Condensed milk bun dough | C16: Main formula | D16: Yeast | E16: 15 | F16: 75 | G16: =IF(Prices!B7="","",Prices!B7) | H16: =IF(G16="","",E16/1000*G16) | I16: Nevada instant dry; sweet-dough suitability requires trial
A17: O-B02 | B17: Condensed milk bun dough | C17: Main formula | D17: Vanilla | E17: 4 | F17: 20 | G17: =IF(Prices!B11="","",Prices!B11) | H17: =IF(G17="","",E17/1000*G17) | I17: Purchase quote/specification required
A18: O-B03 | B18: Sweet potato milk bread dough | C18: Main formula | D18: Bread flour | E18: 850 | F18: 4250 | G18: =IF(Prices!B2="","",Prices!B2) | H18: =IF(G18="","",E18/1000*G18) | I18: Owner flour price; flour performance requires trial
A19: O-B03 | B19: Sweet potato milk bread dough | C19: Main formula | D19: Sweet potato flour | E19: 150 | F19: 750 | G19: =IF(Prices!B12="","",Prices!B12) | H19: =IF(G19="","",E19/1000*G19) | I19: Purchase quote/specification required
A20: O-B03 | B20: Sweet potato milk bread dough | C20: Main formula | D20: Water | E20: 570 | F20: 2850 | G20: =IF(Prices!B3="","",Prices!B3) | H20: =IF(G20="","",E20/1000*G20) | I20: Purchase quote/specification required
A21: O-B03 | B21: Sweet potato milk bread dough | C21: Main formula | D21: Condensed milk | E21: 100 | F21: 500 | G21: =IF(Prices!B8="","",Prices!B8) | H21: =IF(G21="","",E21/1000*G21) | I21: Purchase quote/specification required
A22: O-B03 | B22: Sweet potato milk bread dough | C22: Main formula | D22: Sugar | E22: 40 | F22: 200 | G22: =IF(Prices!B4="","",Prices!B4) | H22: =IF(G22="","",E22/1000*G22) | I22: Owner granulated sugar price; grind specification must match
A23: O-B03 | B23: Sweet potato milk bread dough | C23: Main formula | D23: Margarine | E23: 50 | F23: 250 | G23: =IF(Prices!B5="","",Prices!B5) | H23: =IF(G23="","",E23/1000*G23) | I23: Roma; fat, salt and application suitability unconfirmed
A24: O-B03 | B24: Sweet potato milk bread dough | C24: Main formula | D24: Whole milk powder | E24: 20 | F24: 100 | G24: =IF(Prices!B10="","",Prices!B10) | H24: =IF(G24="","",E24/1000*G24) | I24: Purchase quote/specification required
A25: O-B03 | B25: Sweet potato milk bread dough | C25: Main formula | D25: Salt | E25: 18 | F25: 90 | G25: =IF(Prices!B6="","",Prices!B6) | H25: =IF(G25="","",E25/1000*G25) | I25: Owner price
A26: O-B03 | B26: Sweet potato milk bread dough | C26: Main formula | D26: Yeast | E26: 14 | F26: 70 | G26: =IF(Prices!B7="","",Prices!B7) | H26: =IF(G26="","",E26/1000*G26) | I26: Nevada instant dry; sweet-dough suitability requires trial
A27: O-B04 | B27: Yeast doughnut dough | C27: Main formula | D27: Bread flour | E27: 1000 | F27: 5000 | G27: =IF(Prices!B2="","",Prices!B2) | H27: =IF(G27="","",E27/1000*G27) | I27: Owner flour price; flour performance requires trial
A28: O-B04 | B28: Yeast doughnut dough | C28: Main formula | D28: Water | E28: 440 | F28: 2200 | G28: =IF(Prices!B3="","",Prices!B3) | H28: =IF(G28="","",E28/1000*G28) | I28: Purchase quote/specification required
A29: O-B04 | B29: Yeast doughnut dough | C29: Main formula | D29: Egg | E29: 100 | F29: 500 | G29: =IF(Prices!B9="","",Prices!B9) | H29: =IF(G29="","",E29/1000*G29) | I29: Purchase quote/specification required
A30: O-B04 | B30: Yeast doughnut dough | C30: Main formula | D30: Sugar | E30: 120 | F30: 600 | G30: =IF(Prices!B4="","",Prices!B4) | H30: =IF(G30="","",E30/1000*G30) | I30: Owner granulated sugar price; grind specification must match
A31: O-B04 | B31: Yeast doughnut dough | C31: Main formula | D31: Margarine | E31: 80 | F31: 400 | G31: =IF(Prices!B5="","",Prices!B5) | H31: =IF(G31="","",E31/1000*G31) | I31: Roma; fat, salt and application suitability unconfirmed
A32: O-B04 | B32: Yeast doughnut dough | C32: Main formula | D32: Whole milk powder | E32: 30 | F32: 150 | G32: =IF(Prices!B10="","",Prices!B10) | H32: =IF(G32="","",E32/1000*G32) | I32: Purchase quote/specification required
A33: O-B04 | B33: Yeast doughnut dough | C33: Main formula | D33: Salt | E33: 15 | F33: 75 | G33: =IF(Prices!B6="","",Prices!B6) | H33: =IF(G33="","",E33/1000*G33) | I33: Owner price
A34: O-B04 | B34: Yeast doughnut dough | C34: Main formula | D34: Yeast | E34: 18 | F34: 90 | G34: =IF(Prices!B7="","",Prices!B7) | H34: =IF(G34="","",E34/1000*G34) | I34: Nevada instant dry; sweet-dough suitability requires trial
A35: O-B04 | B35: Yeast doughnut dough | C35: Main formula | D35: Nutmeg | E35: 2 | F35: 10 | G35: =IF(Prices!B13="","",Prices!B13) | H35: =IF(G35="","",E35/1000*G35) | I35: Purchase quote/specification required
A36: O-B04 | B36: Yeast doughnut dough | C36: Main formula | D36: Vanilla | E36: 3 | F36: 15 | G36: =IF(Prices!B11="","",Prices!B11) | H36: =IF(G36="","",E36/1000*G36) | I36: Purchase quote/specification required
A37: O-B05 | B37: Puff puff batter | C37: Main formula | D37: Plain flour | E37: 1000 | F37: 5000 | G37: =IF(Prices!B14="","",Prices!B14) | H37: =IF(G37="","",E37/1000*G37) | I37: Purchase quote/specification required
A38: O-B05 | B38: Puff puff batter | C38: Main formula | D38: Water | E38: 700 | F38: 3500 | G38: =IF(Prices!B3="","",Prices!B3) | H38: =IF(G38="","",E38/1000*G38) | I38: Purchase quote/specification required
A39: O-B05 | B39: Puff puff batter | C39: Main formula | D39: Sugar | E39: 120 | F39: 600 | G39: =IF(Prices!B4="","",Prices!B4) | H39: =IF(G39="","",E39/1000*G39) | I39: Owner granulated sugar price; grind specification must match
A40: O-B05 | B40: Puff puff batter | C40: Main formula | D40: Salt | E40: 12 | F40: 60 | G40: =IF(Prices!B6="","",Prices!B6) | H40: =IF(G40="","",E40/1000*G40) | I40: Owner price
...

Sheet Summary
A1: ID | B1: Recipe | C1: Input grams | D1: Usable basis grams | E1: Planned units | F1: Known ingredient subtotal | G1: Missing price line count | H1: Complete variable batch cost INPUT | I1: Selling price INPUT | J1: Full cost per unit | K1: Contribution per unit | L1: Original missing inputs
A2: O-B01 | B2: Family bread dough | C2: 1715 | D2: 1700 | F2: =SUMIF(Ingredients!A:A,A2,Ingredients!H:H) | G2: =COUNTIFS(Ingredients!A:A,A2,Ingredients!G:G,"") | J2: =IF(OR(H2="",E2="",E2=0),"",H2/E2) | K2: =IF(OR(J2="",I2=""),"",I2-J2) | L2: Water
A3: O-B02 | B3: Condensed milk bun dough | C3: 1895 | D3: 1870 | F3: =SUMIF(Ingredients!A:A,A3,Ingredients!H:H) | G3: =COUNTIFS(Ingredients!A:A,A3,Ingredients!G:G,"") | J3: =IF(OR(H3="",E3="",E3=0),"",H3/E3) | K3: =IF(OR(J3="",I3=""),"",I3-J3) | L3: Condensed milk; Egg; Vanilla; Water; Whole milk powder
A4: O-B03 | B4: Sweet potato milk bread dough | C4: 1812 | D4: 1790 | F4: =SUMIF(Ingredients!A:A,A4,Ingredients!H:H) | G4: =COUNTIFS(Ingredients!A:A,A4,Ingredients!G:G,"") | J4: =IF(OR(H4="",E4="",E4=0),"",H4/E4) | K4: =IF(OR(J4="",I4=""),"",I4-J4) | L4: Condensed milk; Sweet potato flour; Water; Whole milk powder
A5: O-B04 | B5: Yeast doughnut dough | C5: 1808 | D5: 1780 | F5: =SUMIF(Ingredients!A:A,A5,Ingredients!H:H) | G5: =COUNTIFS(Ingredients!A:A,A5,Ingredients!G:G,"") | J5: =IF(OR(H5="",E5="",E5=0),"",H5/E5) | K5: =IF(OR(J5="",I5=""),"",I5-J5) | L5: Egg; Nutmeg; Vanilla; Water; Whole milk powder
A6: O-B05 | B6: Puff puff batter | C6: 1846 | D6: 1830 | F6: =SUMIF(Ingredients!A:A,A6,Ingredients!H:H) | G6: =COUNTIFS(Ingredients!A:A,A6,Ingredients!G:G,"") | J6: =IF(OR(H6="",E6="",E6=0),"",H6/E6) | K6: =IF(OR(J6="",I6=""),"",I6-J6) | L6: Nutmeg; Plain flour; Water
A7: O-B06 | B7: Fish roll dough | C7: 1679 | D7: 1660 | F7: =SUMIF(Ingredients!A:A,A7,Ingredients!H:H) | G7: =COUNTIFS(Ingredients!A:A,A7,Ingredients!G:G,"") | J7: =IF(OR(H7="",E7="",E7=0),"",H7/E7) | K7: =IF(OR(J7="",I7=""),"",I7-J7) | L7: Nutmeg; Plain flour; Water; Whole milk powder
A8: O-B07 | B8: Shortcrust pie pastry | C8: 1773 | D8: 1740 | F8: =SUMIF(Ingredients!A:A,A8,Ingredients!H:H) | G8: =COUNTIFS(Ingredients!A:A,A8,Ingredients!G:G,"") | J8: =IF(OR(H8="",E8="",E8=0),"",H8/E8) | K8: =IF(OR(J8="",I8=""),"",I8-J8) | L8: Baking powder; Egg; Plain flour; Water
A9: O-B08 | B9: Fish filling | C9: 783 | D9: 700 | F9: =SUMIF(Ingredients!A:A,A9,Ingredients!H:H) | G9: =COUNTIFS(Ingredients!A:A,A9,Ingredients!G:G,"") | J9: =IF(OR(H9="",E9="",E9=0),"",H9/E9) | K9: =IF(OR(J9="",I9=""),"",I9-J9) | L9: Black pepper; Canned fish drained; Carrot trimmed; Garlic peeled; Ginger peeled; Onion trimmed; Paprika
A10: O-B09 | B10: Beef pie filling | C10: 1506 | D10: 1300 | F10: =SUMIF(Ingredients!A:A,A10,Ingredients!H:H) | G10: =COUNTIFS(Ingredients!A:A,A10,Ingredients!G:G,"") | J10: =IF(OR(H10="",E10="",E10=0),"",H10/E10) | K10: =IF(OR(J10="",I10=""),"",I10-J10) | L10: Beef mince; Black pepper; Carrot trimmed; Curry powder; Garlic peeled; Ginger peeled; Onion trimmed; Plain flour; Potato peeled; Thyme; Water
A11: O-B10 | B11: Sausage roll filling | C11: 1000 | D11: 980 | F11: =SUMIF(Ingredients!A:A,A11,Ingredients!H:H) | G11: =COUNTIFS(Ingredients!A:A,A11,Ingredients!G:G,"") | J11: =IF(OR(H11="",E11="",E11=0),"",H11/E11) | K11: =IF(OR(J11="",I11=""),"",I11-J11) | L11: Black pepper; Breadcrumbs; Egg; Garlic peeled; Onion trimmed; Paprika; Sausage meat
A12: O-B11 | B12: Creamy chicken filling | C12: 1502 | D12: 1300 | F12: =SUMIF(Ingredients!A:A,A12,Ingredients!H:H) | G12: =COUNTIFS(Ingredients!A:A,A12,Ingredients!G:G,"") | J12: =IF(OR(H12="",E12="",E12=0),"",H12/E12) | K12: =IF(OR(J12="",I12=""),"",I12-J12) | L12: Black pepper; Carrot trimmed; Chicken boneless; Garlic peeled; Onion trimmed; Pepper trimmed; Plain flour; Potato peeled; Thyme; UHT milk; Water
A13: O-B12 | B13: Egg roll dough | C13: 1674 | D13: 1650 | F13: =SUMIF(Ingredients!A:A,A13,Ingredients!H:H) | G13: =COUNTIFS(Ingredients!A:A,A13,Ingredients!G:G,"") | J13: =IF(OR(H13="",E13="",E13=0),"",H13/E13) | K13: =IF(OR(J13="",I13=""),"",I13-J13) | L13: Nutmeg; Plain flour; Water; Whole milk powder
... A37: O-B36 | B37: lemon-garlic oven fish | C37: 1081 | D37: 800 | F37: =SUMIF(Ingredients!A:A,A37,Ingredients!H:H) | G37: =COUNTIFS(Ingredients!A:A,A37,Ingredients!G:G,"") | J37: =IF(OR(H37="",E37="",E37=0),"",H37/E37) | K37: =IF(OR(J37="",I37=""),"",I37-J37) | L37: Black pepper; Boneless trimmed white fish; Garlic, finely crushed; Lemon juice; Paprika
A38: O-P01 | B38: Soft family bread | C38: 1700 | D38: 1700 | E38: 3 | F38: =SUMIF(Ingredients!A:A,A38,Ingredients!H:H) | G38: =COUNTIFS(Ingredients!A:A,A38,Ingredients!G:G,"") | J38: =IF(OR(H38="",E38="",E38=0),"",H38/E38) | K38: =IF(OR(J38="",I38=""),"",I38-J38) | L38: O-B01: Water
A39: O-P02 | B39: Condensed milk breakfast buns | C39: 1910 | D39: 1910 | E39: 20 | F39: =SUMIF(Ingredients!A:A,A39,Ingredients!H:H) | G39: =COUNTIFS(Ingredients!A:A,A39,Ingredients!G:G,"") | J39: =IF(OR(H39="",E39="",E39=0),"",H39/E39) | K39: =IF(OR(J39="",I39=""),"",I39-J39) | L39: Egg; O-B02: Condensed milk; O-B02: Egg; O-B02: Vanilla; O-B02: Water; O-B02: Whole milk powder
A40: O-P03 | B40: Nkambe sweet potato milk loaf | C40: 1790 | D40: 1790 | E40: 3 | F40: =SUMIF(Ingredients!A:A,A40,Ingredients!H:H) | G40: =COUNTIFS(Ingredients!A:A,A40,Ingredients!G:G,"") | J40: =IF(OR(H40="",E40="",E40=0),"",H40/E40) | K40: =IF(OR(J40="",I40=""),"",I40-J40) | L40: O-B03: Condensed milk; O-B03: Sweet potato flour; O-B03: Water; O-B03: Whole milk powder
A41: O-P04 | B41: Sugar ring doughnuts | C41: 2100 | D41: 2100 | E41: 25 | F41: =SUMIF(Ingredients!A:A,A41,Ingredients!H:H) | G41: =COUNTIFS(Ingredients!A:A,A41,Ingredients!G:G,"") | J41: =IF(OR(H41="",E41="",E41=0),"",H41/E41) | K41: =IF(OR(J41="",I41=""),"",I41-J41) | L41: O-B04: Egg; O-B04: Nutmeg; O-B04: Vanilla; O-B04: Water; O-B04: Whole milk powder
A42: O-P05 | B42: Puff puff | C42: 2010 | D42: 2010 | E42: 60 | F42: =SUMIF(Ingredients!A:A,A42,Ingredients!H:H) | G42: =COUNTIFS(Ingredients!A:A,A42,Ingredients!G:G,"") | J42: =IF(OR(H42="",E42="",E42=0),"",H42/E42) | K42: =IF(OR(J42="",I42=""),"",I42-J42) | L42: O-B05: Nutmeg; O-B05: Plain flour; O-B05: Water
A43: O-P06 | B43: Cameroon style fish rolls | C43: 2440 | D43: 2440 | E43: 24 | F43: =SUMIF(Ingredients!A:A,A43,Ingredients!H:H) | G43: =COUNTIFS(Ingredients!A:A,A43,Ingredients!G:G,"") | J43: =IF(OR(H43="",E43="",E43=0),"",H43/E43) | K43: =IF(OR(J43="",I43=""),"",I43-J43) | L43: O-B06: Nutmeg; O-B06: Plain flour; O-B06: Water; O-B06: Whole milk powder; O-B08: Black pepper; O-B08: Canned fish drained; O-B08: Carrot trimmed; O-B08: Garlic peeled; O-B08: Ginger peeled; O-B08: Onion trimmed; O-B08: Paprika
A44: O-P07 | B44: Beef meat pies | C44: 2885 | D44: 2885 | E44: 22 | F44: =SUMIF(Ingredients!A:A,A44,Ingredients!H:H) | G44: =COUNTIFS(Ingredients!A:A,A44,Ingredients!G:G,"") | J44: =IF(OR(H44="",E44="",E44=0),"",H44/E44) | K44: =IF(OR(J44="",I44=""),"",I44-J44) | L44: Egg; O-B07: Baking powder; O-B07: Egg; O-B07: Plain flour; O-B07: Water; O-B09: Beef mince; O-B09: Black pepper; O-B09: Carrot trimmed; O-B09: Curry powder; O-B09: Garlic peeled; O-B09: Ginger peeled; O-B09: Onion trimmed; O-B09: Plain flour; O-B09: Potato peeled; O-B09: Thyme; O-B09: Water
A45: O-P08 | B45: Sausage rolls | C45: 2745 | D45: 2745 | E45: 24 | F45: =SUMIF(Ingredients!A:A,A45,Ingredients!H:H) | G45: =COUNTIFS(Ingredients!A:A,A45,Ingredients!G:G,"") | J45: =IF(OR(H45="",E45="",E45=0),"",H45/E45) | K45: =IF(OR(J45="",I45=""),"",I45-J45) | L45: Egg; O-B07: Baking powder; O-B07: Egg; O-B07: Plain flour; O-B07: Water; O-B10: Black pepper; O-B10: Breadcrumbs; O-B10: Egg; O-B10: Garlic peeled; O-B10: Onion trimmed; O-B10: Paprika; O-B10: Sausage meat
A46: O-P09 | B46: Creamy chicken pies | C46: 3045 | D46: 3045 | E46: 21 | F46: =SUMIF(Ingredients!A:A,A46,Ingredients!H:H) | G46: =COUNTIFS(Ingredients!A:A,A46,Ingredients!G:G,"") | J46: =IF(OR(H46="",E46="",E46=0),"",H46/E46) | K46: =IF(OR(J46="",I46=""),"",I46-J46) | L46: Egg; O-B07: Baking powder; O-B07: Egg; O-B07: Plain flour; O-B07: Water; O-B11: Black pepper; O-B11: Carrot trimmed; O-B11: Chicken boneless; O-B11: Garlic peeled; O-B11: Onion trimmed; O-B11: Pepper trimmed; O-B11: Plain flour; O-B11: Potato peeled; O-B11: Thyme; O-B11: UHT milk; O-B11: Water
A47: O-P10 | B47: Whole egg dough rolls | C47: 2630 | D47: 2630 | E47: 16 | F47: =SUMIF(Ingredients!A:A,A47,Ingredients!H:H) | G47: =COUNTIFS(Ingredients!A:A,A47,Ingredients!G:G,"") | J47: =IF(OR(H47="",E47="",E47=0),"",H47/E47) | K47: =IF(OR(J47="",I47=""),"",I47-J47) | L47: O-B12: Nutmeg; O-B12: Plain flour; O-B12: Water; O-B12: Whole milk powder; O-B13: Egg
A48: O-P11 | B48: Banana condensed milk cake slices | C48: 3010 | D48: 3010 | E48: 24 | F48: =SUMIF(Ingredients!A:A,A48,Ingredients!H:H) | G48: =COUNTIFS(Ingredients!A:A,A48,Ingredients!G:G,"") | J48: =IF(OR(H48="",E48="",E48=0),"",H48/E48) | K48: =IF(OR(J48="",I48=""),"",I48-J48) | L48: O-B14: Baking powder; O-B14: Baking soda; O-B14: Banana peeled; O-B14: Cinnamon; O-B14: Condensed milk; O-B14: Egg; O-B14: Plain flour; O-B14: Vanilla
A49: O-P12 | B49: Personal chicken pizza | C49: 3450 | D49: 3450 | E49: 11 | F49: =SUMIF(Ingredients!A:A,A49,Ingredients!H:H) | G49: =COUNTIFS(Ingredients!A:A,A49,Ingredients!G:G,"") | J49: =IF(OR(H49="",E49="",E49=0),"",H49/E49) | K49: =IF(OR(J49="",I49=""),"",I49-J49) | L49: Mozzarella; O-B15: Water; O-B16: Black pepper; O-B16: Garlic peeled; O-B16: Onion trimmed; O-B16: Oregano; O-B16: Tomato trimmed; O-B18: Black pepper; O-B18: Chicken boneless; O-B18: Chili trimmed; O-B18: Cinnamon; O-B18: Coriander; O-B18: Cumin; O-B18: Garlic peeled; O-B18: Lemon juice; O-B18: Paprika; O-B18: Vinegar 5%; O-B18: Yogurt plain; Onion trimmed; Pepper trimmed
... A61: O-A04 | B61: Beef mini pizza — ten-unit pilot | C61: 3126.3158 | D61: 3126.3158 | E61: 10 | F61: =SUMIF(Ingredients!A:A,A61,Ingredients!H:H) | G61: =COUNTIFS(Ingredients!A:A,A61,Ingredients!G:G,"") | J61: =IF(OR(H61="",E61="",E61=0),"",H61/E61) | K61: =IF(OR(J61="",I61=""),"",I61-J61) | L61: Mozzarella; O-B15: Water; O-B16: Black pepper; O-B16: Garlic peeled; O-B16: Onion trimmed; O-B16: Oregano; O-B16: Tomato trimmed; O-B19: Beef boneless; O-B19: Black pepper; O-B19: Cinnamon; O-B19: Coriander; O-B19: Cumin; O-B19: Garlic peeled; O-B19: Lemon juice; O-B19: Onion trimmed; O-B19: Paprika; O-B19: Vinegar 5%; Onion; Sweet pepper
A62: O-FBASE1 | B62: Gravity soft serve vanilla trial mix | C62: 1000 | D62: 970 | F62: =SUMIF(Ingredients!A:A,A62,Ingredients!H:H) | G62: =COUNTIFS(Ingredients!A:A,A62,Ingredients!G:G,"") | J62: =IF(OR(H62="",E62="",E62=0),"",H62/E62) | K62: =IF(OR(J62="",I62=""),"",I62-J62) | L62: Condensed milk; Cream 35%; Glucose powder; Ice cream stabilizer blend; Skim milk powder; UHT milk; Vanilla
A63: O-FBASE2 | B63: Vanilla condensed milk popsicle mix | C63: 1000 | D63: 970 | F63: =SUMIF(Ingredients!A:A,A63,Ingredients!H:H) | G63: =COUNTIFS(Ingredients!A:A,A63,Ingredients!G:G,"") | J63: =IF(OR(H63="",E63="",E63=0),"",H63/E63) | K63: =IF(OR(J63="",I63=""),"",I63-J63) | L63: Condensed milk; Cream 35%; Ice cream stabilizer blend; Skim milk powder; UHT milk; Vanilla
A64: O-FBASE3 | B64: Pineapple fruit ice mix | C64: 1000 | D64: 970 | F64: =SUMIF(Ingredients!A:A,A64,Ingredients!H:H) | G64: =COUNTIFS(Ingredients!A:A,A64,Ingredients!G:G,"") | J64: =IF(OR(H64="",E64="",E64=0),"",H64/E64) | K64: =IF(OR(J64="",I64=""),"",I64-J64) | L64: Glucose powder; Ice cream stabilizer blend; Lemon juice; Pineapple puree pasteurized; Water
A65: O-FBASE4 | B65: Mango yogurt popsicle mix | C65: 1000 | D65: 970 | F65: =SUMIF(Ingredients!A:A,A65,Ingredients!H:H) | G65: =COUNTIFS(Ingredients!A:A,A65,Ingredients!G:G,"") | J65: =IF(OR(H65="",E65="",E65=0),"",H65/E65) | K65: =IF(OR(J65="",I65=""),"",I65-J65) | L65: Condensed milk; Ice cream stabilizer blend; Mango puree pasteurized; Water; Yogurt plain
A66: O-FBASE5 | B66: Chocolate sundae sauce | C66: 955 | D66: 900 | F66: =SUMIF(Ingredients!A:A,A66,Ingredients!H:H) | G66: =COUNTIFS(Ingredients!A:A,A66,Ingredients!G:G,"") | J66: =IF(OR(H66="",E66="",E66=0),"",H66/E66) | K66: =IF(OR(J66="",I66=""),"",I66-J66) | L66: Cocoa; Condensed milk; Vanilla; Water
A67: O-FBASE6 | B67: Soft sandwich cookies | C67: 1086 | D67: 900 | F67: =SUMIF(Ingredients!A:A,A67,Ingredients!H:H) | G67: =COUNTIFS(Ingredients!A:A,A67,Ingredients!G:G,"") | J67: =IF(OR(H67="",E67="",E67=0),"",H67/E67) | K67: =IF(OR(J67="",I67=""),"",I67-J67) | L67: Baking powder; Cocoa; Egg; Plain flour; Vanilla
A68: O-FBASE7 | B68: Chocolate dipping coating | C68: 1000 | D68: 980 | F68: =SUMIF(Ingredients!A:A,A68,Ingredients!H:H) | G68: =COUNTIFS(Ingredients!A:A,A68,Ingredients!G:G,"") | J68: =IF(OR(H68="",E68="",E68=0),"",H68/E68) | K68: =IF(OR(J68="",I68=""),"",I68-J68) | L68: Compound chocolate coating
A69: O-F01 | B69: Vanilla soft serve cup or cone | C69: 970 | D69: 970 | F69: =SUMIF(Ingredients!A:A,A69,Ingredients!H:H) | G69: =COUNTIFS(Ingredients!A:A,A69,Ingredients!G:G,"") | J69: =IF(OR(H69="",E69="",E69=0),"",H69/E69) | K69: =IF(OR(J69="",I69=""),"",I69-J69) | L69: O-FBASE1: Condensed milk; O-FBASE1: Cream 35%; O-FBASE1: Glucose powder; O-FBASE1: Ice cream stabilizer blend; O-FBASE1: Skim milk powder; O-FBASE1: UHT milk; O-FBASE1: Vanilla
A70: O-F02 | B70: Chocolate peanut sundae | C70: 750 | D70: 750 | F70: =SUMIF(Ingredients!A:A,A70,Ingredients!H:H) | G70: =COUNTIFS(Ingredients!A:A,A70,Ingredients!G:G,"") | J70: =IF(OR(H70="",E70="",E70=0),"",H70/E70) | K70: =IF(OR(J70="",I70=""),"",I70-J70) | L70: O-FBASE1: Condensed milk; O-FBASE1: Cream 35%; O-FBASE1: Glucose powder; O-FBASE1: Ice cream stabilizer blend; O-FBASE1: Skim milk powder; O-FBASE1: UHT milk; O-FBASE1: Vanilla; O-FBASE5: Cocoa; O-FBASE5: Condensed milk; O-FBASE5: Vanilla; O-FBASE5: Water; Peanut roasted
A71: O-F03 | B71: Chocolate milkshake | C71: 1450 | D71: 1450 | F71: =SUMIF(Ingredients!A:A,A71,Ingredients!H:H) | G71: =COUNTIFS(Ingredients!A:A,A71,Ingredients!G:G,"") | J71: =IF(OR(H71="",E71="",E71=0),"",H71/E71) | K71: =IF(OR(J71="",I71=""),"",I71-J71) | L71: O-FBASE1: Condensed milk; O-FBASE1: Cream 35%; O-FBASE1: Glucose powder; O-FBASE1: Ice cream stabilizer blend; O-FBASE1: Skim milk powder; O-FBASE1: UHT milk; O-FBASE1: Vanilla; O-FBASE5: Cocoa; O-FBASE5: Condensed milk; O-FBASE5: Vanilla; O-FBASE5: Water; UHT milk
A72: O-F04 | B72: Chocolate cookie ice cream sandwich | C72: 1100 | D72: 1100 | F72: =SUMIF(Ingredients!A:A,A72,Ingredients!H:H) | G72: =COUNTIFS(Ingredients!A:A,A72,Ingredients!G:G,"") | J72: =IF(OR(H72="",E72="",E72=0),"",H72/E72) | K72: =IF(OR(J72="",I72=""),"",I72-J72) | L72: O-FBASE1: Condensed milk; O-FBASE1: Cream 35%; O-FBASE1: Glucose powder; O-FBASE1: Ice cream stabilizer blend; O-FBASE1: Skim milk powder; O-FBASE1: UHT milk; O-FBASE1: Vanilla; O-FBASE6: Baking powder; O-FBASE6: Cocoa; O-FBASE6: Egg; O-FBASE6: Plain flour; O-FBASE6: Vanilla
A73: O-F05 | B73: Condensed milk popsicles | C73: 970 | D73: 970 | F73: =SUMIF(Ingredients!A:A,A73,Ingredients!H:H) | G73: =COUNTIFS(Ingredients!A:A,A73,Ingredients!G:G,"") | J73: =IF(OR(H73="",E73="",E73=0),"",H73/E73) | K73: =IF(OR(J73="",I73=""),"",I73-J73) | L73: O-FBASE2: Condensed milk; O-FBASE2: Cream 35%; O-FBASE2: Ice cream stabilizer blend; O-FBASE2: Skim milk powder; O-FBASE2: UHT milk; O-FBASE2: Vanilla
... A76: O-F08 | B76: Chocolate dipped peanut milk bar | C76: 890 | D76: 890 | F76: =SUMIF(Ingredients!A:A,A76,Ingredients!H:H) | G76: =COUNTIFS(Ingredients!A:A,A76,Ingredients!G:G,"") | J76: =IF(OR(H76="",E76="",E76=0),"",H76/E76) | K76: =IF(OR(J76="",I76=""),"",I76-J76) | L76: O-FBASE2: Condensed milk; O-FBASE2: Cream 35%; O-FBASE2: Ice cream stabilizer blend; O-FBASE2: Skim milk powder; O-FBASE2: UHT milk; O-FBASE2: Vanilla; O-FBASE7: Compound chocolate coating; Peanut roasted
...

Sheet Coverage
A1: ID | B1: Name | C1: Record type | D1: Source | E1: Locator | F1: Status | G1: Decision or issue
A2: O-B01 | B2: Family bread dough | C2: Working card | D2: S163 | E2: lines 186-212 | F2: Harmonized source formulation — production trial required | G2: Retain the specified source formula because its ingredients, process and component routing are more explicit than the earlier drafts. Replace obsolete costs; use Nevada for the named instant yeast at the stated trial dose. Keep true butter, skim powder, whole powder and sweetened condensed milk specifications separate from the owner’s stocked substitutes.
A3: O-B02 | B3: Condensed milk bun dough | C3: Working card | D3: S163 | E3: lines 213-243 | F3: Harmonized source formulation — production trial required | G3: Retain the specified source formula because its ingredients, process and component routing are more explicit than the earlier drafts. Replace obsolete costs; use Nevada for the named instant yeast at the stated trial dose. Keep true butter, skim powder, whole powder and sweetened condensed milk specifications separate from the owner’s stocked substitutes.
A4: O-B03 | B4: Sweet potato milk bread dough | C4: Working card | D4: S163 | E4: lines 244-273 | F4: Harmonized source formulation — production trial required | G4: Retain the specified source formula because its ingredients, process and component routing are more explicit than the earlier drafts. Replace obsolete costs; use Nevada for the named instant yeast at the stated trial dose. Keep true butter, skim powder, whole powder and sweetened condensed milk specifications separate from the owner’s stocked substitutes.
A5: O-B04 | B5: Yeast doughnut dough | C5: Working card | D5: S163 | E5: lines 274-304 | F5: Harmonized source formulation — production trial required | G5: Retain the specified source formula because its ingredients, process and component routing are more explicit than the earlier drafts. Replace obsolete costs; use Nevada for the named instant yeast at the stated trial dose. Keep true butter, skim powder, whole powder and sweetened condensed milk specifications separate from the owner’s stocked substitutes.
A6: O-B05 | B6: Puff puff batter | C6: Working card | D6: S163 | E6: lines 305-331 | F6: Harmonized source formulation — production trial required | G6: Retain the specified source formula because its ingredients, process and component routing are more explicit than the earlier drafts. Replace obsolete costs; use Nevada for the named instant yeast at the stated trial dose. Keep true butter, skim powder, whole powder and sweetened condensed milk specifications separate from the owner’s stocked substitutes.
A7: O-B06 | B7: Fish roll dough | C7: Working card | D7: S163 | E7: lines 332-360 | F7: Harmonized source formulation — production trial required | G7: Retain the specified source formula because its ingredients, process and component routing are more explicit than the earlier drafts. Replace obsolete costs; use Nevada for the named instant yeast at the stated trial dose. Keep true butter, skim powder, whole powder and sweetened condensed milk specifications separate from the owner’s stocked substitutes.
A8: O-B07 | B8: Shortcrust pie pastry | C8: Working card | D8: S163 | E8: lines 361-387 | F8: Harmonized source formulation — production trial required | G8: Retain the specified source formula because its ingredients, process and component routing are more explicit than the earlier drafts. Replace obsolete costs; use Nevada for the named instant yeast at the stated trial dose. Keep true butter, skim powder, whole powder and sweetened condensed milk specifications separate from the owner’s stocked substitutes.
A9: O-B08 | B9: Fish filling | C9: Working card | D9: S163 | E9: lines 388-415 | F9: Harmonized source formulation — production trial required | G9: Retain the specified source formula because its ingredients, process and component routing are more explicit than the earlier drafts. Replace obsolete costs; use Nevada for the named instant yeast at the stated trial dose. Keep true butter, skim powder, whole powder and sweetened condensed milk specifications separate from the owner’s stocked substitutes.
A10: O-B09 | B10: Beef pie filling | C10: Working card | D10: S163 | E10: lines 416-447 | F10: Harmonized source formulation — production trial required | G10: Retain the specified source formula because its ingredients, process and component routing are more explicit than the earlier drafts. Replace obsolete costs; use Nevada for the named instant yeast at the stated trial dose. Keep true butter, skim powder, whole powder and sweetened condensed milk specifications separate from the owner’s stocked substitutes.
A11: O-B10 | B11: Sausage roll filling | C11: Working card | D11: S163 | E11: lines 448-474 | F11: Harmonized source formulation — production trial required | G11: Retain the specified source formula because its ingredients, process and component routing are more explicit than the earlier drafts. Replace obsolete costs; use Nevada for the named instant yeast at the stated trial dose. Keep true butter, skim powder, whole powder and sweetened condensed milk specifications separate from the owner’s stocked substitutes.
A12: O-B11 | B12: Creamy chicken filling | C12: Working card | D12: S163 | E12: lines 475-506 | F12: Harmonized source formulation — production trial required | G12: Retain the specified source formula because its ingredients, process and component routing are more explicit than the earlier drafts. Replace obsolete costs; use Nevada for the named instant yeast at the stated trial dose. Keep true butter, skim powder, whole powder and sweetened condensed milk specifications separate from the owner’s stocked substitutes.
... A797: PLAN-BAG-H | B797: 800 raw-piece campaign | C797: Production scenario | D797: S038; S026; S027 | E797: H2 baguette planning chapter | F797: Conditional proposed programme | G797: Not an additional recipe; resources and times require commissioning

Sheet Original formulas
A1: Variant ID | B1: Sheet | C1: Source | D1: Cell | E1: Ingredient | F1: Original g | G1: Cell value/formula | H1: Working alternative
A2: L001 | B2: Baguette AI | C2: S132 | D2: 'Baguette AI'!C5,D5 | E2: flour | F2: 18000 | G2: 18000 | H2: M1-B12 / M1-B13 / S-B01
A3: L001 | B3: Baguette AI | C3: S132 | D3: 'Baguette AI'!C6,D6 | E3: yeast | F3: 100 | G3: 100 | H3: M1-B12 / M1-B13 / S-B01
A4: L001 | B4: Baguette AI | C4: S132 | D4: 'Baguette AI'!C7,D7 | E4: salt | F4: 350 | G4: 350 | H4: M1-B12 / M1-B13 / S-B01
A5: L001 | B5: Baguette AI | C5: S132 | D5: 'Baguette AI'!C8,D8 | E5: ice water | F5: 12000 | G5: 12000 | H5: M1-B12 / M1-B13 / S-B01
A6: L001 | B6: Baguette AI | C6: S132 | D6: 'Baguette AI'!C9,D9 | E6: improver | F6: 70 | G6: 70 | H6: M1-B12 / M1-B13 / S-B01
A7: L002 | B7: Baguette AI | C7: S132 | D7: 'Baguette AI'!C5,F5 | E7: flour | F7: 350 | G7: 350 | H7: M1-B12 / M1-B13 / S-B01
A8: L002 | B8: Baguette AI | C8: S132 | D8: 'Baguette AI'!C6,F6 | E8: yeast | F8: 2 | G8: 2 | H8: M1-B12 / M1-B13 / S-B01
A9: L002 | B9: Baguette AI | C9: S132 | D9: 'Baguette AI'!C7,F7 | E9: salt | F9: 10 | G9: 10 | H9: M1-B12 / M1-B13 / S-B01
A10: L002 | B10: Baguette AI | C10: S132 | D10: 'Baguette AI'!C8,F8 | E10: ice water | F10: 210 | G10: 210 | H10: M1-B12 / M1-B13 / S-B01
A11: L002 | B11: Baguette AI | C11: S132 | D11: 'Baguette AI'!C9,F9 | E11: improver | F11: 20 | G11: 20 | H11: M1-B12 / M1-B13 / S-B01
A12: L003 | B12: Banh Mi | C12: S132 | D12: 'Banh Mi'!C5,D5 | E12: flour | F12: 120000 | G12: =F5*20 [cached: 120000] | H12: M1-B13; distinct Banh Mi trial remains open
A13: L003 | B13: Banh Mi | C13: S132 | D13: 'Banh Mi'!C6,D6 | E13: yeast | F13: 1800 | G13: =F6*20 [cached: 1800] | H13: M1-B13; distinct Banh Mi trial remains open
... A2411: L254 | B2411: YUMMY YOGHOURT (YUYO) | C2411: S143 | D2411: 'YUMMY YOGHOURT (YUYO)'!C9,L9 | E2411: vanilla | F2411: 37.5 | G2411: =F9/10 [cached: 37.5] | H2411: S-Y01–S-Y03

Sheet Issues
A1: ID | B1: Issue class | C1: Finding | D1: Required action
A2: O-B01 | B2: Production validation | C2: No signed repeat-batch evidence supplied | D2: Record three independent trials, quality, yield, safety and full cost before release
A3: O-B02 | B3: Production validation | C3: No signed repeat-batch evidence supplied | D3: Record three independent trials, quality, yield, safety and full cost before release
A4: O-B03 | B4: Production validation | C4: No signed repeat-batch evidence supplied | D4: Record three independent trials, quality, yield, safety and full cost before release
A5: O-B04 | B5: Production validation | C5: No signed repeat-batch evidence supplied | D5: Record three independent trials, quality, yield, safety and full cost before release
A6: O-B05 | B6: Production validation | C6: No signed repeat-batch evidence supplied | D6: Record three independent trials, quality, yield, safety and full cost before release
A7: O-B06 | B7: Production validation | C7: No signed repeat-batch evidence supplied | D7: Record three independent trials, quality, yield, safety and full cost before release
A8: O-B07 | B8: Production validation | C8: No signed repeat-batch evidence supplied | D8: Record three independent trials, quality, yield, safety and full cost before release
A9: O-B08 | B9: Production validation | C9: No signed repeat-batch evidence supplied | D9: Record three independent trials, quality, yield, safety and full cost before release
A10: O-B09 | B10: Production validation | C10: No signed repeat-batch evidence supplied | D10: Record three independent trials, quality, yield, safety and full cost before release
A11: O-B10 | B11: Production validation | C11: No signed repeat-batch evidence supplied | D11: Record three independent trials, quality, yield, safety and full cost before release
A12: O-B11 | B12: Production validation | C12: No signed repeat-batch evidence supplied | D12: Record three independent trials, quality, yield, safety and full cost before release
... A815: H05 | B815: EDC identity correction | C815: S132 Danisa lists 9,000 g workbook butter and 50 g EDC per 18 kg flour. Roma margarine is 500 g and EDC is 2.7778 g per 1 kg flour. Other rounded H2 inputs are retained. The former 503 g margarine combined and rounded two different ingredients. EDC is not butter and must not be treated or priced as margarine. Its identity, specification, permitted application, dose and purchase price remain unresolved. Keep EDC as a separate historical ingredient and hold affected formulas until it is identified. The earlier owner-workbook butter-to-margarine instruction remains separate; true dairy butter in independent recipes retains its specification. Milk tantalizer and improver remain omitted from revised recipes. | D815: Hold recipe; identify EDC and complete method and cost

Sheet Sources
A1: Source ID | B1: Title | C1: Full path | D1: Format | E1: Modified date | F1: Bytes | G1: SHA256 | H1: Readability/disposition | I1: Role | J1: Production-test evidence | K1: Language screening | L1: Stated version | M1: Extraction extent
A2: S001 | B2: bakery_strategy_and_recipe_manual_updated.pdf | C2: C:\Users\J COMPUTER\Documents\Codex\2026-09-12\x20-go\docs\bakery\bakery_strategy_and_recipe_manual_updated.pdf | D2: .pdf | E2: 2026-09-12T17:07:02.777893+00:00 | F2: 113921 | G2: 74c7cccf472d4b37c1cb045a39225838a2f871d2451ae2183124f64ab6f6c93f | H2: Extracted text | I2: Related edition, supporting context or superseded source; no independent trial inferred | J2: No owner production trial log found | K2: English (text screening) | L2: No explicit version established; modified date is file metadata only | M2: 10 extracted pages/blocks/rows; 72 recipe keyword signals (not recipe count)
A3: S002 | B3: bakery_strategy_and_recipe_manual.md | C3: C:\Users\J COMPUTER\Documents\Codex\2026-09-12\x20-go\outputs\bakery_strategy_and_recipe_manual.md | D3: .md | E3: 2026-09-12T17:02:51.066689+00:00 | F3: 41737 | G3: dbba9e528b1c8f3130bf52762b5f2e5e0f0c06fbb2155e33a80814eb0bb78713 | H3: Extracted text | I3: Related edition, supporting context or superseded source; no independent trial inferred | J3: No owner production trial log found | K3: English (text screening) | L3: No explicit version established; modified date is file metadata only | M3: 797 extracted pages/blocks/rows; 60 recipe keyword signals (not recipe count)
B4: bakery_strategy_and_recipe_manual.docx | C4: C:\Users\J COMPUTER\Documents\Codex\2026-09-12\x20-go\work\bakery_strategy_and_recipe_manual.docx | D4: .docx | E4: 2026-09-12T17:06:54.130905+00:00 | F4: 59173 | H4: Generated work or software support file | I4: Filename screened | J4: No owner production trial log found | K4: Not established / non-text | L4: No explicit version established; modified date is file metadata only | M4: extracted pages/blocks/rows; recipe keyword signals (not recipe count)
B5: bakery_strategy_and_recipe_manual.pdf | C5: C:\Users\J COMPUTER\Documents\Codex\2026-09-12\x20-go\work\rendered_manual\bakery_strategy_and_recipe_manual.pdf | D5: .pdf | E5: 2026-09-12T17:07:02.777893+00:00 | F5: 113921 | H5: Generated work or software support file | I5: Filename screened | J5: No owner production trial log found | K5: Not established / non-text | L5: No explicit version established; modified date is file metadata only | M5: extracted pages/blocks/rows; recipe keyword signals (not recipe count)
A6: S003 | B6: bakery_strategy_and_recipe_manual.md | C6: C:\Users\J COMPUTER\Documents\Codex\2026-09-12\x20-using-this-document-download-the\docs\bakery\bakery_strategy_and_recipe_manual.md | D6: .md | E6: 2026-09-13T12:08:59.616137+00:00 | F6: 79733 | G6: 4b982269e1d209a62ba8a1800c1b5d847cec607f75b9ea2dde4485121509da08 | H6: Extracted text | I6: Related edition, supporting context or superseded source; no independent trial inferred | J6: No owner production trial log found | K6: English (text screening) | L6: No explicit version established; modified date is file metadata only | M6: 1146 extracted pages/blocks/rows; 95 recipe keyword signals (not recipe count)
A7: S004 | B7: bakery_strategy_and_recipe_manual.pdf | C7: C:\Users\J COMPUTER\Documents\Codex\2026-09-12\x20-using-this-document-download-the\docs\bakery\bakery_strategy_and_recipe_manual.pdf | D7: .pdf | E7: 2026-09-13T12:20:16.996575+00:00 | F7: 312562 | G7: 095af6506a0ddc0d20a6a3cf2e718e609f8fa2def8d26f99a97c75bba7c05746 | H7: Extracted text | I7: Related edition, supporting context or superseded source; no independent trial inferred | J7: No owner production trial log found | K7: English (text screening) | L7: No explicit version established; modified date is file metadata only | M7: 45 extracted pages/blocks/rows; 171 recipe keyword signals (not recipe count)
A8: S005 | B8: Equipment_Gaps_and_Trial_Plan.md | C8: C:\Users\J COMPUTER\Documents\Codex\2026-09-12\x20-using-this-document-download-the\docs\bakery\Equipment_Gaps_and_Trial_Plan.md | D8: .md | E8: 2026-09-13T21:16:23.614072+00:00 | F8: 11936 | G8: 887013ce03097c8cd0e2d559dd8b6f369f6a6e0827b8b35a7aecfa2807f4036a | H8: Extracted text | I8: Related edition, supporting context or superseded source; no independent trial inferred | J8: No owner production trial log found | K8: English (text screening) | L8: No explicit version established; modified date is file metadata only | M8: 74 extracted pages/blocks/rows; 15 recipe keyword signals (not recipe count)
A9: S006 | B9: Nkambe_Bakery_Strategy_and_Recipe_Manual.md | C9: C:\Users\J COMPUTER\Documents\Codex\2026-09-12\x20-using-this-document-download-the\docs\bakery\Nkambe_Bakery_Strategy_and_Recipe_Manual.md | D9: .md | E9: 2026-09-14T14:11:17.347165+00:00 | F9: 215633 | G9: c2449e2d412be100e03097e99d865502306b185c2ac475686f0bdd05aee806aa | H9: Extracted text | I9: Related edition, supporting context or superseded source; no independent trial inferred | J9: No owner production trial log found | K9: English (text screening) | L9: No explicit version established; modified date is file metadata only | M9: 2697 extracted pages/blocks/rows; 375 recipe keyword signals (not recipe count)
A10: S007 | B10: Nkambe_Bakery_Strategy_and_Recipe_Manual.pdf | C10: C:\Users\J COMPUTER\Documents\Codex\2026-09-12\x20-using-this-document-download-the\docs\bakery\Nkambe_Bakery_Strategy_and_Recipe_Manual.pdf | D10: .pdf | E10: 2026-09-14T14:11:36.397636+00:00 | F10: 428291 | G10: 1ff70f54a43346e89057c30486c799af12e845502adaa43fd3ebfc20cf5d24e9 | H10: Extracted text | I10: Related edition, supporting context or superseded source; no independent trial inferred | J10: No owner production trial log found | K10: English (text screening) | L10: No explicit version established; modified date is file metadata only | M10: 89 extracted pages/blocks/rows; 466 recipe keyword signals (not recipe count)
A11: S008 | B11: Product_Selection_and_Costing.xlsx | C11: C:\Users\J COMPUTER\Documents\Codex\2026-09-12\x20-using-this-document-download-the\docs\bakery\Product_Selection_and_Costing.xlsx | D11: .xlsx | E11: 2026-09-13T21:02:47.391404+00:00 | F11: 75646 | G11: 5935cf2783344af2e6912671a4edd7fdc04d241e00487c5cc048fff60c471587 | H11: Extracted text | I11: Related edition, supporting context or superseded source; no independent trial inferred | J11: No owner production trial log found | K11: English (text screening) | L11: No explicit version established; modified date is file metadata only | M11: 631 extracted pages/blocks/rows; 40 recipe keyword signals (not recipe count)
A12: S005 | B12: Equipment_Gaps_and_Trial_Plan.md | C12: C:\Users\J COMPUTER\Documents\Codex\2026-09-12\x20-using-this-document-download-the\docs\bakery\research-edition\Equipment_Gaps_and_Trial_Plan.md | D12: .md | E12: 2026-09-13T21:16:23.614072+00:00 | F12: 11936 | G12: 887013ce03097c8cd0e2d559dd8b6f369f6a6e0827b8b35a7aecfa2807f4036a | H12: Exact duplicate | I12: Related edition, supporting context or superseded source; no independent trial inferred | J12: No owner production trial log found | K12: English (text screening) | L12: No explicit version established; modified date is file metadata only | M12: extracted pages/blocks/rows; recipe keyword signals (not recipe count)
A13: S006 | B13: Nkambe_Bakery_Strategy_and_Recipe_Manual.md | C13: C:\Users\J COMPUTER\Documents\Codex\2026-09-12\x20-using-this-document-download-the\docs\bakery\research-edition\Nkambe_Bakery_Strategy_and_Recipe_Manual.md | D13: .md | E13: 2026-09-14T14:11:17.347165+00:00 | F13: 215633 | G13: c2449e2d412be100e03097e99d865502306b185c2ac475686f0bdd05aee806aa | H13: Exact duplicate | I13: Related edition, supporting context or superseded source; no independent trial inferred | J13: No owner production trial log found | K13: English (text screening) | L13: No explicit version established; modified date is file metadata only | M13: extracted pages/blocks/rows; recipe keyword signals (not recipe count)
A14: S007 | B14: Nkambe_Bakery_Strategy_and_Recipe_Manual.pdf | C14: C:\Users\J COMPUTER\Documents\Codex\2026-09-12\x20-using-this-document-download-the\docs\bakery\research-edition\Nkambe_Bakery_Strategy_and_Recipe_Manual.pdf | D14: .pdf | E14: 2026-09-14T14:11:36.397636+00:00 | F14: 428291 | G14: 1ff70f54a43346e89057c30486c799af12e845502adaa43fd3ebfc20cf5d24e9 | H14: Exact duplicate | I14: Related edition, supporting context or superseded source; no independent trial inferred | J14: No owner production trial log found | K14: English (text screening) | L14: No explicit version established; modified date is file metadata only | M14: extracted pages/blocks/rows; recipe keyword signals (not recipe count)
A15: S009 | B15: Product_Selection_and_Costing.xlsx | C15: C:\Users\J COMPUTER\Documents\Codex\2026-09-12\x20-using-this-document-download-the\docs\bakery\research-edition\Product_Selection_and_Costing.xlsx | D15: .xlsx | E15: 2026-09-14T20:11:44.845456+00:00 | F15: 87464 | G15: 692365afec02ade7ab75bf2a2534a6f3cbea000009b7b7dcb95679ccd4bffa68 | H15: Extracted text | I15: Related edition, supporting context or superseded source; no independent trial inferred | J15: No owner production trial log found | K15: English (text screening) | L15: No explicit version established; modified date is file metadata only | M15: 631 extracted pages/blocks/rows; 40 recipe keyword signals (not recipe count)
A16: S010 | B16: Research_Sources_and_Evidence.md | C16: C:\Users\J COMPUTER\Documents\Codex\2026-09-12\x20-using-this-document-download-the\docs\bakery\research-edition\Research_Sources_and_Evidence.md | D16: .md | E16: 2026-09-14T14:11:17.375622+00:00 | F16: 15552 | G16: c4931fb1f6acb269edc18f1a2fb642bc594bbc4ccb0afb48898ec35a34bf9041 | H16: Extracted text | I16: Related edition, supporting context or superseded source; no independent trial inferred | J16: No owner production trial log found | K16: English (text screening) | L16: No explicit version established; modified date is file metadata only | M16: 292 extracted pages/blocks/rows; 7 recipe keyword signals (not recipe count)
A17: S011 | B17: Revision_and_Verification_Report.md | C17: C:\Users\J COMPUTER\Documents\Codex\2026-09-12\x20-using-this-document-download-the\docs\bakery\research-edition\Revision_and_Verification_Report.md | D17: .md | E17: 2026-09-14T14:13:48.143033+00:00 | F17: 14340 | G17: 6cb443dad8899af30c5d089ae1b9ce5e1ed2790a9d28e3f5004054d79a3107a3 | H17: Extracted text | I17: Related edition, supporting context or superseded source; no independent trial inferred | J17: No owner production trial log found | K17: English (text screening) | L17: No explicit version established; modified date is file metadata only | M17: 85 extracted pages/blocks/rows; 22 recipe keyword signals (not recipe count)
... A19: S011 | B19: Revision_and_Verification_Report.md | C19: C:\Users\J COMPUTER\Documents\Codex\2026-09-12\x20-using-this-document-download-the\docs\bakery\Revision_and_Verification_Report.md | D19: .md | E19: 2026-09-14T14:13:48.143033+00:00 | F19: 14340 | G19: 6cb443dad8899af30c5d089ae1b9ce5e1ed2790a9d28e3f5004054d79a3107a3 | H19: Exact duplicate | I19: Related edition, supporting context or superseded source; no independent trial inferred | J19: No owner production trial log found | K19: English (text screening) | L19: No explicit version established; modified date is file metadata only | M19: extracted pages/blocks/rows; recipe keyword signals (not recipe count)
B20: bakery_manual_before_redesign.pdf | C20: C:\Users\J COMPUTER\Documents\Codex\2026-09-12\x20-using-this-document-download-the\work\bakery_design_review\bakery_manual_before_redesign.pdf | D20: .pdf | E20: 2026-09-13T12:09:27.201531+00:00 | F20: 160616 | H20: Generated work or software support file | I20: Filename screened | J20: No owner production trial log found | K20: Not established / non-text | L20: No explicit version established; modified date is file metadata only | M20: extracted pages/blocks/rows; recipe keyword signals (not recipe count)
B21: bakery_strategy_and_recipe_manual.pdf | C21: C:\Users\J COMPUTER\Documents\Codex\2026-09-12\x20-using-this-document-download-the\work\bakery_design_review\bakery_strategy_and_recipe_manual.pdf | D21: .pdf | E21: 2026-09-13T12:20:16.996575+00:00 | F21: 312562 | H21: Generated work or software support file | I21: Filename screened | J21: No owner production trial log found | K21: Not established / non-text | L21: No explicit version established; modified date is file metadata only | M21: extracted pages/blocks/rows; recipe keyword signals (not recipe count)
B22: contact_1.jpg | C22: C:\Users\J COMPUTER\Documents\Codex\2026-09-12\x20-using-this-document-download-the\work\bakery_design_review\contact_1.jpg | D22: .jpg | E22: 2026-09-13T12:20:20.239397+00:00 | F22: 184113 | H22: Generated work or software support file | I22: Filename screened | J22: No owner production trial log found | K22: Not established / non-text | L22: No explicit version established; modified date is file metadata only | M22: extracted pages/blocks/rows; recipe keyword signals (not recipe count)
B23: contact_2.jpg | C23: C:\Users\J COMPUTER\Documents\Codex\2026-09-12\x20-using-this-document-download-the\work\bakery_design_review\contact_2.jpg | D23: .jpg | E23: 2026-09-13T12:20:20.252282+00:00 | F23: 221509 | H23: Generated work or software support file | I23: Filename screened | J23: No owner production trial log found | K23: Not established / non-text | L23: No explicit version established; modified date is file metadata only | M23: extracted pages/blocks/rows; recipe keyword signals (not recipe count)
B24: contact_3.jpg | C24: C:\Users\J COMPUTER\Documents\Codex\2026-09-12\x20-using-this-document-download-the\work\bakery_design_review\contact_3.jpg | D24: .jpg | E24: 2026-09-13T12:20:20.261636+00:00 | F24: 262077 | H24: Generated work or software support file | I24: Filename screened | J24: No owner production trial log found | K24: Not established / non-text | L24: No explicit version established; modified date is file metadata only | M24: extracted pages/blocks/rows; recipe keyword signals (not recipe count)
B25: contact_4.jpg | C25: C:\Users\J COMPUTER\Documents\Codex\2026-09-12\x20-using-this-document-download-the\work\bakery_design_review\contact_4.jpg | D25: .jpg | E25: 2026-09-13T12:20:20.280204+00:00 | F25: 163483 | H25: Generated work or software support file | I25: Filename screened | J25: No owner production trial log found | K25: Not established / non-text | L25: No explicit version established; modified date is file metadata only | M25: extracted pages/blocks/rows; recipe keyword signals (not recipe count)
B26: contact_5.jpg | C26: C:\Users\J COMPUTER\Documents\Codex\2026-09-12\x20-using-this-document-download-the\work\bakery_design_review\contact_5.jpg | D26: .jpg | E26: 2026-09-13T12:16:36.370112+00:00 | F26: 83177 | H26: Generated work or software support file | I26: Filename screened | J26: No owner production trial log found | K26: Not established / non-text | L26: No explicit version established; modified date is file metadata only | M26: extracted pages/blocks/rows; recipe keyword signals (not recipe count)
B27: page_01.png | C27: C:\Users\J COMPUTER\Documents\Codex\2026-09-12\x20-using-this-document-download-the\work\bakery_design_review\page_01.png | D27: .png | E27: 2026-09-13T12:20:18.003646+00:00 | F27: 107700 | H27: Generated work or software support file | I27: Filename screened | J27: No owner production trial log found | K27: Not established / non-text | L27: No explicit version established; modified date is file metadata only | M27: extracted pages/blocks/rows; recipe keyword signals (not recipe count)
B28: page_02.png | C28: C:\Users\J COMPUTER\Documents\Codex\2026-09-12\x20-using-this-document-download-the\work\bakery_design_review\page_02.png | D28: .png | E28: 2026-09-13T12:20:18.048571+00:00 | F28: 101258 | H28: Generated work or software support file | I28: Filename screened | J28: No owner production trial log found | K28: Not established / non-text | L28: No explicit version established; modified date is file metadata only | M28: extracted pages/blocks/rows; recipe keyword signals (not recipe count)
B29: page_03.png | C29: C:\Users\J COMPUTER\Documents\Codex\2026-09-12\x20-using-this-document-download-the\work\bakery_design_review\page_03.png | D29: .png | E29: 2026-09-13T12:20:18.100704+00:00 | F29: 102723 | H29: Generated work or software support file | I29: Filename screened | J29: No owner production trial log found | K29: Not established / non-text | L29: No explicit version established; modified date is file metadata only | M29: extracted pages/blocks/rows; recipe keyword signals (not recipe count)
B30: page_04.png | C30: C:\Users\J COMPUTER\Documents\Codex\2026-09-12\x20-using-this-document-download-the\work\bakery_design_review\page_04.png | D30: .png | E30: 2026-09-13T12:20:18.147408+00:00 | F30: 101540 | H30: Generated work or software support file | I30: Filename screened | J30: No owner production trial log found | K30: Not established / non-text | L30: No explicit version established; modified date is file metadata only | M30: extracted pages/blocks/rows; recipe keyword signals (not recipe count)
B31: page_05.png | C31: C:\Users\J COMPUTER\Documents\Codex\2026-09-12\x20-using-this-document-download-the\work\bakery_design_review\page_05.png | D31: .png | E31: 2026-09-13T12:20:18.198012+00:00 | F31: 163772 | H31: Generated work or software support file | I31: Filename screened | J31: No owner production trial log found | K31: Not established / non-text | L31: No explicit version established; modified date is file metadata only | M31: extracted pages/blocks/rows; recipe keyword signals (not recipe count)
... B86: Staggered_Baguette_Production_Schedule.pdf.txt | C86: C:\Users\J COMPUTER\Documents\Codex\2026-09-12\x20-using-this-document-download-the\work\research_review\Staggered_Baguette_Production_Schedule.pdf.txt | D86: .txt | E86: 2026-09-13T20:38:03.592762+00:00 | F86: 3833 | H86: Generated work or software support file | I86: Filename screened | J86: No owner production trial log found | K86: Not established / non-text | L86: No explicit version established; modified date is file metadata only | M86: extracted pages/blocks/rows; recipe keyword signals (not recipe count)
A87: S012 | B87: Nkambe_Bakery_Business_Report_Partial.pdf | C87: C:\Users\J COMPUTER\Documents\Codex\2026-10-01\referenced-chatgpt-conversation-this-is-an\outputs\Nkambe_Bakery_Business_Report_Partial.pdf | D87: .pdf | E87: 2026-10-03T09:28:58.150452+00:00 | F87: 140585 | G87: 92619ed7f32b4f682ed206490adf5e7aff3eed8588b4511bd938dd8ea0067ca5 | H87: Extracted text | I87: Related edition, supporting context or superseded source; no independent trial inferred | J87: No owner production trial log found | K87: English (text screening) | L87: No explicit version established; modified date is file metadata only | M87: 21 extracted pages/blocks/rows; 45 recipe keyword signals (not recipe count)
A88: S013 | B88: Nkambe_Bakery_Product_Development_and_Profitability_Strategy.pdf | C88: C:\Users\J COMPUTER\Documents\Codex\2026-10-08\referenced-chatgpt-conversation-this-is-an-2\outputs\Nkambe_Bakery_Product_Development_and_Profitability_Strategy.pdf | D88: .pdf | E88: 2026-10-08T12:08:08.212843+00:00 | F88: 118715 | G88: e8f97c198f48cc035c0576d1a468fb627c37ddc51d0f8658281053a950ac8b84 | H88: Extracted text | I88: Recipe source or technical context included | J88: No owner production trial log found | K88: English (text screening) | L88: No explicit version established; modified date is file metadata only | M88: 20 extracted pages/blocks/rows; 14 recipe keyword signals (not recipe count)
A89: S014 | B89: Nkambe_Recipe_Manual_Module_1_Breads_and_Baguettes.pdf | C89: C:\Users\J COMPUTER\Documents\Codex\2026-10-08\referenced-chatgpt-conversation-this-is-an-2\outputs\Nkambe_Recipe_Manual_Module_1_Breads_and_Baguettes.pdf | D89: .pdf | E89: 2026-10-08T16:19:26.752118+00:00 | F89: 255392 | G89: febe5a7bf8d9cea610fec8a88ad2c460e2b05ae840503f43cdaa2108825f62b6 | H89: Extracted text | I89: Related edition, supporting context or superseded source; no independent trial inferred | J89: No owner production trial log found | K89: English (text screening) | L89: Version 0.1 | M89: 58 extracted pages/blocks/rows; 476 recipe keyword signals (not recipe count)
