Workbook

Sheet Read me
A1: NKAMBE BAGUETTE PRODUCTION PLANNER H2
A2: 8 October 2026 — local bakery clock times; all programmes require commissioning
A3: Blue-font cells are inputs. Default timing and capacities are assumptions, not installed-equipment certification.
A4: Use BAG-H2-01 only: 100 flour / 66 water / 2 salt / 0.5 instant yeast, baker percentages.
A5: Changing Inputs or Scenarios recalculates stage clocks, yields, capacity gates and vehicle sequencing when opened in Excel.
A6: One batch is one oven load. For 4 pieces/tray, reduce pieces per batch to 64; the fit gate rejects an 80-piece batch.
A7: Scenarios accepts 1–20 batches; each schedule contains 20 rows. Rows beyond the selected batch count stay blank.
A8: The fit gate checks the model, not actual dough readiness, staff, electrical loads or commissioning.
A9: Proof bay count and rack sets are editable ASSUMPTIONS until physically confirmed. Field release remains open.
A10: The 15-minute portion rest overlaps FIFO division/moulding. Do not insert a second full-batch pause without revising the model.
A11: Time columns are Excel time fractions; [h]:mm permits schedules after midnight without hiding elapsed days.
A12: Costing blanks mean unknown. Enter 0 only for a confirmed zero cost. Full cost and contribution remain blank until required fields are filled.
... A16: Read the Baguette Production Planning H2 PDF and C01–C05 in the anthology before trials.

Sheet Inputs
A1: Parameter | B1: Editable value | C1: Unit / basis | D1: Evidence status
A2: Raw piece | B2: 300 | C2: g | D2: Provisional model input; field check required
A3: Handling loss | B3: 0.01 | C3: fraction | D3: Provisional model input; field check required
A4: Bake loss illustration | B4: 0.15 | C4: fraction | D4: Provisional model input; field check required
A5: Reject allowance | B5: 0.02 | C5: fraction, rounded up per batch | D5: Provisional model input; field check required
A6: Water baker ratio | B6: 0.66 | C6: fraction of flour | D6: Provisional model input; field check required
A7: Salt baker ratio | B7: 0.02 | C7: fraction of flour | D7: Provisional model input; field check required
A8: Nevada instant yeast ratio | B8: 0.005 | C8: fraction of flour | D8: Provisional model input; field check required
A9: First mix start | B9: 140 | C9: minutes after midnight: 140 = 02:20 | D9: Provisional model input; field check required
A10: Mix/rest occupancy | B10: 18 | C10: min | D10: Provisional model input; field check required
A11: Bulk fermentation | B11: 45 | C11: min, dough endpoint governs | D11: Provisional model input; field check required
A12: Division/preshape | B12: 15 | C12: min | D12: Provisional model input; field check required
A13: Mould and rack loading | B13: 15 | C13: min; individual FIFO rest about 15 min | D13: Provisional model input; field check required
... A39: Nevada yeast price | B39: 1666.6667 | C39: FCFA/kg, owner quote | D39: Owner price

Sheet Scenarios
A1: ID | B1: Batches INPUT | C1: Pieces/batch INPUT | D1: Cadence min INPUT | E1: Flour g/batch | F1: Water g/batch | G1: Salt g/batch | H1: Yeast g/batch | I1: Input g/batch | J1: After handling g | K1: Whole raw pieces | L1: Allocated pieces | M1: Leftover g | N1: Rejects/batch | O1: Retained/batch | P1: Campaign raw | Q1: Campaign retained | R1: Known campaign FCFA | S1: Oven reservation min | T1: Proof bays needed | U1: Rack sets needed | V1: Cool/pack positions | W1: Arithmetic capacity gate
A2: PLAN-BAG-P | B2: 2 | C2: 40 | D2: 90 | E2: =ROUNDUP(C2*Inputs!$B$2/(1-Inputs!$B$3)/(1+Inputs!$B$6+Inputs!$B$7+Inputs!$B$8),0) -> 7194 | F2: =ROUND(E2*Inputs!$B$6,0) -> 4748 | G2: =ROUND(E2*Inputs!$B$7,1) -> 143.9 | H2: =ROUND(E2*Inputs!$B$8,1) -> 36 | I2: =SUM(E2:H2) -> 12121.9 | J2: =I2*(1-Inputs!$B$3) -> 12000.681 | K2: =ROUNDDOWN(J2/Inputs!$B$2,0) -> 40 | L2: =MIN(C2,K2) -> 40 | M2: =J2-L2*Inputs!$B$2 -> 0.681 | N2: =ROUNDUP(L2*Inputs!$B$5,0) -> 1 | O2: =MAX(0,L2-N2) -> 39 | P2: =B2*L2 -> 80 | Q2: =B2*O2 -> 78 | R2: =B2*(E2*Inputs!$B$37+G2*Inputs!$B$38+H2*Inputs!$B$39)/1000 -> 6218.9211 | S2: =Inputs!$B$15+Inputs!$B$16+Inputs!$B$17+Inputs!$B$18 -> 40 | T2: =MIN(B2,ROUNDUP((Inputs!$B$14+Inputs!$B$22)/D2,0)) -> 1 | U2: =MIN(B2,ROUNDUP((Inputs!$B$13+Inputs!$B$14+Inputs!$B$15+Inputs!$B$16+Inputs!$B$17+Inputs!$B$19+Inputs!$B$20+Inputs!$B$21)/D2,0)) -> 2 | V2: =MIN(B2,ROUNDUP((Inputs!$B$19+Inputs!$B$20)/D2,0)) -> 1 | W2: =IF(AND(B2>=1,B2<=20,B2=INT(B2),C2>0,C2=INT(C2),C2<=Inputs!$B$31*Inputs!$B$32,D2>=S2,D2>=Inputs!$B$23+Inputs!$B$10+Inputs!$B$24,D2>=Inputs!$B$12+Inputs!$B$25,D2>=Inputs!$B$13+Inputs!$B$25,T2<=Inputs!$B$33,U2<=Inputs!$B$34,V2<=Inputs!$B$35),"MODEL FITS - FIELD GATES OPEN","REPLAN / INVALID INPUT") -> MODEL FITS - FIELD GATES OPEN
A3: PLAN-BAG-N | B3: 5 | C3: 80 | D3: 45 | E3: =ROUNDUP(C3*Inputs!$B$2/(1-Inputs!$B$3)/(1+Inputs!$B$6+Inputs!$B$7+Inputs!$B$8),0) -> 14388 | F3: =ROUND(E3*Inputs!$B$6,0) -> 9496 | G3: =ROUND(E3*Inputs!$B$7,1) -> 287.8 | H3: =ROUND(E3*Inputs!$B$8,1) -> 71.9 | I3: =SUM(E3:H3) -> 24243.7 | J3: =I3*(1-Inputs!$B$3) -> 24001.263 | K3: =ROUNDDOWN(J3/Inputs!$B$2,0) -> 80 | L3: =MIN(C3,K3) -> 80 | M3: =J3-L3*Inputs!$B$2 -> 1.263 | N3: =ROUNDUP(L3*Inputs!$B$5,0) -> 2 | O3: =MAX(0,L3-N3) -> 78 | P3: =B3*L3 -> 400 | Q3: =B3*O3 -> 390 | R3: =B3*(E3*Inputs!$B$37+G3*Inputs!$B$38+H3*Inputs!$B$39)/1000 -> 31093.772 | S3: =Inputs!$B$15+Inputs!$B$16+Inputs!$B$17+Inputs!$B$18 -> 40 | T3: =MIN(B3,ROUNDUP((Inputs!$B$14+Inputs!$B$22)/D3,0)) -> 2 | U3: =MIN(B3,ROUNDUP((Inputs!$B$13+Inputs!$B$14+Inputs!$B$15+Inputs!$B$16+Inputs!$B$17+Inputs!$B$19+Inputs!$B$20+Inputs!$B$21)/D3,0)) -> 4 | V3: =MIN(B3,ROUNDUP((Inputs!$B$19+Inputs!$B$20)/D3,0)) -> 2 | W3: =IF(AND(B3>=1,B3<=20,B3=INT(B3),C3>0,C3=INT(C3),C3<=Inputs!$B$31*Inputs!$B$32,D3>=S3,D3>=Inputs!$B$23+Inputs!$B$10+Inputs!$B$24,D3>=Inputs!$B$12+Inputs!$B$25,D3>=Inputs!$B$13+Inputs!$B$25,T3<=Inputs!$B$33,U3<=Inputs!$B$34,V3<=Inputs!$B$35),"MODEL FITS - FIELD GATES OPEN","REPLAN / INVALID INPUT") -> MODEL FITS - FIELD GATES OPEN
A4: PLAN-BAG-H | B4: 10 | C4: 80 | D4: 45 | E4: =ROUNDUP(C4*Inputs!$B$2/(1-Inputs!$B$3)/(1+Inputs!$B$6+Inputs!$B$7+Inputs!$B$8),0) -> 14388 | F4: =ROUND(E4*Inputs!$B$6,0) -> 9496 | G4: =ROUND(E4*Inputs!$B$7,1) -> 287.8 | H4: =ROUND(E4*Inputs!$B$8,1) -> 71.9 | I4: =SUM(E4:H4) -> 24243.7 | J4: =I4*(1-Inputs!$B$3) -> 24001.263 | K4: =ROUNDDOWN(J4/Inputs!$B$2,0) -> 80 | L4: =MIN(C4,K4) -> 80 | M4: =J4-L4*Inputs!$B$2 -> 1.263 | N4: =ROUNDUP(L4*Inputs!$B$5,0) -> 2 | O4: =MAX(0,L4-N4) -> 78 | P4: =B4*L4 -> 800 | Q4: =B4*O4 -> 780 | R4: =B4*(E4*Inputs!$B$37+G4*Inputs!$B$38+H4*Inputs!$B$39)/1000 -> 62187.544 | S4: =Inputs!$B$15+Inputs!$B$16+Inputs!$B$17+Inputs!$B$18 -> 40 | T4: =MIN(B4,ROUNDUP((Inputs!$B$14+Inputs!$B$22)/D4,0)) -> 2 | U4: =MIN(B4,ROUNDUP((Inputs!$B$13+Inputs!$B$14+Inputs!$B$15+Inputs!$B$16+Inputs!$B$17+Inputs!$B$19+Inputs!$B$20+Inputs!$B$21)/D4,0)) -> 4 | V4: =MIN(B4,ROUNDUP((Inputs!$B$19+Inputs!$B$20)/D4,0)) -> 2 | W4: =IF(AND(B4>=1,B4<=20,B4=INT(B4),C4>0,C4=INT(C4),C4<=Inputs!$B$31*Inputs!$B$32,D4>=S4,D4>=Inputs!$B$23+Inputs!$B$10+Inputs!$B$24,D4>=Inputs!$B$12+Inputs!$B$25,D4>=Inputs!$B$13+Inputs!$B$25,T4<=Inputs!$B$33,U4<=Inputs!$B$34,V4<=Inputs!$B$35),"MODEL FITS - FIELD GATES OPEN","REPLAN / INVALID INPUT") -> MODEL FITS - FIELD GATES OPEN

Sheet Pilot schedule
A1: PLAN-BAG-P / BAG-H2-01 / clocks depend on Inputs
A2: Batch | B2: Mix start | C2: Mix end | D2: Bulk end/divide start | E2: Divide end/mould start | F2: Mould end/proof start | G2: Proof end/score start | H2: Loading complete | I2: Bake end | J2: Unload complete | K2: Oven recovered | L2: Cooling complete | M2: Pack release | N2: Rack set free | O2: Proof bay
A3: =IF(1<=Scenarios!B2,1,"") -> 1 | B3: =IF(A3="","",(Inputs!$B$9+(A3-1)*Scenarios!D2)/1440) -> 0.097222222 | C3: =IF(A3="","",B3+Inputs!$B$10/1440) -> 0.10972222 | D3: =IF(A3="","",C3+Inputs!$B$11/1440) -> 0.14097222 | E3: =IF(A3="","",D3+Inputs!$B$12/1440) -> 0.15138889 | F3: =IF(A3="","",E3+Inputs!$B$13/1440) -> 0.16180556 | G3: =IF(A3="","",F3+Inputs!$B$14/1440) -> 0.20347222 | H3: =IF(A3="","",G3+Inputs!$B$15/1440) -> 0.21041667 | I3: =IF(A3="","",H3+Inputs!$B$16/1440) -> 0.22569444 | J3: =IF(A3="","",I3+Inputs!$B$17/1440) -> 0.22777778 | K3: =IF(A3="","",J3+Inputs!$B$18/1440) -> 0.23125 | L3: =IF(A3="","",J3+Inputs!$B$19/1440) -> 0.25902778 | M3: =IF(A3="","",L3+Inputs!$B$20/1440) -> 0.26944444 | N3: =IF(A3="","",M3+Inputs!$B$21/1440) -> 0.27638889 | O3: =IF(A3="","",MOD(A3-1,Inputs!$B$33)+1) -> 1
A4: =IF(2<=Scenarios!B2,2,"") -> 2 | B4: =IF(A4="","",(Inputs!$B$9+(A4-1)*Scenarios!D2)/1440) -> 0.15972222 | C4: =IF(A4="","",B4+Inputs!$B$10/1440) -> 0.17222222 | D4: =IF(A4="","",C4+Inputs!$B$11/1440) -> 0.20347222 | E4: =IF(A4="","",D4+Inputs!$B$12/1440) -> 0.21388889 | F4: =IF(A4="","",E4+Inputs!$B$13/1440) -> 0.22430556 | G4: =IF(A4="","",F4+Inputs!$B$14/1440) -> 0.26597222 | H4: =IF(A4="","",G4+Inputs!$B$15/1440) -> 0.27291667 | I4: =IF(A4="","",H4+Inputs!$B$16/1440) -> 0.28819444 | J4: =IF(A4="","",I4+Inputs!$B$17/1440) -> 0.29027778 | K4: =IF(A4="","",J4+Inputs!$B$18/1440) -> 0.29375 | L4: =IF(A4="","",J4+Inputs!$B$19/1440) -> 0.32152778 | M4: =IF(A4="","",L4+Inputs!$B$20/1440) -> 0.33194444 | N4: =IF(A4="","",M4+Inputs!$B$21/1440) -> 0.33888889 | O4: =IF(A4="","",MOD(A4-1,Inputs!$B$33)+1) -> 2
A5: =IF(3<=Scenarios!B2,3,"") | B5: =IF(A5="","",(Inputs!$B$9+(A5-1)*Scenarios!D2)/1440) | C5: =IF(A5="","",B5+Inputs!$B$10/1440) | D5: =IF(A5="","",C5+Inputs!$B$11/1440) | E5: =IF(A5="","",D5+Inputs!$B$12/1440) | F5: =IF(A5="","",E5+Inputs!$B$13/1440) | G5: =IF(A5="","",F5+Inputs!$B$14/1440) | H5: =IF(A5="","",G5+Inputs!$B$15/1440) | I5: =IF(A5="","",H5+Inputs!$B$16/1440) | J5: =IF(A5="","",I5+Inputs!$B$17/1440) | K5: =IF(A5="","",J5+Inputs!$B$18/1440) | L5: =IF(A5="","",J5+Inputs!$B$19/1440) | M5: =IF(A5="","",L5+Inputs!$B$20/1440) | N5: =IF(A5="","",M5+Inputs!$B$21/1440) | O5: =IF(A5="","",MOD(A5-1,Inputs!$B$33)+1)
A6: =IF(4<=Scenarios!B2,4,"") | B6: =IF(A6="","",(Inputs!$B$9+(A6-1)*Scenarios!D2)/1440) | C6: =IF(A6="","",B6+Inputs!$B$10/1440) | D6: =IF(A6="","",C6+Inputs!$B$11/1440) | E6: =IF(A6="","",D6+Inputs!$B$12/1440) | F6: =IF(A6="","",E6+Inputs!$B$13/1440) | G6: =IF(A6="","",F6+Inputs!$B$14/1440) | H6: =IF(A6="","",G6+Inputs!$B$15/1440) | I6: =IF(A6="","",H6+Inputs!$B$16/1440) | J6: =IF(A6="","",I6+Inputs!$B$17/1440) | K6: =IF(A6="","",J6+Inputs!$B$18/1440) | L6: =IF(A6="","",J6+Inputs!$B$19/1440) | M6: =IF(A6="","",L6+Inputs!$B$20/1440) | N6: =IF(A6="","",M6+Inputs!$B$21/1440) | O6: =IF(A6="","",MOD(A6-1,Inputs!$B$33)+1)
A7: =IF(5<=Scenarios!B2,5,"") | B7: =IF(A7="","",(Inputs!$B$9+(A7-1)*Scenarios!D2)/1440) | C7: =IF(A7="","",B7+Inputs!$B$10/1440) | D7: =IF(A7="","",C7+Inputs!$B$11/1440) | E7: =IF(A7="","",D7+Inputs!$B$12/1440) | F7: =IF(A7="","",E7+Inputs!$B$13/1440) | G7: =IF(A7="","",F7+Inputs!$B$14/1440) | H7: =IF(A7="","",G7+Inputs!$B$15/1440) | I7: =IF(A7="","",H7+Inputs!$B$16/1440) | J7: =IF(A7="","",I7+Inputs!$B$17/1440) | K7: =IF(A7="","",J7+Inputs!$B$18/1440) | L7: =IF(A7="","",J7+Inputs!$B$19/1440) | M7: =IF(A7="","",L7+Inputs!$B$20/1440) | N7: =IF(A7="","",M7+Inputs!$B$21/1440) | O7: =IF(A7="","",MOD(A7-1,Inputs!$B$33)+1)
A8: =IF(6<=Scenarios!B2,6,"") | B8: =IF(A8="","",(Inputs!$B$9+(A8-1)*Scenarios!D2)/1440) | C8: =IF(A8="","",B8+Inputs!$B$10/1440) | D8: =IF(A8="","",C8+Inputs!$B$11/1440) | E8: =IF(A8="","",D8+Inputs!$B$12/1440) | F8: =IF(A8="","",E8+Inputs!$B$13/1440) | G8: =IF(A8="","",F8+Inputs!$B$14/1440) | H8: =IF(A8="","",G8+Inputs!$B$15/1440) | I8: =IF(A8="","",H8+Inputs!$B$16/1440) | J8: =IF(A8="","",I8+Inputs!$B$17/1440) | K8: =IF(A8="","",J8+Inputs!$B$18/1440) | L8: =IF(A8="","",J8+Inputs!$B$19/1440) | M8: =IF(A8="","",L8+Inputs!$B$20/1440) | N8: =IF(A8="","",M8+Inputs!$B$21/1440) | O8: =IF(A8="","",MOD(A8-1,Inputs!$B$33)+1)
A9: =IF(7<=Scenarios!B2,7,"") | B9: =IF(A9="","",(Inputs!$B$9+(A9-1)*Scenarios!D2)/1440) | C9: =IF(A9="","",B9+Inputs!$B$10/1440) | D9: =IF(A9="","",C9+Inputs!$B$11/1440) | E9: =IF(A9="","",D9+Inputs!$B$12/1440) | F9: =IF(A9="","",E9+Inputs!$B$13/1440) | G9: =IF(A9="","",F9+Inputs!$B$14/1440) | H9: =IF(A9="","",G9+Inputs!$B$15/1440) | I9: =IF(A9="","",H9+Inputs!$B$16/1440) | J9: =IF(A9="","",I9+Inputs!$B$17/1440) | K9: =IF(A9="","",J9+Inputs!$B$18/1440) | L9: =IF(A9="","",J9+Inputs!$B$19/1440) | M9: =IF(A9="","",L9+Inputs!$B$20/1440) | N9: =IF(A9="","",M9+Inputs!$B$21/1440) | O9: =IF(A9="","",MOD(A9-1,Inputs!$B$33)+1)
A10: =IF(8<=Scenarios!B2,8,"") | B10: =IF(A10="","",(Inputs!$B$9+(A10-1)*Scenarios!D2)/1440) | C10: =IF(A10="","",B10+Inputs!$B$10/1440) | D10: =IF(A10="","",C10+Inputs!$B$11/1440) | E10: =IF(A10="","",D10+Inputs!$B$12/1440) | F10: =IF(A10="","",E10+Inputs!$B$13/1440) | G10: =IF(A10="","",F10+Inputs!$B$14/1440) | H10: =IF(A10="","",G10+Inputs!$B$15/1440) | I10: =IF(A10="","",H10+Inputs!$B$16/1440) | J10: =IF(A10="","",I10+Inputs!$B$17/1440) | K10: =IF(A10="","",J10+Inputs!$B$18/1440) | L10: =IF(A10="","",J10+Inputs!$B$19/1440) | M10: =IF(A10="","",L10+Inputs!$B$20/1440) | N10: =IF(A10="","",M10+Inputs!$B$21/1440) | O10: =IF(A10="","",MOD(A10-1,Inputs!$B$33)+1)
A11: =IF(9<=Scenarios!B2,9,"") | B11: =IF(A11="","",(Inputs!$B$9+(A11-1)*Scenarios!D2)/1440) | C11: =IF(A11="","",B11+Inputs!$B$10/1440) | D11: =IF(A11="","",C11+Inputs!$B$11/1440) | E11: =IF(A11="","",D11+Inputs!$B$12/1440) | F11: =IF(A11="","",E11+Inputs!$B$13/1440) | G11: =IF(A11="","",F11+Inputs!$B$14/1440) | H11: =IF(A11="","",G11+Inputs!$B$15/1440) | I11: =IF(A11="","",H11+Inputs!$B$16/1440) | J11: =IF(A11="","",I11+Inputs!$B$17/1440) | K11: =IF(A11="","",J11+Inputs!$B$18/1440) | L11: =IF(A11="","",J11+Inputs!$B$19/1440) | M11: =IF(A11="","",L11+Inputs!$B$20/1440) | N11: =IF(A11="","",M11+Inputs!$B$21/1440) | O11: =IF(A11="","",MOD(A11-1,Inputs!$B$33)+1)
A12: =IF(10<=Scenarios!B2,10,"") | B12: =IF(A12="","",(Inputs!$B$9+(A12-1)*Scenarios!D2)/1440) | C12: =IF(A12="","",B12+Inputs!$B$10/1440) | D12: =IF(A12="","",C12+Inputs!$B$11/1440) | E12: =IF(A12="","",D12+Inputs!$B$12/1440) | F12: =IF(A12="","",E12+Inputs!$B$13/1440) | G12: =IF(A12="","",F12+Inputs!$B$14/1440) | H12: =IF(A12="","",G12+Inputs!$B$15/1440) | I12: =IF(A12="","",H12+Inputs!$B$16/1440) | J12: =IF(A12="","",I12+Inputs!$B$17/1440) | K12: =IF(A12="","",J12+Inputs!$B$18/1440) | L12: =IF(A12="","",J12+Inputs!$B$19/1440) | M12: =IF(A12="","",L12+Inputs!$B$20/1440) | N12: =IF(A12="","",M12+Inputs!$B$21/1440) | O12: =IF(A12="","",MOD(A12-1,Inputs!$B$33)+1)
A13: =IF(11<=Scenarios!B2,11,"") | B13: =IF(A13="","",(Inputs!$B$9+(A13-1)*Scenarios!D2)/1440) | C13: =IF(A13="","",B13+Inputs!$B$10/1440) | D13: =IF(A13="","",C13+Inputs!$B$11/1440) | E13: =IF(A13="","",D13+Inputs!$B$12/1440) | F13: =IF(A13="","",E13+Inputs!$B$13/1440) | G13: =IF(A13="","",F13+Inputs!$B$14/1440) | H13: =IF(A13="","",G13+Inputs!$B$15/1440) | I13: =IF(A13="","",H13+Inputs!$B$16/1440) | J13: =IF(A13="","",I13+Inputs!$B$17/1440) | K13: =IF(A13="","",J13+Inputs!$B$18/1440) | L13: =IF(A13="","",J13+Inputs!$B$19/1440) | M13: =IF(A13="","",L13+Inputs!$B$20/1440) | N13: =IF(A13="","",M13+Inputs!$B$21/1440) | O13: =IF(A13="","",MOD(A13-1,Inputs!$B$33)+1)
A14: =IF(12<=Scenarios!B2,12,"") | B14: =IF(A14="","",(Inputs!$B$9+(A14-1)*Scenarios!D2)/1440) | C14: =IF(A14="","",B14+Inputs!$B$10/1440) | D14: =IF(A14="","",C14+Inputs!$B$11/1440) | E14: =IF(A14="","",D14+Inputs!$B$12/1440) | F14: =IF(A14="","",E14+Inputs!$B$13/1440) | G14: =IF(A14="","",F14+Inputs!$B$14/1440) | H14: =IF(A14="","",G14+Inputs!$B$15/1440) | I14: =IF(A14="","",H14+Inputs!$B$16/1440) | J14: =IF(A14="","",I14+Inputs!$B$17/1440) | K14: =IF(A14="","",J14+Inputs!$B$18/1440) | L14: =IF(A14="","",J14+Inputs!$B$19/1440) | M14: =IF(A14="","",L14+Inputs!$B$20/1440) | N14: =IF(A14="","",M14+Inputs!$B$21/1440) | O14: =IF(A14="","",MOD(A14-1,Inputs!$B$33)+1)
A15: =IF(13<=Scenarios!B2,13,"") | B15: =IF(A15="","",(Inputs!$B$9+(A15-1)*Scenarios!D2)/1440) | C15: =IF(A15="","",B15+Inputs!$B$10/1440) | D15: =IF(A15="","",C15+Inputs!$B$11/1440) | E15: =IF(A15="","",D15+Inputs!$B$12/1440) | F15: =IF(A15="","",E15+Inputs!$B$13/1440) | G15: =IF(A15="","",F15+Inputs!$B$14/1440) | H15: =IF(A15="","",G15+Inputs!$B$15/1440) | I15: =IF(A15="","",H15+Inputs!$B$16/1440) | J15: =IF(A15="","",I15+Inputs!$B$17/1440) | K15: =IF(A15="","",J15+Inputs!$B$18/1440) | L15: =IF(A15="","",J15+Inputs!$B$19/1440) | M15: =IF(A15="","",L15+Inputs!$B$20/1440) | N15: =IF(A15="","",M15+Inputs!$B$21/1440) | O15: =IF(A15="","",MOD(A15-1,Inputs!$B$33)+1)
A16: =IF(14<=Scenarios!B2,14,"") | B16: =IF(A16="","",(Inputs!$B$9+(A16-1)*Scenarios!D2)/1440) | C16: =IF(A16="","",B16+Inputs!$B$10/1440) | D16: =IF(A16="","",C16+Inputs!$B$11/1440) | E16: =IF(A16="","",D16+Inputs!$B$12/1440) | F16: =IF(A16="","",E16+Inputs!$B$13/1440) | G16: =IF(A16="","",F16+Inputs!$B$14/1440) | H16: =IF(A16="","",G16+Inputs!$B$15/1440) | I16: =IF(A16="","",H16+Inputs!$B$16/1440) | J16: =IF(A16="","",I16+Inputs!$B$17/1440) | K16: =IF(A16="","",J16+Inputs!$B$18/1440) | L16: =IF(A16="","",J16+Inputs!$B$19/1440) | M16: =IF(A16="","",L16+Inputs!$B$20/1440) | N16: =IF(A16="","",M16+Inputs!$B$21/1440) | O16: =IF(A16="","",MOD(A16-1,Inputs!$B$33)+1)
A17: =IF(15<=Scenarios!B2,15,"") | B17: =IF(A17="","",(Inputs!$B$9+(A17-1)*Scenarios!D2)/1440) | C17: =IF(A17="","",B17+Inputs!$B$10/1440) | D17: =IF(A17="","",C17+Inputs!$B$11/1440) | E17: =IF(A17="","",D17+Inputs!$B$12/1440) | F17: =IF(A17="","",E17+Inputs!$B$13/1440) | G17: =IF(A17="","",F17+Inputs!$B$14/1440) | H17: =IF(A17="","",G17+Inputs!$B$15/1440) | I17: =IF(A17="","",H17+Inputs!$B$16/1440) | J17: =IF(A17="","",I17+Inputs!$B$17/1440) | K17: =IF(A17="","",J17+Inputs!$B$18/1440) | L17: =IF(A17="","",J17+Inputs!$B$19/1440) | M17: =IF(A17="","",L17+Inputs!$B$20/1440) | N17: =IF(A17="","",M17+Inputs!$B$21/1440) | O17: =IF(A17="","",MOD(A17-1,Inputs!$B$33)+1)
A18: =IF(16<=Scenarios!B2,16,"") | B18: =IF(A18="","",(Inputs!$B$9+(A18-1)*Scenarios!D2)/1440) | C18: =IF(A18="","",B18+Inputs!$B$10/1440) | D18: =IF(A18="","",C18+Inputs!$B$11/1440) | E18: =IF(A18="","",D18+Inputs!$B$12/1440) | F18: =IF(A18="","",E18+Inputs!$B$13/1440) | G18: =IF(A18="","",F18+Inputs!$B$14/1440) | H18: =IF(A18="","",G18+Inputs!$B$15/1440) | I18: =IF(A18="","",H18+Inputs!$B$16/1440) | J18: =IF(A18="","",I18+Inputs!$B$17/1440) | K18: =IF(A18="","",J18+Inputs!$B$18/1440) | L18: =IF(A18="","",J18+Inputs!$B$19/1440) | M18: =IF(A18="","",L18+Inputs!$B$20/1440) | N18: =IF(A18="","",M18+Inputs!$B$21/1440) | O18: =IF(A18="","",MOD(A18-1,Inputs!$B$33)+1)
A19: =IF(17<=Scenarios!B2,17,"") | B19: =IF(A19="","",(Inputs!$B$9+(A19-1)*Scenarios!D2)/1440) | C19: =IF(A19="","",B19+Inputs!$B$10/1440) | D19: =IF(A19="","",C19+Inputs!$B$11/1440) | E19: =IF(A19="","",D19+Inputs!$B$12/1440) | F19: =IF(A19="","",E19+Inputs!$B$13/1440) | G19: =IF(A19="","",F19+Inputs!$B$14/1440) | H19: =IF(A19="","",G19+Inputs!$B$15/1440) | I19: =IF(A19="","",H19+Inputs!$B$16/1440) | J19: =IF(A19="","",I19+Inputs!$B$17/1440) | K19: =IF(A19="","",J19+Inputs!$B$18/1440) | L19: =IF(A19="","",J19+Inputs!$B$19/1440) | M19: =IF(A19="","",L19+Inputs!$B$20/1440) | N19: =IF(A19="","",M19+Inputs!$B$21/1440) | O19: =IF(A19="","",MOD(A19-1,Inputs!$B$33)+1)
A20: =IF(18<=Scenarios!B2,18,"") | B20: =IF(A20="","",(Inputs!$B$9+(A20-1)*Scenarios!D2)/1440) | C20: =IF(A20="","",B20+Inputs!$B$10/1440) | D20: =IF(A20="","",C20+Inputs!$B$11/1440) | E20: =IF(A20="","",D20+Inputs!$B$12/1440) | F20: =IF(A20="","",E20+Inputs!$B$13/1440) | G20: =IF(A20="","",F20+Inputs!$B$14/1440) | H20: =IF(A20="","",G20+Inputs!$B$15/1440) | I20: =IF(A20="","",H20+Inputs!$B$16/1440) | J20: =IF(A20="","",I20+Inputs!$B$17/1440) | K20: =IF(A20="","",J20+Inputs!$B$18/1440) | L20: =IF(A20="","",J20+Inputs!$B$19/1440) | M20: =IF(A20="","",L20+Inputs!$B$20/1440) | N20: =IF(A20="","",M20+Inputs!$B$21/1440) | O20: =IF(A20="","",MOD(A20-1,Inputs!$B$33)+1)
A21: =IF(19<=Scenarios!B2,19,"") | B21: =IF(A21="","",(Inputs!$B$9+(A21-1)*Scenarios!D2)/1440) | C21: =IF(A21="","",B21+Inputs!$B$10/1440) | D21: =IF(A21="","",C21+Inputs!$B$11/1440) | E21: =IF(A21="","",D21+Inputs!$B$12/1440) | F21: =IF(A21="","",E21+Inputs!$B$13/1440) | G21: =IF(A21="","",F21+Inputs!$B$14/1440) | H21: =IF(A21="","",G21+Inputs!$B$15/1440) | I21: =IF(A21="","",H21+Inputs!$B$16/1440) | J21: =IF(A21="","",I21+Inputs!$B$17/1440) | K21: =IF(A21="","",J21+Inputs!$B$18/1440) | L21: =IF(A21="","",J21+Inputs!$B$19/1440) | M21: =IF(A21="","",L21+Inputs!$B$20/1440) | N21: =IF(A21="","",M21+Inputs!$B$21/1440) | O21: =IF(A21="","",MOD(A21-1,Inputs!$B$33)+1)
A22: =IF(20<=Scenarios!B2,20,"") | B22: =IF(A22="","",(Inputs!$B$9+(A22-1)*Scenarios!D2)/1440) | C22: =IF(A22="","",B22+Inputs!$B$10/1440) | D22: =IF(A22="","",C22+Inputs!$B$11/1440) | E22: =IF(A22="","",D22+Inputs!$B$12/1440) | F22: =IF(A22="","",E22+Inputs!$B$13/1440) | G22: =IF(A22="","",F22+Inputs!$B$14/1440) | H22: =IF(A22="","",G22+Inputs!$B$15/1440) | I22: =IF(A22="","",H22+Inputs!$B$16/1440) | J22: =IF(A22="","",I22+Inputs!$B$17/1440) | K22: =IF(A22="","",J22+Inputs!$B$18/1440) | L22: =IF(A22="","",J22+Inputs!$B$19/1440) | M22: =IF(A22="","",L22+Inputs!$B$20/1440) | N22: =IF(A22="","",M22+Inputs!$B$21/1440) | O22: =IF(A22="","",MOD(A22-1,Inputs!$B$33)+1)

Sheet Normal schedule
A1: PLAN-BAG-N / BAG-H2-01 / clocks depend on Inputs
A2: Batch | B2: Mix start | C2: Mix end | D2: Bulk end/divide start | E2: Divide end/mould start | F2: Mould end/proof start | G2: Proof end/score start | H2: Loading complete | I2: Bake end | J2: Unload complete | K2: Oven recovered | L2: Cooling complete | M2: Pack release | N2: Rack set free | O2: Proof bay
A3: =IF(1<=Scenarios!B3,1,"") -> 1 | B3: =IF(A3="","",(Inputs!$B$9+(A3-1)*Scenarios!D3)/1440) -> 0.097222222 | C3: =IF(A3="","",B3+Inputs!$B$10/1440) -> 0.10972222 | D3: =IF(A3="","",C3+Inputs!$B$11/1440) -> 0.14097222 | E3: =IF(A3="","",D3+Inputs!$B$12/1440) -> 0.15138889 | F3: =IF(A3="","",E3+Inputs!$B$13/1440) -> 0.16180556 | G3: =IF(A3="","",F3+Inputs!$B$14/1440) -> 0.20347222 | H3: =IF(A3="","",G3+Inputs!$B$15/1440) -> 0.21041667 | I3: =IF(A3="","",H3+Inputs!$B$16/1440) -> 0.22569444 | J3: =IF(A3="","",I3+Inputs!$B$17/1440) -> 0.22777778 | K3: =IF(A3="","",J3+Inputs!$B$18/1440) -> 0.23125 | L3: =IF(A3="","",J3+Inputs!$B$19/1440) -> 0.25902778 | M3: =IF(A3="","",L3+Inputs!$B$20/1440) -> 0.26944444 | N3: =IF(A3="","",M3+Inputs!$B$21/1440) -> 0.27638889 | O3: =IF(A3="","",MOD(A3-1,Inputs!$B$33)+1) -> 1
A4: =IF(2<=Scenarios!B3,2,"") -> 2 | B4: =IF(A4="","",(Inputs!$B$9+(A4-1)*Scenarios!D3)/1440) -> 0.12847222 | C4: =IF(A4="","",B4+Inputs!$B$10/1440) -> 0.14097222 | D4: =IF(A4="","",C4+Inputs!$B$11/1440) -> 0.17222222 | E4: =IF(A4="","",D4+Inputs!$B$12/1440) -> 0.18263889 | F4: =IF(A4="","",E4+Inputs!$B$13/1440) -> 0.19305556 | G4: =IF(A4="","",F4+Inputs!$B$14/1440) -> 0.23472222 | H4: =IF(A4="","",G4+Inputs!$B$15/1440) -> 0.24166667 | I4: =IF(A4="","",H4+Inputs!$B$16/1440) -> 0.25694444 | J4: =IF(A4="","",I4+Inputs!$B$17/1440) -> 0.25902778 | K4: =IF(A4="","",J4+Inputs!$B$18/1440) -> 0.2625 | L4: =IF(A4="","",J4+Inputs!$B$19/1440) -> 0.29027778 | M4: =IF(A4="","",L4+Inputs!$B$20/1440) -> 0.30069444 | N4: =IF(A4="","",M4+Inputs!$B$21/1440) -> 0.30763889 | O4: =IF(A4="","",MOD(A4-1,Inputs!$B$33)+1) -> 2
A5: =IF(3<=Scenarios!B3,3,"") -> 3 | B5: =IF(A5="","",(Inputs!$B$9+(A5-1)*Scenarios!D3)/1440) -> 0.15972222 | C5: =IF(A5="","",B5+Inputs!$B$10/1440) -> 0.17222222 | D5: =IF(A5="","",C5+Inputs!$B$11/1440) -> 0.20347222 | E5: =IF(A5="","",D5+Inputs!$B$12/1440) -> 0.21388889 | F5: =IF(A5="","",E5+Inputs!$B$13/1440) -> 0.22430556 | G5: =IF(A5="","",F5+Inputs!$B$14/1440) -> 0.26597222 | H5: =IF(A5="","",G5+Inputs!$B$15/1440) -> 0.27291667 | I5: =IF(A5="","",H5+Inputs!$B$16/1440) -> 0.28819444 | J5: =IF(A5="","",I5+Inputs!$B$17/1440) -> 0.29027778 | K5: =IF(A5="","",J5+Inputs!$B$18/1440) -> 0.29375 | L5: =IF(A5="","",J5+Inputs!$B$19/1440) -> 0.32152778 | M5: =IF(A5="","",L5+Inputs!$B$20/1440) -> 0.33194444 | N5: =IF(A5="","",M5+Inputs!$B$21/1440) -> 0.33888889 | O5: =IF(A5="","",MOD(A5-1,Inputs!$B$33)+1) -> 1
A6: =IF(4<=Scenarios!B3,4,"") -> 4 | B6: =IF(A6="","",(Inputs!$B$9+(A6-1)*Scenarios!D3)/1440) -> 0.19097222 | C6: =IF(A6="","",B6+Inputs!$B$10/1440) -> 0.20347222 | D6: =IF(A6="","",C6+Inputs!$B$11/1440) -> 0.23472222 | E6: =IF(A6="","",D6+Inputs!$B$12/1440) -> 0.24513889 | F6: =IF(A6="","",E6+Inputs!$B$13/1440) -> 0.25555556 | G6: =IF(A6="","",F6+Inputs!$B$14/1440) -> 0.29722222 | H6: =IF(A6="","",G6+Inputs!$B$15/1440) -> 0.30416667 | I6: =IF(A6="","",H6+Inputs!$B$16/1440) -> 0.31944444 | J6: =IF(A6="","",I6+Inputs!$B$17/1440) -> 0.32152778 | K6: =IF(A6="","",J6+Inputs!$B$18/1440) -> 0.325 | L6: =IF(A6="","",J6+Inputs!$B$19/1440) -> 0.35277778 | M6: =IF(A6="","",L6+Inputs!$B$20/1440) -> 0.36319444 | N6: =IF(A6="","",M6+Inputs!$B$21/1440) -> 0.37013889 | O6: =IF(A6="","",MOD(A6-1,Inputs!$B$33)+1) -> 2
A7: =IF(5<=Scenarios!B3,5,"") -> 5 | B7: =IF(A7="","",(Inputs!$B$9+(A7-1)*Scenarios!D3)/1440) -> 0.22222222 | C7: =IF(A7="","",B7+Inputs!$B$10/1440) -> 0.23472222 | D7: =IF(A7="","",C7+Inputs!$B$11/1440) -> 0.26597222 | E7: =IF(A7="","",D7+Inputs!$B$12/1440) -> 0.27638889 | F7: =IF(A7="","",E7+Inputs!$B$13/1440) -> 0.28680556 | G7: =IF(A7="","",F7+Inputs!$B$14/1440) -> 0.32847222 | H7: =IF(A7="","",G7+Inputs!$B$15/1440) -> 0.33541667 | I7: =IF(A7="","",H7+Inputs!$B$16/1440) -> 0.35069444 | J7: =IF(A7="","",I7+Inputs!$B$17/1440) -> 0.35277778 | K7: =IF(A7="","",J7+Inputs!$B$18/1440) -> 0.35625 | L7: =IF(A7="","",J7+Inputs!$B$19/1440) -> 0.38402778 | M7: =IF(A7="","",L7+Inputs!$B$20/1440) -> 0.39444444 | N7: =IF(A7="","",M7+Inputs!$B$21/1440) -> 0.40138889 | O7: =IF(A7="","",MOD(A7-1,Inputs!$B$33)+1) -> 1
A8: =IF(6<=Scenarios!B3,6,"") | B8: =IF(A8="","",(Inputs!$B$9+(A8-1)*Scenarios!D3)/1440) | C8: =IF(A8="","",B8+Inputs!$B$10/1440) | D8: =IF(A8="","",C8+Inputs!$B$11/1440) | E8: =IF(A8="","",D8+Inputs!$B$12/1440) | F8: =IF(A8="","",E8+Inputs!$B$13/1440) | G8: =IF(A8="","",F8+Inputs!$B$14/1440) | H8: =IF(A8="","",G8+Inputs!$B$15/1440) | I8: =IF(A8="","",H8+Inputs!$B$16/1440) | J8: =IF(A8="","",I8+Inputs!$B$17/1440) | K8: =IF(A8="","",J8+Inputs!$B$18/1440) | L8: =IF(A8="","",J8+Inputs!$B$19/1440) | M8: =IF(A8="","",L8+Inputs!$B$20/1440) | N8: =IF(A8="","",M8+Inputs!$B$21/1440) | O8: =IF(A8="","",MOD(A8-1,Inputs!$B$33)+1)
A9: =IF(7<=Scenarios!B3,7,"") | B9: =IF(A9="","",(Inputs!$B$9+(A9-1)*Scenarios!D3)/1440) | C9: =IF(A9="","",B9+Inputs!$B$10/1440) | D9: =IF(A9="","",C9+Inputs!$B$11/1440) | E9: =IF(A9="","",D9+Inputs!$B$12/1440) | F9: =IF(A9="","",E9+Inputs!$B$13/1440) | G9: =IF(A9="","",F9+Inputs!$B$14/1440) | H9: =IF(A9="","",G9+Inputs!$B$15/1440) | I9: =IF(A9="","",H9+Inputs!$B$16/1440) | J9: =IF(A9="","",I9+Inputs!$B$17/1440) | K9: =IF(A9="","",J9+Inputs!$B$18/1440) | L9: =IF(A9="","",J9+Inputs!$B$19/1440) | M9: =IF(A9="","",L9+Inputs!$B$20/1440) | N9: =IF(A9="","",M9+Inputs!$B$21/1440) | O9: =IF(A9="","",MOD(A9-1,Inputs!$B$33)+1)
A10: =IF(8<=Scenarios!B3,8,"") | B10: =IF(A10="","",(Inputs!$B$9+(A10-1)*Scenarios!D3)/1440) | C10: =IF(A10="","",B10+Inputs!$B$10/1440) | D10: =IF(A10="","",C10+Inputs!$B$11/1440) | E10: =IF(A10="","",D10+Inputs!$B$12/1440) | F10: =IF(A10="","",E10+Inputs!$B$13/1440) | G10: =IF(A10="","",F10+Inputs!$B$14/1440) | H10: =IF(A10="","",G10+Inputs!$B$15/1440) | I10: =IF(A10="","",H10+Inputs!$B$16/1440) | J10: =IF(A10="","",I10+Inputs!$B$17/1440) | K10: =IF(A10="","",J10+Inputs!$B$18/1440) | L10: =IF(A10="","",J10+Inputs!$B$19/1440) | M10: =IF(A10="","",L10+Inputs!$B$20/1440) | N10: =IF(A10="","",M10+Inputs!$B$21/1440) | O10: =IF(A10="","",MOD(A10-1,Inputs!$B$33)+1)
A11: =IF(9<=Scenarios!B3,9,"") | B11: =IF(A11="","",(Inputs!$B$9+(A11-1)*Scenarios!D3)/1440) | C11: =IF(A11="","",B11+Inputs!$B$10/1440) | D11: =IF(A11="","",C11+Inputs!$B$11/1440) | E11: =IF(A11="","",D11+Inputs!$B$12/1440) | F11: =IF(A11="","",E11+Inputs!$B$13/1440) | G11: =IF(A11="","",F11+Inputs!$B$14/1440) | H11: =IF(A11="","",G11+Inputs!$B$15/1440) | I11: =IF(A11="","",H11+Inputs!$B$16/1440) | J11: =IF(A11="","",I11+Inputs!$B$17/1440) | K11: =IF(A11="","",J11+Inputs!$B$18/1440) | L11: =IF(A11="","",J11+Inputs!$B$19/1440) | M11: =IF(A11="","",L11+Inputs!$B$20/1440) | N11: =IF(A11="","",M11+Inputs!$B$21/1440) | O11: =IF(A11="","",MOD(A11-1,Inputs!$B$33)+1)
A12: =IF(10<=Scenarios!B3,10,"") | B12: =IF(A12="","",(Inputs!$B$9+(A12-1)*Scenarios!D3)/1440) | C12: =IF(A12="","",B12+Inputs!$B$10/1440) | D12: =IF(A12="","",C12+Inputs!$B$11/1440) | E12: =IF(A12="","",D12+Inputs!$B$12/1440) | F12: =IF(A12="","",E12+Inputs!$B$13/1440) | G12: =IF(A12="","",F12+Inputs!$B$14/1440) | H12: =IF(A12="","",G12+Inputs!$B$15/1440) | I12: =IF(A12="","",H12+Inputs!$B$16/1440) | J12: =IF(A12="","",I12+Inputs!$B$17/1440) | K12: =IF(A12="","",J12+Inputs!$B$18/1440) | L12: =IF(A12="","",J12+Inputs!$B$19/1440) | M12: =IF(A12="","",L12+Inputs!$B$20/1440) | N12: =IF(A12="","",M12+Inputs!$B$21/1440) | O12: =IF(A12="","",MOD(A12-1,Inputs!$B$33)+1)
A13: =IF(11<=Scenarios!B3,11,"") | B13: =IF(A13="","",(Inputs!$B$9+(A13-1)*Scenarios!D3)/1440) | C13: =IF(A13="","",B13+Inputs!$B$10/1440) | D13: =IF(A13="","",C13+Inputs!$B$11/1440) | E13: =IF(A13="","",D13+Inputs!$B$12/1440) | F13: =IF(A13="","",E13+Inputs!$B$13/1440) | G13: =IF(A13="","",F13+Inputs!$B$14/1440) | H13: =IF(A13="","",G13+Inputs!$B$15/1440) | I13: =IF(A13="","",H13+Inputs!$B$16/1440) | J13: =IF(A13="","",I13+Inputs!$B$17/1440) | K13: =IF(A13="","",J13+Inputs!$B$18/1440) | L13: =IF(A13="","",J13+Inputs!$B$19/1440) | M13: =IF(A13="","",L13+Inputs!$B$20/1440) | N13: =IF(A13="","",M13+Inputs!$B$21/1440) | O13: =IF(A13="","",MOD(A13-1,Inputs!$B$33)+1)
A14: =IF(12<=Scenarios!B3,12,"") | B14: =IF(A14="","",(Inputs!$B$9+(A14-1)*Scenarios!D3)/1440) | C14: =IF(A14="","",B14+Inputs!$B$10/1440) | D14: =IF(A14="","",C14+Inputs!$B$11/1440) | E14: =IF(A14="","",D14+Inputs!$B$12/1440) | F14: =IF(A14="","",E14+Inputs!$B$13/1440) | G14: =IF(A14="","",F14+Inputs!$B$14/1440) | H14: =IF(A14="","",G14+Inputs!$B$15/1440) | I14: =IF(A14="","",H14+Inputs!$B$16/1440) | J14: =IF(A14="","",I14+Inputs!$B$17/1440) | K14: =IF(A14="","",J14+Inputs!$B$18/1440) | L14: =IF(A14="","",J14+Inputs!$B$19/1440) | M14: =IF(A14="","",L14+Inputs!$B$20/1440) | N14: =IF(A14="","",M14+Inputs!$B$21/1440) | O14: =IF(A14="","",MOD(A14-1,Inputs!$B$33)+1)
A15: =IF(13<=Scenarios!B3,13,"") | B15: =IF(A15="","",(Inputs!$B$9+(A15-1)*Scenarios!D3)/1440) | C15: =IF(A15="","",B15+Inputs!$B$10/1440) | D15: =IF(A15="","",C15+Inputs!$B$11/1440) | E15: =IF(A15="","",D15+Inputs!$B$12/1440) | F15: =IF(A15="","",E15+Inputs!$B$13/1440) | G15: =IF(A15="","",F15+Inputs!$B$14/1440) | H15: =IF(A15="","",G15+Inputs!$B$15/1440) | I15: =IF(A15="","",H15+Inputs!$B$16/1440) | J15: =IF(A15="","",I15+Inputs!$B$17/1440) | K15: =IF(A15="","",J15+Inputs!$B$18/1440) | L15: =IF(A15="","",J15+Inputs!$B$19/1440) | M15: =IF(A15="","",L15+Inputs!$B$20/1440) | N15: =IF(A15="","",M15+Inputs!$B$21/1440) | O15: =IF(A15="","",MOD(A15-1,Inputs!$B$33)+1)
A16: =IF(14<=Scenarios!B3,14,"") | B16: =IF(A16="","",(Inputs!$B$9+(A16-1)*Scenarios!D3)/1440) | C16: =IF(A16="","",B16+Inputs!$B$10/1440) | D16: =IF(A16="","",C16+Inputs!$B$11/1440) | E16: =IF(A16="","",D16+Inputs!$B$12/1440) | F16: =IF(A16="","",E16+Inputs!$B$13/1440) | G16: =IF(A16="","",F16+Inputs!$B$14/1440) | H16: =IF(A16="","",G16+Inputs!$B$15/1440) | I16: =IF(A16="","",H16+Inputs!$B$16/1440) | J16: =IF(A16="","",I16+Inputs!$B$17/1440) | K16: =IF(A16="","",J16+Inputs!$B$18/1440) | L16: =IF(A16="","",J16+Inputs!$B$19/1440) | M16: =IF(A16="","",L16+Inputs!$B$20/1440) | N16: =IF(A16="","",M16+Inputs!$B$21/1440) | O16: =IF(A16="","",MOD(A16-1,Inputs!$B$33)+1)
A17: =IF(15<=Scenarios!B3,15,"") | B17: =IF(A17="","",(Inputs!$B$9+(A17-1)*Scenarios!D3)/1440) | C17: =IF(A17="","",B17+Inputs!$B$10/1440) | D17: =IF(A17="","",C17+Inputs!$B$11/1440) | E17: =IF(A17="","",D17+Inputs!$B$12/1440) | F17: =IF(A17="","",E17+Inputs!$B$13/1440) | G17: =IF(A17="","",F17+Inputs!$B$14/1440) | H17: =IF(A17="","",G17+Inputs!$B$15/1440) | I17: =IF(A17="","",H17+Inputs!$B$16/1440) | J17: =IF(A17="","",I17+Inputs!$B$17/1440) | K17: =IF(A17="","",J17+Inputs!$B$18/1440) | L17: =IF(A17="","",J17+Inputs!$B$19/1440) | M17: =IF(A17="","",L17+Inputs!$B$20/1440) | N17: =IF(A17="","",M17+Inputs!$B$21/1440) | O17: =IF(A17="","",MOD(A17-1,Inputs!$B$33)+1)
A18: =IF(16<=Scenarios!B3,16,"") | B18: =IF(A18="","",(Inputs!$B$9+(A18-1)*Scenarios!D3)/1440) | C18: =IF(A18="","",B18+Inputs!$B$10/1440) | D18: =IF(A18="","",C18+Inputs!$B$11/1440) | E18: =IF(A18="","",D18+Inputs!$B$12/1440) | F18: =IF(A18="","",E18+Inputs!$B$13/1440) | G18: =IF(A18="","",F18+Inputs!$B$14/1440) | H18: =IF(A18="","",G18+Inputs!$B$15/1440) | I18: =IF(A18="","",H18+Inputs!$B$16/1440) | J18: =IF(A18="","",I18+Inputs!$B$17/1440) | K18: =IF(A18="","",J18+Inputs!$B$18/1440) | L18: =IF(A18="","",J18+Inputs!$B$19/1440) | M18: =IF(A18="","",L18+Inputs!$B$20/1440) | N18: =IF(A18="","",M18+Inputs!$B$21/1440) | O18: =IF(A18="","",MOD(A18-1,Inputs!$B$33)+1)
A19: =IF(17<=Scenarios!B3,17,"") | B19: =IF(A19="","",(Inputs!$B$9+(A19-1)*Scenarios!D3)/1440) | C19: =IF(A19="","",B19+Inputs!$B$10/1440) | D19: =IF(A19="","",C19+Inputs!$B$11/1440) | E19: =IF(A19="","",D19+Inputs!$B$12/1440) | F19: =IF(A19="","",E19+Inputs!$B$13/1440) | G19: =IF(A19="","",F19+Inputs!$B$14/1440) | H19: =IF(A19="","",G19+Inputs!$B$15/1440) | I19: =IF(A19="","",H19+Inputs!$B$16/1440) | J19: =IF(A19="","",I19+Inputs!$B$17/1440) | K19: =IF(A19="","",J19+Inputs!$B$18/1440) | L19: =IF(A19="","",J19+Inputs!$B$19/1440) | M19: =IF(A19="","",L19+Inputs!$B$20/1440) | N19: =IF(A19="","",M19+Inputs!$B$21/1440) | O19: =IF(A19="","",MOD(A19-1,Inputs!$B$33)+1)
A20: =IF(18<=Scenarios!B3,18,"") | B20: =IF(A20="","",(Inputs!$B$9+(A20-1)*Scenarios!D3)/1440) | C20: =IF(A20="","",B20+Inputs!$B$10/1440) | D20: =IF(A20="","",C20+Inputs!$B$11/1440) | E20: =IF(A20="","",D20+Inputs!$B$12/1440) | F20: =IF(A20="","",E20+Inputs!$B$13/1440) | G20: =IF(A20="","",F20+Inputs!$B$14/1440) | H20: =IF(A20="","",G20+Inputs!$B$15/1440) | I20: =IF(A20="","",H20+Inputs!$B$16/1440) | J20: =IF(A20="","",I20+Inputs!$B$17/1440) | K20: =IF(A20="","",J20+Inputs!$B$18/1440) | L20: =IF(A20="","",J20+Inputs!$B$19/1440) | M20: =IF(A20="","",L20+Inputs!$B$20/1440) | N20: =IF(A20="","",M20+Inputs!$B$21/1440) | O20: =IF(A20="","",MOD(A20-1,Inputs!$B$33)+1)
A21: =IF(19<=Scenarios!B3,19,"") | B21: =IF(A21="","",(Inputs!$B$9+(A21-1)*Scenarios!D3)/1440) | C21: =IF(A21="","",B21+Inputs!$B$10/1440) | D21: =IF(A21="","",C21+Inputs!$B$11/1440) | E21: =IF(A21="","",D21+Inputs!$B$12/1440) | F21: =IF(A21="","",E21+Inputs!$B$13/1440) | G21: =IF(A21="","",F21+Inputs!$B$14/1440) | H21: =IF(A21="","",G21+Inputs!$B$15/1440) | I21: =IF(A21="","",H21+Inputs!$B$16/1440) | J21: =IF(A21="","",I21+Inputs!$B$17/1440) | K21: =IF(A21="","",J21+Inputs!$B$18/1440) | L21: =IF(A21="","",J21+Inputs!$B$19/1440) | M21: =IF(A21="","",L21+Inputs!$B$20/1440) | N21: =IF(A21="","",M21+Inputs!$B$21/1440) | O21: =IF(A21="","",MOD(A21-1,Inputs!$B$33)+1)
A22: =IF(20<=Scenarios!B3,20,"") | B22: =IF(A22="","",(Inputs!$B$9+(A22-1)*Scenarios!D3)/1440) | C22: =IF(A22="","",B22+Inputs!$B$10/1440) | D22: =IF(A22="","",C22+Inputs!$B$11/1440) | E22: =IF(A22="","",D22+Inputs!$B$12/1440) | F22: =IF(A22="","",E22+Inputs!$B$13/1440) | G22: =IF(A22="","",F22+Inputs!$B$14/1440) | H22: =IF(A22="","",G22+Inputs!$B$15/1440) | I22: =IF(A22="","",H22+Inputs!$B$16/1440) | J22: =IF(A22="","",I22+Inputs!$B$17/1440) | K22: =IF(A22="","",J22+Inputs!$B$18/1440) | L22: =IF(A22="","",J22+Inputs!$B$19/1440) | M22: =IF(A22="","",L22+Inputs!$B$20/1440) | N22: =IF(A22="","",M22+Inputs!$B$21/1440) | O22: =IF(A22="","",MOD(A22-1,Inputs!$B$33)+1)

Sheet High schedule
A1: PLAN-BAG-H / BAG-H2-01 / clocks depend on Inputs
A2: Batch | B2: Mix start | C2: Mix end | D2: Bulk end/divide start | E2: Divide end/mould start | F2: Mould end/proof start | G2: Proof end/score start | H2: Loading complete | I2: Bake end | J2: Unload complete | K2: Oven recovered | L2: Cooling complete | M2: Pack release | N2: Rack set free | O2: Proof bay
A3: =IF(1<=Scenarios!B4,1,"") -> 1 | B3: =IF(A3="","",(Inputs!$B$9+(A3-1)*Scenarios!D4)/1440) -> 0.097222222 | C3: =IF(A3="","",B3+Inputs!$B$10/1440) -> 0.10972222 | D3: =IF(A3="","",C3+Inputs!$B$11/1440) -> 0.14097222 | E3: =IF(A3="","",D3+Inputs!$B$12/1440) -> 0.15138889 | F3: =IF(A3="","",E3+Inputs!$B$13/1440) -> 0.16180556 | G3: =IF(A3="","",F3+Inputs!$B$14/1440) -> 0.20347222 | H3: =IF(A3="","",G3+Inputs!$B$15/1440) -> 0.21041667 | I3: =IF(A3="","",H3+Inputs!$B$16/1440) -> 0.22569444 | J3: =IF(A3="","",I3+Inputs!$B$17/1440) -> 0.22777778 | K3: =IF(A3="","",J3+Inputs!$B$18/1440) -> 0.23125 | L3: =IF(A3="","",J3+Inputs!$B$19/1440) -> 0.25902778 | M3: =IF(A3="","",L3+Inputs!$B$20/1440) -> 0.26944444 | N3: =IF(A3="","",M3+Inputs!$B$21/1440) -> 0.27638889 | O3: =IF(A3="","",MOD(A3-1,Inputs!$B$33)+1) -> 1
A4: =IF(2<=Scenarios!B4,2,"") -> 2 | B4: =IF(A4="","",(Inputs!$B$9+(A4-1)*Scenarios!D4)/1440) -> 0.12847222 | C4: =IF(A4="","",B4+Inputs!$B$10/1440) -> 0.14097222 | D4: =IF(A4="","",C4+Inputs!$B$11/1440) -> 0.17222222 | E4: =IF(A4="","",D4+Inputs!$B$12/1440) -> 0.18263889 | F4: =IF(A4="","",E4+Inputs!$B$13/1440) -> 0.19305556 | G4: =IF(A4="","",F4+Inputs!$B$14/1440) -> 0.23472222 | H4: =IF(A4="","",G4+Inputs!$B$15/1440) -> 0.24166667 | I4: =IF(A4="","",H4+Inputs!$B$16/1440) -> 0.25694444 | J4: =IF(A4="","",I4+Inputs!$B$17/1440) -> 0.25902778 | K4: =IF(A4="","",J4+Inputs!$B$18/1440) -> 0.2625 | L4: =IF(A4="","",J4+Inputs!$B$19/1440) -> 0.29027778 | M4: =IF(A4="","",L4+Inputs!$B$20/1440) -> 0.30069444 | N4: =IF(A4="","",M4+Inputs!$B$21/1440) -> 0.30763889 | O4: =IF(A4="","",MOD(A4-1,Inputs!$B$33)+1) -> 2
A5: =IF(3<=Scenarios!B4,3,"") -> 3 | B5: =IF(A5="","",(Inputs!$B$9+(A5-1)*Scenarios!D4)/1440) -> 0.15972222 | C5: =IF(A5="","",B5+Inputs!$B$10/1440) -> 0.17222222 | D5: =IF(A5="","",C5+Inputs!$B$11/1440) -> 0.20347222 | E5: =IF(A5="","",D5+Inputs!$B$12/1440) -> 0.21388889 | F5: =IF(A5="","",E5+Inputs!$B$13/1440) -> 0.22430556 | G5: =IF(A5="","",F5+Inputs!$B$14/1440) -> 0.26597222 | H5: =IF(A5="","",G5+Inputs!$B$15/1440) -> 0.27291667 | I5: =IF(A5="","",H5+Inputs!$B$16/1440) -> 0.28819444 | J5: =IF(A5="","",I5+Inputs!$B$17/1440) -> 0.29027778 | K5: =IF(A5="","",J5+Inputs!$B$18/1440) -> 0.29375 | L5: =IF(A5="","",J5+Inputs!$B$19/1440) -> 0.32152778 | M5: =IF(A5="","",L5+Inputs!$B$20/1440) -> 0.33194444 | N5: =IF(A5="","",M5+Inputs!$B$21/1440) -> 0.33888889 | O5: =IF(A5="","",MOD(A5-1,Inputs!$B$33)+1) -> 1
A6: =IF(4<=Scenarios!B4,4,"") -> 4 | B6: =IF(A6="","",(Inputs!$B$9+(A6-1)*Scenarios!D4)/1440) -> 0.19097222 | C6: =IF(A6="","",B6+Inputs!$B$10/1440) -> 0.20347222 | D6: =IF(A6="","",C6+Inputs!$B$11/1440) -> 0.23472222 | E6: =IF(A6="","",D6+Inputs!$B$12/1440) -> 0.24513889 | F6: =IF(A6="","",E6+Inputs!$B$13/1440) -> 0.25555556 | G6: =IF(A6="","",F6+Inputs!$B$14/1440) -> 0.29722222 | H6: =IF(A6="","",G6+Inputs!$B$15/1440) -> 0.30416667 | I6: =IF(A6="","",H6+Inputs!$B$16/1440) -> 0.31944444 | J6: =IF(A6="","",I6+Inputs!$B$17/1440) -> 0.32152778 | K6: =IF(A6="","",J6+Inputs!$B$18/1440) -> 0.325 | L6: =IF(A6="","",J6+Inputs!$B$19/1440) -> 0.35277778 | M6: =IF(A6="","",L6+Inputs!$B$20/1440) -> 0.36319444 | N6: =IF(A6="","",M6+Inputs!$B$21/1440) -> 0.37013889 | O6: =IF(A6="","",MOD(A6-1,Inputs!$B$33)+1) -> 2
A7: =IF(5<=Scenarios!B4,5,"") -> 5 | B7: =IF(A7="","",(Inputs!$B$9+(A7-1)*Scenarios!D4)/1440) -> 0.22222222 | C7: =IF(A7="","",B7+Inputs!$B$10/1440) -> 0.23472222 | D7: =IF(A7="","",C7+Inputs!$B$11/1440) -> 0.26597222 | E7: =IF(A7="","",D7+Inputs!$B$12/1440) -> 0.27638889 | F7: =IF(A7="","",E7+Inputs!$B$13/1440) -> 0.28680556 | G7: =IF(A7="","",F7+Inputs!$B$14/1440) -> 0.32847222 | H7: =IF(A7="","",G7+Inputs!$B$15/1440) -> 0.33541667 | I7: =IF(A7="","",H7+Inputs!$B$16/1440) -> 0.35069444 | J7: =IF(A7="","",I7+Inputs!$B$17/1440) -> 0.35277778 | K7: =IF(A7="","",J7+Inputs!$B$18/1440) -> 0.35625 | L7: =IF(A7="","",J7+Inputs!$B$19/1440) -> 0.38402778 | M7: =IF(A7="","",L7+Inputs!$B$20/1440) -> 0.39444444 | N7: =IF(A7="","",M7+Inputs!$B$21/1440) -> 0.40138889 | O7: =IF(A7="","",MOD(A7-1,Inputs!$B$33)+1) -> 1
A8: =IF(6<=Scenarios!B4,6,"") -> 6 | B8: =IF(A8="","",(Inputs!$B$9+(A8-1)*Scenarios!D4)/1440) -> 0.25347222 | C8: =IF(A8="","",B8+Inputs!$B$10/1440) -> 0.26597222 | D8: =IF(A8="","",C8+Inputs!$B$11/1440) -> 0.29722222 | E8: =IF(A8="","",D8+Inputs!$B$12/1440) -> 0.30763889 | F8: =IF(A8="","",E8+Inputs!$B$13/1440) -> 0.31805556 | G8: =IF(A8="","",F8+Inputs!$B$14/1440) -> 0.35972222 | H8: =IF(A8="","",G8+Inputs!$B$15/1440) -> 0.36666667 | I8: =IF(A8="","",H8+Inputs!$B$16/1440) -> 0.38194444 | J8: =IF(A8="","",I8+Inputs!$B$17/1440) -> 0.38402778 | K8: =IF(A8="","",J8+Inputs!$B$18/1440) -> 0.3875 | L8: =IF(A8="","",J8+Inputs!$B$19/1440) -> 0.41527778 | M8: =IF(A8="","",L8+Inputs!$B$20/1440) -> 0.42569444 | N8: =IF(A8="","",M8+Inputs!$B$21/1440) -> 0.43263889 | O8: =IF(A8="","",MOD(A8-1,Inputs!$B$33)+1) -> 2
A9: =IF(7<=Scenarios!B4,7,"") -> 7 | B9: =IF(A9="","",(Inputs!$B$9+(A9-1)*Scenarios!D4)/1440) -> 0.28472222 | C9: =IF(A9="","",B9+Inputs!$B$10/1440) -> 0.29722222 | D9: =IF(A9="","",C9+Inputs!$B$11/1440) -> 0.32847222 | E9: =IF(A9="","",D9+Inputs!$B$12/1440) -> 0.33888889 | F9: =IF(A9="","",E9+Inputs!$B$13/1440) -> 0.34930556 | G9: =IF(A9="","",F9+Inputs!$B$14/1440) -> 0.39097222 | H9: =IF(A9="","",G9+Inputs!$B$15/1440) -> 0.39791667 | I9: =IF(A9="","",H9+Inputs!$B$16/1440) -> 0.41319444 | J9: =IF(A9="","",I9+Inputs!$B$17/1440) -> 0.41527778 | K9: =IF(A9="","",J9+Inputs!$B$18/1440) -> 0.41875 | L9: =IF(A9="","",J9+Inputs!$B$19/1440) -> 0.44652778 | M9: =IF(A9="","",L9+Inputs!$B$20/1440) -> 0.45694444 | N9: =IF(A9="","",M9+Inputs!$B$21/1440) -> 0.46388889 | O9: =IF(A9="","",MOD(A9-1,Inputs!$B$33)+1) -> 1
A10: =IF(8<=Scenarios!B4,8,"") -> 8 | B10: =IF(A10="","",(Inputs!$B$9+(A10-1)*Scenarios!D4)/1440) -> 0.31597222 | C10: =IF(A10="","",B10+Inputs!$B$10/1440) -> 0.32847222 | D10: =IF(A10="","",C10+Inputs!$B$11/1440) -> 0.35972222 | E10: =IF(A10="","",D10+Inputs!$B$12/1440) -> 0.37013889 | F10: =IF(A10="","",E10+Inputs!$B$13/1440) -> 0.38055556 | G10: =IF(A10="","",F10+Inputs!$B$14/1440) -> 0.42222222 | H10: =IF(A10="","",G10+Inputs!$B$15/1440) -> 0.42916667 | I10: =IF(A10="","",H10+Inputs!$B$16/1440) -> 0.44444444 | J10: =IF(A10="","",I10+Inputs!$B$17/1440) -> 0.44652778 | K10: =IF(A10="","",J10+Inputs!$B$18/1440) -> 0.45 | L10: =IF(A10="","",J10+Inputs!$B$19/1440) -> 0.47777778 | M10: =IF(A10="","",L10+Inputs!$B$20/1440) -> 0.48819444 | N10: =IF(A10="","",M10+Inputs!$B$21/1440) -> 0.49513889 | O10: =IF(A10="","",MOD(A10-1,Inputs!$B$33)+1) -> 2
A11: =IF(9<=Scenarios!B4,9,"") -> 9 | B11: =IF(A11="","",(Inputs!$B$9+(A11-1)*Scenarios!D4)/1440) -> 0.34722222 | C11: =IF(A11="","",B11+Inputs!$B$10/1440) -> 0.35972222 | D11: =IF(A11="","",C11+Inputs!$B$11/1440) -> 0.39097222 | E11: =IF(A11="","",D11+Inputs!$B$12/1440) -> 0.40138889 | F11: =IF(A11="","",E11+Inputs!$B$13/1440) -> 0.41180556 | G11: =IF(A11="","",F11+Inputs!$B$14/1440) -> 0.45347222 | H11: =IF(A11="","",G11+Inputs!$B$15/1440) -> 0.46041667 | I11: =IF(A11="","",H11+Inputs!$B$16/1440) -> 0.47569444 | J11: =IF(A11="","",I11+Inputs!$B$17/1440) -> 0.47777778 | K11: =IF(A11="","",J11+Inputs!$B$18/1440) -> 0.48125 | L11: =IF(A11="","",J11+Inputs!$B$19/1440) -> 0.50902778 | M11: =IF(A11="","",L11+Inputs!$B$20/1440) -> 0.51944444 | N11: =IF(A11="","",M11+Inputs!$B$21/1440) -> 0.52638889 | O11: =IF(A11="","",MOD(A11-1,Inputs!$B$33)+1) -> 1
A12: =IF(10<=Scenarios!B4,10,"") -> 10 | B12: =IF(A12="","",(Inputs!$B$9+(A12-1)*Scenarios!D4)/1440) -> 0.37847222 | C12: =IF(A12="","",B12+Inputs!$B$10/1440) -> 0.39097222 | D12: =IF(A12="","",C12+Inputs!$B$11/1440) -> 0.42222222 | E12: =IF(A12="","",D12+Inputs!$B$12/1440) -> 0.43263889 | F12: =IF(A12="","",E12+Inputs!$B$13/1440) -> 0.44305556 | G12: =IF(A12="","",F12+Inputs!$B$14/1440) -> 0.48472222 | H12: =IF(A12="","",G12+Inputs!$B$15/1440) -> 0.49166667 | I12: =IF(A12="","",H12+Inputs!$B$16/1440) -> 0.50694444 | J12: =IF(A12="","",I12+Inputs!$B$17/1440) -> 0.50902778 | K12: =IF(A12="","",J12+Inputs!$B$18/1440) -> 0.5125 | L12: =IF(A12="","",J12+Inputs!$B$19/1440) -> 0.54027778 | M12: =IF(A12="","",L12+Inputs!$B$20/1440) -> 0.55069444 | N12: =IF(A12="","",M12+Inputs!$B$21/1440) -> 0.55763889 | O12: =IF(A12="","",MOD(A12-1,Inputs!$B$33)+1) -> 2
A13: =IF(11<=Scenarios!B4,11,"") | B13: =IF(A13="","",(Inputs!$B$9+(A13-1)*Scenarios!D4)/1440) | C13: =IF(A13="","",B13+Inputs!$B$10/1440) | D13: =IF(A13="","",C13+Inputs!$B$11/1440) | E13: =IF(A13="","",D13+Inputs!$B$12/1440) | F13: =IF(A13="","",E13+Inputs!$B$13/1440) | G13: =IF(A13="","",F13+Inputs!$B$14/1440) | H13: =IF(A13="","",G13+Inputs!$B$15/1440) | I13: =IF(A13="","",H13+Inputs!$B$16/1440) | J13: =IF(A13="","",I13+Inputs!$B$17/1440) | K13: =IF(A13="","",J13+Inputs!$B$18/1440) | L13: =IF(A13="","",J13+Inputs!$B$19/1440) | M13: =IF(A13="","",L13+Inputs!$B$20/1440) | N13: =IF(A13="","",M13+Inputs!$B$21/1440) | O13: =IF(A13="","",MOD(A13-1,Inputs!$B$33)+1)
A14: =IF(12<=Scenarios!B4,12,"") | B14: =IF(A14="","",(Inputs!$B$9+(A14-1)*Scenarios!D4)/1440) | C14: =IF(A14="","",B14+Inputs!$B$10/1440) | D14: =IF(A14="","",C14+Inputs!$B$11/1440) | E14: =IF(A14="","",D14+Inputs!$B$12/1440) | F14: =IF(A14="","",E14+Inputs!$B$13/1440) | G14: =IF(A14="","",F14+Inputs!$B$14/1440) | H14: =IF(A14="","",G14+Inputs!$B$15/1440) | I14: =IF(A14="","",H14+Inputs!$B$16/1440) | J14: =IF(A14="","",I14+Inputs!$B$17/1440) | K14: =IF(A14="","",J14+Inputs!$B$18/1440) | L14: =IF(A14="","",J14+Inputs!$B$19/1440) | M14: =IF(A14="","",L14+Inputs!$B$20/1440) | N14: =IF(A14="","",M14+Inputs!$B$21/1440) | O14: =IF(A14="","",MOD(A14-1,Inputs!$B$33)+1)
A15: =IF(13<=Scenarios!B4,13,"") | B15: =IF(A15="","",(Inputs!$B$9+(A15-1)*Scenarios!D4)/1440) | C15: =IF(A15="","",B15+Inputs!$B$10/1440) | D15: =IF(A15="","",C15+Inputs!$B$11/1440) | E15: =IF(A15="","",D15+Inputs!$B$12/1440) | F15: =IF(A15="","",E15+Inputs!$B$13/1440) | G15: =IF(A15="","",F15+Inputs!$B$14/1440) | H15: =IF(A15="","",G15+Inputs!$B$15/1440) | I15: =IF(A15="","",H15+Inputs!$B$16/1440) | J15: =IF(A15="","",I15+Inputs!$B$17/1440) | K15: =IF(A15="","",J15+Inputs!$B$18/1440) | L15: =IF(A15="","",J15+Inputs!$B$19/1440) | M15: =IF(A15="","",L15+Inputs!$B$20/1440) | N15: =IF(A15="","",M15+Inputs!$B$21/1440) | O15: =IF(A15="","",MOD(A15-1,Inputs!$B$33)+1)
A16: =IF(14<=Scenarios!B4,14,"") | B16: =IF(A16="","",(Inputs!$B$9+(A16-1)*Scenarios!D4)/1440) | C16: =IF(A16="","",B16+Inputs!$B$10/1440) | D16: =IF(A16="","",C16+Inputs!$B$11/1440) | E16: =IF(A16="","",D16+Inputs!$B$12/1440) | F16: =IF(A16="","",E16+Inputs!$B$13/1440) | G16: =IF(A16="","",F16+Inputs!$B$14/1440) | H16: =IF(A16="","",G16+Inputs!$B$15/1440) | I16: =IF(A16="","",H16+Inputs!$B$16/1440) | J16: =IF(A16="","",I16+Inputs!$B$17/1440) | K16: =IF(A16="","",J16+Inputs!$B$18/1440) | L16: =IF(A16="","",J16+Inputs!$B$19/1440) | M16: =IF(A16="","",L16+Inputs!$B$20/1440) | N16: =IF(A16="","",M16+Inputs!$B$21/1440) | O16: =IF(A16="","",MOD(A16-1,Inputs!$B$33)+1)
A17: =IF(15<=Scenarios!B4,15,"") | B17: =IF(A17="","",(Inputs!$B$9+(A17-1)*Scenarios!D4)/1440) | C17: =IF(A17="","",B17+Inputs!$B$10/1440) | D17: =IF(A17="","",C17+Inputs!$B$11/1440) | E17: =IF(A17="","",D17+Inputs!$B$12/1440) | F17: =IF(A17="","",E17+Inputs!$B$13/1440) | G17: =IF(A17="","",F17+Inputs!$B$14/1440) | H17: =IF(A17="","",G17+Inputs!$B$15/1440) | I17: =IF(A17="","",H17+Inputs!$B$16/1440) | J17: =IF(A17="","",I17+Inputs!$B$17/1440) | K17: =IF(A17="","",J17+Inputs!$B$18/1440) | L17: =IF(A17="","",J17+Inputs!$B$19/1440) | M17: =IF(A17="","",L17+Inputs!$B$20/1440) | N17: =IF(A17="","",M17+Inputs!$B$21/1440) | O17: =IF(A17="","",MOD(A17-1,Inputs!$B$33)+1)
A18: =IF(16<=Scenarios!B4,16,"") | B18: =IF(A18="","",(Inputs!$B$9+(A18-1)*Scenarios!D4)/1440) | C18: =IF(A18="","",B18+Inputs!$B$10/1440) | D18: =IF(A18="","",C18+Inputs!$B$11/1440) | E18: =IF(A18="","",D18+Inputs!$B$12/1440) | F18: =IF(A18="","",E18+Inputs!$B$13/1440) | G18: =IF(A18="","",F18+Inputs!$B$14/1440) | H18: =IF(A18="","",G18+Inputs!$B$15/1440) | I18: =IF(A18="","",H18+Inputs!$B$16/1440) | J18: =IF(A18="","",I18+Inputs!$B$17/1440) | K18: =IF(A18="","",J18+Inputs!$B$18/1440) | L18: =IF(A18="","",J18+Inputs!$B$19/1440) | M18: =IF(A18="","",L18+Inputs!$B$20/1440) | N18: =IF(A18="","",M18+Inputs!$B$21/1440) | O18: =IF(A18="","",MOD(A18-1,Inputs!$B$33)+1)
A19: =IF(17<=Scenarios!B4,17,"") | B19: =IF(A19="","",(Inputs!$B$9+(A19-1)*Scenarios!D4)/1440) | C19: =IF(A19="","",B19+Inputs!$B$10/1440) | D19: =IF(A19="","",C19+Inputs!$B$11/1440) | E19: =IF(A19="","",D19+Inputs!$B$12/1440) | F19: =IF(A19="","",E19+Inputs!$B$13/1440) | G19: =IF(A19="","",F19+Inputs!$B$14/1440) | H19: =IF(A19="","",G19+Inputs!$B$15/1440) | I19: =IF(A19="","",H19+Inputs!$B$16/1440) | J19: =IF(A19="","",I19+Inputs!$B$17/1440) | K19: =IF(A19="","",J19+Inputs!$B$18/1440) | L19: =IF(A19="","",J19+Inputs!$B$19/1440) | M19: =IF(A19="","",L19+Inputs!$B$20/1440) | N19: =IF(A19="","",M19+Inputs!$B$21/1440) | O19: =IF(A19="","",MOD(A19-1,Inputs!$B$33)+1)
A20: =IF(18<=Scenarios!B4,18,"") | B20: =IF(A20="","",(Inputs!$B$9+(A20-1)*Scenarios!D4)/1440) | C20: =IF(A20="","",B20+Inputs!$B$10/1440) | D20: =IF(A20="","",C20+Inputs!$B$11/1440) | E20: =IF(A20="","",D20+Inputs!$B$12/1440) | F20: =IF(A20="","",E20+Inputs!$B$13/1440) | G20: =IF(A20="","",F20+Inputs!$B$14/1440) | H20: =IF(A20="","",G20+Inputs!$B$15/1440) | I20: =IF(A20="","",H20+Inputs!$B$16/1440) | J20: =IF(A20="","",I20+Inputs!$B$17/1440) | K20: =IF(A20="","",J20+Inputs!$B$18/1440) | L20: =IF(A20="","",J20+Inputs!$B$19/1440) | M20: =IF(A20="","",L20+Inputs!$B$20/1440) | N20: =IF(A20="","",M20+Inputs!$B$21/1440) | O20: =IF(A20="","",MOD(A20-1,Inputs!$B$33)+1)
A21: =IF(19<=Scenarios!B4,19,"") | B21: =IF(A21="","",(Inputs!$B$9+(A21-1)*Scenarios!D4)/1440) | C21: =IF(A21="","",B21+Inputs!$B$10/1440) | D21: =IF(A21="","",C21+Inputs!$B$11/1440) | E21: =IF(A21="","",D21+Inputs!$B$12/1440) | F21: =IF(A21="","",E21+Inputs!$B$13/1440) | G21: =IF(A21="","",F21+Inputs!$B$14/1440) | H21: =IF(A21="","",G21+Inputs!$B$15/1440) | I21: =IF(A21="","",H21+Inputs!$B$16/1440) | J21: =IF(A21="","",I21+Inputs!$B$17/1440) | K21: =IF(A21="","",J21+Inputs!$B$18/1440) | L21: =IF(A21="","",J21+Inputs!$B$19/1440) | M21: =IF(A21="","",L21+Inputs!$B$20/1440) | N21: =IF(A21="","",M21+Inputs!$B$21/1440) | O21: =IF(A21="","",MOD(A21-1,Inputs!$B$33)+1)
A22: =IF(20<=Scenarios!B4,20,"") | B22: =IF(A22="","",(Inputs!$B$9+(A22-1)*Scenarios!D4)/1440) | C22: =IF(A22="","",B22+Inputs!$B$10/1440) | D22: =IF(A22="","",C22+Inputs!$B$11/1440) | E22: =IF(A22="","",D22+Inputs!$B$12/1440) | F22: =IF(A22="","",E22+Inputs!$B$13/1440) | G22: =IF(A22="","",F22+Inputs!$B$14/1440) | H22: =IF(A22="","",G22+Inputs!$B$15/1440) | I22: =IF(A22="","",H22+Inputs!$B$16/1440) | J22: =IF(A22="","",I22+Inputs!$B$17/1440) | K22: =IF(A22="","",J22+Inputs!$B$18/1440) | L22: =IF(A22="","",J22+Inputs!$B$19/1440) | M22: =IF(A22="","",L22+Inputs!$B$20/1440) | N22: =IF(A22="","",M22+Inputs!$B$21/1440) | O22: =IF(A22="","",MOD(A22-1,Inputs!$B$33)+1)

Sheet Dispatch
A1: Scenario | B1: Wave | C1: First batch | D1: Last batch | E1: Retained units | F1: Ready packed | G1: Vehicle load start | H1: Depart A | I1: Arrive B | J1: Vehicle ready A | K1: Max staged min | L1: Vehicle capacity gate
A2: =IF(1<=Scenarios!B2,Scenarios!A2,"") -> PLAN-BAG-P | B2: =IF(A2="","",1) -> 1 | C2: =IF(A2="","",1) -> 1 | D2: =IF(A2="","",MIN(Scenarios!B2,1)) -> 1 | E2: =IF(A2="","",(D2-C2+1)*Scenarios!O2) -> 39 | F2: =IF(A2="","",INDEX('Pilot schedule'!M:M,D2+2)) -> 0.26944444 | G2: =IF(A2="","",F2) -> 0.26944444 | H2: =IF(A2="","",G2+Inputs!$B$26/1440) -> 0.27291667 | I2: =IF(A2="","",H2+Inputs!$B$27/1440) -> 0.29375 | J2: =IF(A2="","",I2+(Inputs!$B$28+Inputs!$B$29+Inputs!$B$30)/1440) -> 0.32847222 | K2: =IF(A2="","",(G2-INDEX('Pilot schedule'!M:M,C2+2))*1440) -> 0 | L2: =IF(A2="","",IF(E2<=Inputs!$B$36,"MODEL FITS; CONFIRM ROUTE","CAPACITY EXCEEDED")) -> MODEL FITS; CONFIRM ROUTE
A3: =IF(2<=Scenarios!B2,Scenarios!A2,"") -> PLAN-BAG-P | B3: =IF(A3="","",2) -> 2 | C3: =IF(A3="","",2) -> 2 | D3: =IF(A3="","",MIN(Scenarios!B2,3)) -> 2 | E3: =IF(A3="","",(D3-C3+1)*Scenarios!O2) -> 39 | F3: =IF(A3="","",INDEX('Pilot schedule'!M:M,D3+2)) -> 0.33194444 | G3: =IF(A3="","",MAX(F3,J2)) -> 0.33194444 | H3: =IF(A3="","",G3+Inputs!$B$26/1440) -> 0.33541667 | I3: =IF(A3="","",H3+Inputs!$B$27/1440) -> 0.35625 | J3: =IF(A3="","",I3+(Inputs!$B$28+Inputs!$B$29+Inputs!$B$30)/1440) -> 0.39097222 | K3: =IF(A3="","",(G3-INDEX('Pilot schedule'!M:M,C3+2))*1440) -> 0 | L3: =IF(A3="","",IF(E3<=Inputs!$B$36,"MODEL FITS; CONFIRM ROUTE","CAPACITY EXCEEDED")) -> MODEL FITS; CONFIRM ROUTE
A4: =IF(4<=Scenarios!B2,Scenarios!A2,"") | B4: =IF(A4="","",3) | C4: =IF(A4="","",4) | D4: =IF(A4="","",MIN(Scenarios!B2,5)) | E4: =IF(A4="","",(D4-C4+1)*Scenarios!O2) | F4: =IF(A4="","",INDEX('Pilot schedule'!M:M,D4+2)) | G4: =IF(A4="","",MAX(F4,J3)) | H4: =IF(A4="","",G4+Inputs!$B$26/1440) | I4: =IF(A4="","",H4+Inputs!$B$27/1440) | J4: =IF(A4="","",I4+(Inputs!$B$28+Inputs!$B$29+Inputs!$B$30)/1440) | K4: =IF(A4="","",(G4-INDEX('Pilot schedule'!M:M,C4+2))*1440) | L4: =IF(A4="","",IF(E4<=Inputs!$B$36,"MODEL FITS; CONFIRM ROUTE","CAPACITY EXCEEDED"))
A5: =IF(6<=Scenarios!B2,Scenarios!A2,"") | B5: =IF(A5="","",4) | C5: =IF(A5="","",6) | D5: =IF(A5="","",MIN(Scenarios!B2,7)) | E5: =IF(A5="","",(D5-C5+1)*Scenarios!O2) | F5: =IF(A5="","",INDEX('Pilot schedule'!M:M,D5+2)) | G5: =IF(A5="","",MAX(F5,J4)) | H5: =IF(A5="","",G5+Inputs!$B$26/1440) | I5: =IF(A5="","",H5+Inputs!$B$27/1440) | J5: =IF(A5="","",I5+(Inputs!$B$28+Inputs!$B$29+Inputs!$B$30)/1440) | K5: =IF(A5="","",(G5-INDEX('Pilot schedule'!M:M,C5+2))*1440) | L5: =IF(A5="","",IF(E5<=Inputs!$B$36,"MODEL FITS; CONFIRM ROUTE","CAPACITY EXCEEDED"))
A6: =IF(8<=Scenarios!B2,Scenarios!A2,"") | B6: =IF(A6="","",5) | C6: =IF(A6="","",8) | D6: =IF(A6="","",MIN(Scenarios!B2,9)) | E6: =IF(A6="","",(D6-C6+1)*Scenarios!O2) | F6: =IF(A6="","",INDEX('Pilot schedule'!M:M,D6+2)) | G6: =IF(A6="","",MAX(F6,J5)) | H6: =IF(A6="","",G6+Inputs!$B$26/1440) | I6: =IF(A6="","",H6+Inputs!$B$27/1440) | J6: =IF(A6="","",I6+(Inputs!$B$28+Inputs!$B$29+Inputs!$B$30)/1440) | K6: =IF(A6="","",(G6-INDEX('Pilot schedule'!M:M,C6+2))*1440) | L6: =IF(A6="","",IF(E6<=Inputs!$B$36,"MODEL FITS; CONFIRM ROUTE","CAPACITY EXCEEDED"))
A7: =IF(10<=Scenarios!B2,Scenarios!A2,"") | B7: =IF(A7="","",6) | C7: =IF(A7="","",10) | D7: =IF(A7="","",MIN(Scenarios!B2,11)) | E7: =IF(A7="","",(D7-C7+1)*Scenarios!O2) | F7: =IF(A7="","",INDEX('Pilot schedule'!M:M,D7+2)) | G7: =IF(A7="","",MAX(F7,J6)) | H7: =IF(A7="","",G7+Inputs!$B$26/1440) | I7: =IF(A7="","",H7+Inputs!$B$27/1440) | J7: =IF(A7="","",I7+(Inputs!$B$28+Inputs!$B$29+Inputs!$B$30)/1440) | K7: =IF(A7="","",(G7-INDEX('Pilot schedule'!M:M,C7+2))*1440) | L7: =IF(A7="","",IF(E7<=Inputs!$B$36,"MODEL FITS; CONFIRM ROUTE","CAPACITY EXCEEDED"))
A8: =IF(12<=Scenarios!B2,Scenarios!A2,"") | B8: =IF(A8="","",7) | C8: =IF(A8="","",12) | D8: =IF(A8="","",MIN(Scenarios!B2,13)) | E8: =IF(A8="","",(D8-C8+1)*Scenarios!O2) | F8: =IF(A8="","",INDEX('Pilot schedule'!M:M,D8+2)) | G8: =IF(A8="","",MAX(F8,J7)) | H8: =IF(A8="","",G8+Inputs!$B$26/1440) | I8: =IF(A8="","",H8+Inputs!$B$27/1440) | J8: =IF(A8="","",I8+(Inputs!$B$28+Inputs!$B$29+Inputs!$B$30)/1440) | K8: =IF(A8="","",(G8-INDEX('Pilot schedule'!M:M,C8+2))*1440) | L8: =IF(A8="","",IF(E8<=Inputs!$B$36,"MODEL FITS; CONFIRM ROUTE","CAPACITY EXCEEDED"))
A9: =IF(14<=Scenarios!B2,Scenarios!A2,"") | B9: =IF(A9="","",8) | C9: =IF(A9="","",14) | D9: =IF(A9="","",MIN(Scenarios!B2,15)) | E9: =IF(A9="","",(D9-C9+1)*Scenarios!O2) | F9: =IF(A9="","",INDEX('Pilot schedule'!M:M,D9+2)) | G9: =IF(A9="","",MAX(F9,J8)) | H9: =IF(A9="","",G9+Inputs!$B$26/1440) | I9: =IF(A9="","",H9+Inputs!$B$27/1440) | J9: =IF(A9="","",I9+(Inputs!$B$28+Inputs!$B$29+Inputs!$B$30)/1440) | K9: =IF(A9="","",(G9-INDEX('Pilot schedule'!M:M,C9+2))*1440) | L9: =IF(A9="","",IF(E9<=Inputs!$B$36,"MODEL FITS; CONFIRM ROUTE","CAPACITY EXCEEDED"))
A10: =IF(16<=Scenarios!B2,Scenarios!A2,"") | B10: =IF(A10="","",9) | C10: =IF(A10="","",16) | D10: =IF(A10="","",MIN(Scenarios!B2,17)) | E10: =IF(A10="","",(D10-C10+1)*Scenarios!O2) | F10: =IF(A10="","",INDEX('Pilot schedule'!M:M,D10+2)) | G10: =IF(A10="","",MAX(F10,J9)) | H10: =IF(A10="","",G10+Inputs!$B$26/1440) | I10: =IF(A10="","",H10+Inputs!$B$27/1440) | J10: =IF(A10="","",I10+(Inputs!$B$28+Inputs!$B$29+Inputs!$B$30)/1440) | K10: =IF(A10="","",(G10-INDEX('Pilot schedule'!M:M,C10+2))*1440) | L10: =IF(A10="","",IF(E10<=Inputs!$B$36,"MODEL FITS; CONFIRM ROUTE","CAPACITY EXCEEDED"))
A11: =IF(18<=Scenarios!B2,Scenarios!A2,"") | B11: =IF(A11="","",10) | C11: =IF(A11="","",18) | D11: =IF(A11="","",MIN(Scenarios!B2,19)) | E11: =IF(A11="","",(D11-C11+1)*Scenarios!O2) | F11: =IF(A11="","",INDEX('Pilot schedule'!M:M,D11+2)) | G11: =IF(A11="","",MAX(F11,J10)) | H11: =IF(A11="","",G11+Inputs!$B$26/1440) | I11: =IF(A11="","",H11+Inputs!$B$27/1440) | J11: =IF(A11="","",I11+(Inputs!$B$28+Inputs!$B$29+Inputs!$B$30)/1440) | K11: =IF(A11="","",(G11-INDEX('Pilot schedule'!M:M,C11+2))*1440) | L11: =IF(A11="","",IF(E11<=Inputs!$B$36,"MODEL FITS; CONFIRM ROUTE","CAPACITY EXCEEDED"))
A12: =IF(20<=Scenarios!B2,Scenarios!A2,"") | B12: =IF(A12="","",11) | C12: =IF(A12="","",20) | D12: =IF(A12="","",MIN(Scenarios!B2,21)) | E12: =IF(A12="","",(D12-C12+1)*Scenarios!O2) | F12: =IF(A12="","",INDEX('Pilot schedule'!M:M,D12+2)) | G12: =IF(A12="","",MAX(F12,J11)) | H12: =IF(A12="","",G12+Inputs!$B$26/1440) | I12: =IF(A12="","",H12+Inputs!$B$27/1440) | J12: =IF(A12="","",I12+(Inputs!$B$28+Inputs!$B$29+Inputs!$B$30)/1440) | K12: =IF(A12="","",(G12-INDEX('Pilot schedule'!M:M,C12+2))*1440) | L12: =IF(A12="","",IF(E12<=Inputs!$B$36,"MODEL FITS; CONFIRM ROUTE","CAPACITY EXCEEDED"))
A13: =IF(1<=Scenarios!B3,Scenarios!A3,"") -> PLAN-BAG-N | B13: =IF(A13="","",1) -> 1 | C13: =IF(A13="","",1) -> 1 | D13: =IF(A13="","",MIN(Scenarios!B3,1)) -> 1 | E13: =IF(A13="","",(D13-C13+1)*Scenarios!O3) -> 78 | F13: =IF(A13="","",INDEX('Normal schedule'!M:M,D13+2)) -> 0.26944444 | G13: =IF(A13="","",F13) -> 0.26944444 | H13: =IF(A13="","",G13+Inputs!$B$26/1440) -> 0.27291667 | I13: =IF(A13="","",H13+Inputs!$B$27/1440) -> 0.29375 | J13: =IF(A13="","",I13+(Inputs!$B$28+Inputs!$B$29+Inputs!$B$30)/1440) -> 0.32847222 | K13: =IF(A13="","",(G13-INDEX('Normal schedule'!M:M,C13+2))*1440) -> 0 | L13: =IF(A13="","",IF(E13<=Inputs!$B$36,"MODEL FITS; CONFIRM ROUTE","CAPACITY EXCEEDED")) -> MODEL FITS; CONFIRM ROUTE
A14: =IF(2<=Scenarios!B3,Scenarios!A3,"") -> PLAN-BAG-N | B14: =IF(A14="","",2) -> 2 | C14: =IF(A14="","",2) -> 2 | D14: =IF(A14="","",MIN(Scenarios!B3,3)) -> 3 | E14: =IF(A14="","",(D14-C14+1)*Scenarios!O3) -> 156 | F14: =IF(A14="","",INDEX('Normal schedule'!M:M,D14+2)) -> 0.33194444 | G14: =IF(A14="","",MAX(F14,J13)) -> 0.33194444 | H14: =IF(A14="","",G14+Inputs!$B$26/1440) -> 0.33541667 | I14: =IF(A14="","",H14+Inputs!$B$27/1440) -> 0.35625 | J14: =IF(A14="","",I14+(Inputs!$B$28+Inputs!$B$29+Inputs!$B$30)/1440) -> 0.39097222 | K14: =IF(A14="","",(G14-INDEX('Normal schedule'!M:M,C14+2))*1440) -> 45 | L14: =IF(A14="","",IF(E14<=Inputs!$B$36,"MODEL FITS; CONFIRM ROUTE","CAPACITY EXCEEDED")) -> MODEL FITS; CONFIRM ROUTE
A15: =IF(4<=Scenarios!B3,Scenarios!A3,"") -> PLAN-BAG-N | B15: =IF(A15="","",3) -> 3 | C15: =IF(A15="","",4) -> 4 | D15: =IF(A15="","",MIN(Scenarios!B3,5)) -> 5 | E15: =IF(A15="","",(D15-C15+1)*Scenarios!O3) -> 156 | F15: =IF(A15="","",INDEX('Normal schedule'!M:M,D15+2)) -> 0.39444444 | G15: =IF(A15="","",MAX(F15,J14)) -> 0.39444444 | H15: =IF(A15="","",G15+Inputs!$B$26/1440) -> 0.39791667 | I15: =IF(A15="","",H15+Inputs!$B$27/1440) -> 0.41875 | J15: =IF(A15="","",I15+(Inputs!$B$28+Inputs!$B$29+Inputs!$B$30)/1440) -> 0.45347222 | K15: =IF(A15="","",(G15-INDEX('Normal schedule'!M:M,C15+2))*1440) -> 45 | L15: =IF(A15="","",IF(E15<=Inputs!$B$36,"MODEL FITS; CONFIRM ROUTE","CAPACITY EXCEEDED")) -> MODEL FITS; CONFIRM ROUTE
